Workbook
Name DescMap_Description: Description_Map!$A$5:INDEX(Description_Map!$A:$A, MAX(5, COUNTA(Description_Map!$A:$A)+4))
Name DescMap_Label: Description_Map!$B$5:INDEX(Description_Map!$B:$B, MAX(5, COUNTA(Description_Map!$A:$A)+4))
Name RR_Period_Date: 'Rent Roll Recon'!$B$2
Name T12_Period_Date: 'T12 Analytics'!$E$2
Name RR_Input_Data: 'Rent Roll Input'!$A$7:$S$606
Name T12_Input_Data: 'T12 Input'!$A$12:$O$511
Name Property_Name: Cover!$B$5

Sheet Cover
A1: ALF Financial Analyzer | AZ1: Workbook landing — versions, links, orientation
A2: Senior-housing underwriting workbook — RR + T12 reconciliation, UW-ready output | AZ2: reference
AZ3: visible
A4: Property | AZ4: v0.2.7
A5: Property name
A7: Versions
A8: Substrate template | B8: v0.2.7
A9: Rent Roll Normalizer (app) | B9: v1.12.0
A10: T12 Normalizer | B10: v0.1.0
A12: Links
A13: GitHub | B13: https://github.com/<your-repo>/rent-roll-normalizer
A14: App URL | B14: https://rrnormalizer.streamlit.app/
A16: About
A17: This workbook is the underwriting destination for the Rent Roll Normalizer and T12 Normalizer pipeline. Paste normalized rent roll data into 'Rent Roll Input', T12 data into 'T12 Input', and the analytical sheets recalculate automatically.
A18: Visible tabs flow left to right: T12 inputs → RR inputs → reconciliation → UW Output. The 'Workbook Health' sheet is hidden by default — right-click any tab and choose 'Unhide' to access it for diagnostics, validation checks, and version pills.
A19: Property name entered at B5 above propagates to T12 Analytics via the Property_Name named range.

Sheet Dashboard
O1: Care Type | P1: Property | Q1: Market | AZ1: Underwriting at-a-glance KPI dashboard with embedded charts
B2: ="UNDERWRITING DASHBOARD"&IF(AND(ISTEXT(Cover!B5),Cover!B5<>"")," — "&Cover!B5,"") | O2: Independent Living | P2: =IFERROR(IF('T12 Analytics'!B6>0,'T12 Analytics'!B11/'T12 Analytics'!B6,NA()),NA()) | Q2: 0.91 | AZ2: Analytical (handoff)
B3: ="Period: "&IF(AND(ISTEXT('T12 Analytics'!E2),'T12 Analytics'!E2<>""),'T12 Analytics'!E2,"T12")&" | Basis: "&IF(AND(ISTEXT('T12 Analytics'!H2),'T12 Analytics'!H2<>""),'T12 Analytics'!H2,"As-Reported")&" | Refreshed: "&TEXT(TODAY(),"mmm d, yyyy") | O3: Assisted Living | P3: =IFERROR(IF('T12 Analytics'!C6>0,'T12 Analytics'!C11/'T12 Analytics'!C6,NA()),NA()) | Q3: 0.879 | AZ3: visible
O4: Memory Care | P4: =IFERROR(IF('T12 Analytics'!D6>0,'T12 Analytics'!D11/'T12 Analytics'!D6,NA()),NA()) | Q4: 0.88 | AZ4: v0.2.7
B5: OCCUPANCY | E5: EBITDARM MARGIN | H5: GOING-IN CAP RATE | K5: REVPOR | O5: Blended | P5: =IFERROR('T12 Analytics'!F134,NA()) | Q5: 0.895 | AZ5: All value cells are formula references into T12 Analytics, Rent Roll Recon, Monthly Trending, and Cover. 6 native Excel charts embedded. No source-of-truth data lives here. Supersedes the v0.2.4-v0.2.6 Investment Dashboard.
B6: =IFERROR(IF(ISNUMBER('T12 Analytics'!F134),TEXT('T12 Analytics'!F134,"0.0%"),"—"),"—") | E6: =IFERROR(IF(ISNUMBER('T12 Analytics'!F162),TEXT('T12 Analytics'!F162,"0.0%"),"—"),"—") | H6: =IFERROR(IF(ISNUMBER('T12 Analytics'!F118),TEXT('T12 Analytics'!F118,"0.00%"),"—"),"—") | K6: =IFERROR(IF(ISNUMBER('T12 Analytics'!F143),TEXT('T12 Analytics'!F143,"$#,##0"),"—"),"—")
B7: Normalized community occupancy | E7: Normalized (pre-mgmt fee) | H7: Normalized NOI / Purchase Price | K7: Normalized RevPOR per resident | O7: Payer | P7: Revenue
B8: =IF(ISNUMBER('T12 Analytics'!F134),IF('T12 Analytics'!F134>=0.9,"✓ At/above 90% stabilized hurdle",IF('T12 Analytics'!F134>=0.85,"⚠ Below stabilized, lease-up risk","✗ Distressed occupancy")),"— Source not populated") | E8: =IF(ISNUMBER('T12 Analytics'!F162),IF('T12 Analytics'!F162>=0.27,"✓ In-line with REIT SHOP avg ~27%",IF('T12 Analytics'!F162>=0.22,"⚠ Below institutional median","✗ Margin distressed")),"— Source not populated") | H8: =IF(ISNUMBER('T12 Analytics'!F118),IF('T12 Analytics'!F118>=0.07,"✓ Above 6.2% market avg",IF('T12 Analytics'!F118>=0.055,"⚠ At market, modest yield","✗ Below market, aggressive")),"— Source not populated") | K8: =IF(ISNUMBER('T12 Analytics'!F143),"vs blended market $5,500-$6,500","— Source not populated") | O8: Private Pay | P8: =IFERROR(IF(ISNUMBER(E43),E43,0),0)
B10: EFFECTIVE GROSS INCOME | E10: EBITDAR | H10: PRICE / BED
B11: =IFERROR(IF(ISNUMBER('T12 Analytics'!F52),TEXT('T12 Analytics'!F52,"$#,##0"),"—"),"—") | E11: =IFERROR(IF(ISNUMBER('T12 Analytics'!F163),TEXT('T12 Analytics'!F163,"$#,##0"),"—"),"—") | H11: =IFERROR(IF(AND(ISNUMBER('T12 Analytics'!F117),ISNUMBER('T12 Analytics'!E6),'T12 Analytics'!E6>0),TEXT('T12 Analytics'!F117/'T12 Analytics'!E6,"$#,##0"),"—"),"—")
B12: Annual revenue (T12) | E12: After mgmt fee (lender NOI) | H12: Purchase price / licensed bed
B13: =IF(ISNUMBER('T12 Analytics'!F52),"✓ EGI captured","— Source not populated") | E13: =IFERROR(IF(ISNUMBER('T12 Analytics'!F164),"Margin: "&TEXT('T12 Analytics'!F164,"0.0%"),"— Margin n/a"),"—") | H13: =IFERROR(IF(AND(ISNUMBER('T12 Analytics'!F117),ISNUMBER('T12 Analytics'!E6),'T12 Analytics'!E6>0),"on "&TEXT('T12 Analytics'!E6,"#,##0")&" licensed beds","— Source not populated"),"—")
O14: Medicaid | P14: =IFERROR(IF(ISNUMBER(E44),E44,0),0)
B15: OPERATING PERFORMANCE | O15: LTC Insurance | P15: =IFERROR(IF(ISNUMBER(E45),E45,0),0)
O16: VA | P16: =IFERROR(IF(ISNUMBER(E46),E46,0),0)
B17: CAPACITY & OCCUPANCY | E17: REVENUE & RATE | H17: PROFITABILITY | K17: COST STRUCTURE & LABOR | O17: Managed Care | P17: =IFERROR(IF(ISNUMBER(E47),E47,0),0)
B18: Licensed beds (total) | C18: =IFERROR(IF(ISNUMBER('T12 Analytics'!E6),'T12 Analytics'!E6,"—"),"—") | E18: Gross potential rent | F18: =IFERROR(IF(ISNUMBER('T12 Analytics'!F37),'T12 Analytics'!F37,"—"),"—") | H18: EBITDARM $ | I18: =IFERROR(IF(ISNUMBER('T12 Analytics'!F161),'T12 Analytics'!F161,"—"),"—") | K18: Total labor % EGI | L18: =IFERROR(IF(ISNUMBER('T12 Analytics'!F148),'T12 Analytics'!F148,"—"),"—") | O18: Self-Pay | P18: =IFERROR(IF(ISNUMBER(E48),E48,0),0)
B19: IL / AL / MC | C19: =IFERROR(IF(ISNUMBER('T12 Analytics'!B6),TEXT('T12 Analytics'!B6,"0")&" / "&TEXT('T12 Analytics'!C6,"0")&" / "&TEXT('T12 Analytics'!D6,"0"),"—"),"—") | E19: Effective gross income | F19: =IFERROR(IF(ISNUMBER('T12 Analytics'!F52),'T12 Analytics'!F52,"—"),"—") | H19: EBITDARM margin | I19: =IFERROR(IF(ISNUMBER('T12 Analytics'!F162),'T12 Analytics'!F162,"—"),"—") | K19: Direct labor % EGI | L19: =IFERROR(IF(ISNUMBER('T12 Analytics'!F149),'T12 Analytics'!F149,"—"),"—") | O19: Other | P19: =IFERROR(IF(ISNUMBER(E49),E49,0),0)
B20: Avg occupied beds | C20: =IFERROR(IF(ISNUMBER('T12 Analytics'!E11),'T12 Analytics'!E11,"—"),"—") | E20: Blended ADR / day | F20: =IFERROR(IF(ISNUMBER('T12 Analytics'!F140),'T12 Analytics'!F140,"—"),"—") | H20: EBITDAR $ (post mgmt fee) | I20: =IFERROR(IF(ISNUMBER('T12 Analytics'!F163),'T12 Analytics'!F163,"—"),"—") | K20: Overtime % | L20: =IFERROR(IF(ISNUMBER('T12 Analytics'!F150),'T12 Analytics'!F150,"—"),"—")
B21: Community occupancy % | C21: =IFERROR(IF(ISNUMBER('T12 Analytics'!F134),'T12 Analytics'!F134,"—"),"—") | E21: RevPOR (blended) | F21: =IFERROR(IF(ISNUMBER('T12 Analytics'!F143),'T12 Analytics'!F143,"—"),"—") | H21: EBITDAR margin | I21: =IFERROR(IF(ISNUMBER('T12 Analytics'!F164),'T12 Analytics'!F164,"—"),"—") | K21: Agency labor % | L21: =IFERROR(IF(ISNUMBER('T12 Analytics'!F152),'T12 Analytics'!F152,"—"),"—")
B22: Economic occupancy % | C22: =IFERROR(IF(ISNUMBER('Rent Roll Recon'!E13),'Rent Roll Recon'!E13,"—"),"—") | E22: RevPAB | F22: =IFERROR(IF(ISNUMBER('T12 Analytics'!F145),'T12 Analytics'!F145,"—"),"—") | H22: EGI / occupied bed | I22: =IFERROR(IF(ISNUMBER('T12 Analytics'!F144),'T12 Analytics'!F144,"—"),"—") | K22: Food PPD | L22: =IFERROR(IF(ISNUMBER('T12 Analytics'!F154),'T12 Analytics'!F154,"—"),"—")
B23: Loss to lease % | C23: =IFERROR(IF(AND(ISNUMBER('T12 Analytics'!F41),ISNUMBER('T12 Analytics'!F37),'T12 Analytics'!F37<>0),ABS('T12 Analytics'!F41)/'T12 Analytics'!F37,"—"),"—") | E23: Level of care % | F23: =IFERROR(IF(ISNUMBER('T12 Analytics'!F146),'T12 Analytics'!F146,"—"),"—") | H23: Opex / occupied bed | I23: =IFERROR(IF(ISNUMBER('T12 Analytics'!F160),'T12 Analytics'!F160,"—"),"—") | K23: Mgmt fee % | L23: =IFERROR(IF(ISNUMBER('T12 Analytics'!F157),'T12 Analytics'!F157,"—"),"—")
B24: Vacancy % | C24: =IFERROR(IF(AND(ISNUMBER('T12 Analytics'!F38),ISNUMBER('T12 Analytics'!F37),'T12 Analytics'!F37<>0),ABS('T12 Analytics'!F38)/'T12 Analytics'!F37,"—"),"—") | E24: Bad debt % | F24: =IFERROR(IF(ISNUMBER('T12 Analytics'!F158),'T12 Analytics'!F158,"—"),"—") | H24: Total opex $ | I24: =IFERROR(IF(ISNUMBER('T12 Analytics'!F105),'T12 Analytics'!F105,"—"),"—") | K24: Insurance (P&C) % | L24: =IFERROR(IF(ISNUMBER('T12 Analytics'!F159),'T12 Analytics'!F159,"—"),"—")
B26: VALUATION & MARKET BENCHMARKING
B28: DEAL ECONOMICS | H28: OCCUPANCY vs MARKET (NIC MAP Q1 2026)
B29: Metric | D29: Property | E29: Market | F29: Read
B30: Purchase price | D30: =IFERROR(IF(ISNUMBER('T12 Analytics'!F117),'T12 Analytics'!F117,"—"),"—") | E30: n/a | F30: —
B31: Price / total bed | D31: =IFERROR(IF(AND(ISNUMBER('T12 Analytics'!F117),ISNUMBER('T12 Analytics'!E6),'T12 Analytics'!E6>0),'T12 Analytics'!F117/'T12 Analytics'!E6,"—"),"—") | E31: $220-280k | F31: =IF(ISNUMBER(D31),IF(D31<=280000,"✓",IF(D31<=350000,"⚠","✗")),"—")
B32: Going-in cap rate | D32: =IFERROR(IF(ISNUMBER('T12 Analytics'!F118),'T12 Analytics'!F118,"—"),"—") | E32: 0.062 | F32: =IF(ISNUMBER(D32),IF(D32>=0.07,"✓",IF(D32>=0.055,"⚠","✗")),"—")
B33: EBITDAR cap rate | D33: =IFERROR(IF(ISNUMBER('T12 Analytics'!F120),'T12 Analytics'!F120,"—"),"—") | E33: 5.7-6.5% | F33: =IF(ISNUMBER(D33),IF(D33>=0.065,"✓",IF(D33>=0.055,"⚠","✗")),"—")
B34: EBITDARM margin | D34: =IFERROR(IF(ISNUMBER('T12 Analytics'!F162),'T12 Analytics'!F162,"—"),"—") | E34: 0.27 | F34: =IF(ISNUMBER(D34),IF(D34>=0.27,"✓",IF(D34>=0.22,"⚠","✗")),"—")
B35: Community occupancy | D35: =IFERROR(IF(ISNUMBER('T12 Analytics'!F134),'T12 Analytics'!F134,"—"),"—") | E35: 0.895 | F35: =IF(ISNUMBER(D35),IF(D35>=0.9,"✓",IF(D35>=0.85,"⚠","✗")),"—")
B36: Labor % EGI | D36: =IFERROR(IF(ISNUMBER('T12 Analytics'!F148),'T12 Analytics'!F148,"—"),"—") | E36: 43-45% | F36: =IF(ISNUMBER(D36),IF(D36<=0.45,"✓",IF(D36<=0.5,"⚠","✗")),"—")
B37: Agency labor % | D37: =IFERROR(IF(ISNUMBER('T12 Analytics'!F152),'T12 Analytics'!F152,"—"),"—") | E37: <3% | F37: =IF(ISNUMBER(D37),IF(D37<=0.03,"✓",IF(D37<=0.06,"⚠","✗")),"—")
B39: PAYER MIX
B41: Payer Mix — Revenue & Census | H41: Payer Mix — Revenue Share
B42: Payer Type | C42: Resident Count | D42: % of Census | E42: Revenue (T12) | F42: % of Revenue
B43: Private Pay | C43: =IFERROR(IF(ISNUMBER('Rent Roll Recon'!B40),'Rent Roll Recon'!B40,"—"),"—") | D43: =IFERROR(IF(ISNUMBER('Rent Roll Recon'!C40),'Rent Roll Recon'!C40,"—"),"—") | E43: =IFERROR(IF(ISNUMBER('Rent Roll Recon'!H40),'Rent Roll Recon'!H40,"—"),"—") | F43: =IFERROR(IF(ISNUMBER('Rent Roll Recon'!I40),'Rent Roll Recon'!I40,"—"),"—")
B44: Medicaid | C44: =IFERROR(IF(ISNUMBER('Rent Roll Recon'!B41),'Rent Roll Recon'!B41,"—"),"—") | D44: =IFERROR(IF(ISNUMBER('Rent Roll Recon'!C41),'Rent Roll Recon'!C41,"—"),"—") | E44: =IFERROR(IF(ISNUMBER('Rent Roll Recon'!H41),'Rent Roll Recon'!H41,"—"),"—") | F44: =IFERROR(IF(ISNUMBER('Rent Roll Recon'!I41),'Rent Roll Recon'!I41,"—"),"—")
B45: LTC Insurance | C45: =IFERROR(IF(ISNUMBER('Rent Roll Recon'!B42),'Rent Roll Recon'!B42,"—"),"—") | D45: =IFERROR(IF(ISNUMBER('Rent Roll Recon'!C42),'Rent Roll Recon'!C42,"—"),"—") | E45: =IFERROR(IF(ISNUMBER('Rent Roll Recon'!H42),'Rent Roll Recon'!H42,"—"),"—") | F45: =IFERROR(IF(ISNUMBER('Rent Roll Recon'!I42),'Rent Roll Recon'!I42,"—"),"—")
...

Sheet T12 Analytics
A1: ALF T12 Analytics — Underwriting Supplement | AZ1: Per-Label T12 aggregation; main feed for UW Output
A2: Property Name: | B2: =IFERROR(IF(LEN(TRIM('Rent Roll Input'!A3))>0,'Rent Roll Input'!A3,IF(LEN(TRIM('T12 Input'!A10))>0,'T12 Input'!A10,Property_Name)),Property_Name) | D2: T12 Period Ending: | E2: =IFERROR(LOOKUP(2,1/('T12 Input'!$C$11:$N$11<>""),'T12 Input'!$C$11:$N$11),"") | G2: Basis: | H2: ACCRUAL | AZ2: aggregator
AZ3: visible
A4: SECTION 1 · PROPERTY CAPACITY — IL / AL / MC | AZ4: v0.2.7
B5: Independent Living (IL) | C5: Assisted Living (AL) | D5: Memory Care (MC) | E5: Total | H5: Notes
A6: Licensed beds (total) | B6: ='Rent Roll Recon'!B7 | C6: ='Rent Roll Recon'!C7 | D6: ='Rent Roll Recon'!D7 | E6: =SUM(B6:D6) | H6: Licensed / available beds per certificate
A7: Avg occupied beds (T12) | B7: =IFERROR(IF('Rent Roll Recon'!B34>0,'Rent Roll Recon'!B34,0),0) | C7: =IFERROR(IF('Rent Roll Recon'!C35>0,'Rent Roll Recon'!C35,0),0) | D7: =IFERROR(IF('Rent Roll Recon'!D36>0,'Rent Roll Recon'!D36,0),0) | E7: =SUM(B7:D7) | H7: Auto-filled from Rent Roll Recon when period selected (Sections E). Override directly if needed.
A8: Physical occupancy % (T12) | B8: =IFERROR(B7/B6,"-") | C8: =IFERROR(C7/C6,"-") | D8: =IFERROR(D7/D6,"-") | E8: =IFERROR(E7/E6,"-") | H8: Avg occ. beds ÷ licensed beds
A10: Target occupancy % (stabilized) | C10: 0 | E10: =IFERROR((B6*B10+C6*C10+D6*D10)/E6,"-") | H10: Target: 87–92% stabilized for AL/MC; 90%+ for IL
A11: Stabilized occupied beds | B11: =IFERROR(B6*B10,"-") | C11: =IFERROR(C6*C10,"-") | D11: =IFERROR(D6*D10,"-") | E11: =IFERROR(SUM(B11:D11),"-") | H11: Licensed beds × target occupancy %
A13: SECTION 2 · REVENUE ANALYSIS — T12 ACTUAL → NORMALIZED
B14: IL | C14: AL | D14: MC | E14: T12 Total | F14: Normalized | G14: Delta | H14: Notes / Flag
A15: Base Rent | K15: =IF(OR('Rent Roll Recon'!B12<0.85,'Rent Roll Recon'!C12<0.85,'Rent Roll Recon'!D12<0.85),"⚠ One or more care types below 85% physical occupancy — investigate stabilization assumptions.","✓ All care types ≥ 85% physical occupancy.") | P15: =IF('Rent Roll Recon'!E41>0.3,"⚠ Medicaid revenue share "&TEXT('Rent Roll Recon'!E41,"0.0%")&" — reimbursement rate risk; verify stabilized assumption.",IF('Rent Roll Recon'!E44>0.25,"⚠ Managed Care revenue share "&TEXT('Rent Roll Recon'!E44,"0.0%")&" — verify per-diem rates vs. private pay.","✓ Payer mix dominated by private pay / low reimbursement risk."))
A16: T12 base rent (actual) | B16: =IFERROR(INDEX('T12 Raw Data'!R:R,MATCH("Base rent — IL",'T12 Raw Data'!B:B,0)),0) | C16: =IFERROR(INDEX('T12 Raw Data'!R:R,MATCH("Base rent — AL",'T12 Raw Data'!B:B,0)),0) | D16: =IFERROR(INDEX('T12 Raw Data'!R:R,MATCH("Base rent — MC",'T12 Raw Data'!B:B,0)),0) | E16: =SUM(B16:D16) | H16: Gross base rent from T12 Raw Data
A17: Avg daily rate (T12 back-calc) | B17: =IFERROR(B16/(B7*12),"-") | C17: =IFERROR(C16/(C7*12),"-") | D17: =IFERROR(D16/(D7*12),"-") | E17: =IFERROR(E16/(E7*12),"-") | H17: T12 base rent ÷ avg occ. beds ÷ 12 months
A19: Stabilized monthly rate / bed | B19: =B17 | C19: =C17 | D19: =D17 | E19: =IFERROR((B11*B19+C11*C19+D11*D19)/E11,"-") | H19: Blended stabilized rate weighted by occupied beds
A20: Stabilized annual base rent | B20: =IFERROR(B6*B10*B19*12,0) | C20: =IFERROR(C6*C10*C19*12,0) | D20: =IFERROR(D6*D10*D19*12,0) | E20: =SUM(B20:D20) | F20: =E20 | G20: =F20-E16 | H20: Beds × occ% × monthly rate × 12 (per care type)
A22: Level of Care (LOC) Revenue
A23: T12 LOC revenue (actual) | B23: =IFERROR(INDEX('T12 Raw Data'!R:R,MATCH("LOC revenue — IL",'T12 Raw Data'!B:B,0)),0) | C23: =IFERROR(INDEX('T12 Raw Data'!R:R,MATCH("LOC revenue — AL",'T12 Raw Data'!B:B,0)),0) | D23: =IFERROR(INDEX('T12 Raw Data'!R:R,MATCH("LOC revenue — MC",'T12 Raw Data'!B:B,0)),0) | E23: =SUM(B23:D23) | H23: Care rate / level of care charges from T12
A24: LOC per occ. bed / month (T12) | B24: =IFERROR(B23/(B7*12),"-") | C24: =IFERROR(C23/(C7*12),"-") | D24: =IFERROR(D23/(D7*12),"-") | E24: =IFERROR(E23/(E7*12),"-") | H24: Validate vs. care level assessments; MC should be highest
A26: Stabilized LOC / occ. bed / month | C26: =C24 | E26: =IFERROR((B11*B26+C11*C26+D11*D26)/E11,"-") | H26: =IF(E24<>"-","T12 actual LOC/occ bed: "&TEXT(E24,"$#,##0.00")&"/mo blended (AL: "&TEXT(C24,"$#,##0.00")&"). Enter stabilized rate in B26/C26/D26. Default to T12 unless acuity mix change is justified.","Enter stabilized LOC/bed in B26/C26/D26.")
A27: Stabilized LOC revenue | B27: =IFERROR(B6*B10*B26*12,0) | C27: =IFERROR(C6*C10*C26*12,0) | D27: =IFERROR(D6*D10*D26*12,0) | E27: =SUM(B27:D27) | F27: =E27 | G27: =F27-E23
A29: Revenue Quality Ratios
A30: LOC as % of base rent (T12) | B30: =IFERROR(B23/B16,"-") | C30: =IFERROR(C23/C16,"-") | D30: =IFERROR(D23/D16,"-") | E30: =IFERROR(E23/E16,"-") | H30: Higher = higher acuity mix; validate vs. care assessments | K30: =IF(LEN('Rent Roll Recon'!B96)=0,"-",IF(IFERROR(VALUE(SUBSTITUTE('Rent Roll Recon'!B96,"%",""))/100,0)>0.25,"⚠ IL rate dispersion CV "&TEXT(IFERROR(VALUE(SUBSTITUTE('Rent Roll Recon'!B96,"%",""))/100,0),"0.0%")&" — wide spread may indicate legacy in-place rates.","✓ IL rate dispersion within normal band.")) | P30: =IFERROR(IF(AVERAGE(T54:V54)>AVERAGE(K54:M54)*1.05,"↑ Revenue trending up — latest 3-mo avg "&TEXT(AVERAGE(T54:V54),"$#,##0")&" vs prior 3-mo "&TEXT(AVERAGE(K54:M54),"$#,##0"),IF(AVERAGE(T54:V54)<AVERAGE(K54:M54)*0.95,"↓ Revenue trending down — latest 3-mo avg "&TEXT(AVERAGE(T54:V54),"$#,##0")&" vs prior 3-mo "&TEXT(AVERAGE(K54:M54),"$#,##0"),"→ Revenue stable — within ±5% of prior 3-mo.")),"Insufficient T12 data for trend.")
A31: RevPOR (T12 actual) — base + LOC | B31: =IFERROR((B16+B23)/(B7*12),"-") | C31: =IFERROR((C16+C23)/(C7*12),"-") | D31: =IFERROR((D16+D23)/(D7*12),"-") | E31: =IFERROR((E16+E23)/(E7*12),"-") | H31: Revenue per occupied room per month (base + LOC)
A32: RevPOR (normalized) — base + LOC | B32: =IFERROR((B20+B27)/(B11*12),"-") | C32: =IFERROR((C20+C27)/(C11*12),"-") | D32: =IFERROR((D20+D27)/(D11*12),"-") | E32: =IFERROR((E20+E27)/(E11*12),"-") | H32: Normalized RevPOR — stabilized beds and rates
A34: GPR Revenue Waterfall — Rent Roll projection vs. T12 reported
B35: IL | C35: AL | D35: MC | E35: T12 Reported | F35: RR Projection | G35: Delta | H35: Notes
A36: Market rate / bed / month (from rent roll col G, occupied beds) | B36: =IFERROR(AVERAGEIFS('Rent Roll Input'!$G$7:$G$606,'Rent Roll Input'!$S$7:$S$606,'Rent Roll Recon'!$B$2,'Rent Roll Input'!$E$7:$E$606,"Occupied",'Rent Roll Input'!$D$7:$D$606,"IL"),0) | C36: =IFERROR(AVERAGEIFS('Rent Roll Input'!$G$7:$G$606,'Rent Roll Input'!$S$7:$S$606,'Rent Roll Recon'!$B$2,'Rent Roll Input'!$E$7:$E$606,"Occupied",'Rent Roll Input'!$D$7:$D$606,"AL"),0) | D36: =IFERROR(AVERAGEIFS('Rent Roll Input'!$G$7:$G$606,'Rent Roll Input'!$S$7:$S$606,'Rent Roll Recon'!$B$2,'Rent Roll Input'!$E$7:$E$606,"Occupied",'Rent Roll Input'!$D$7:$D$606,"MC"),0) | E36: — | F36: =IFERROR((B6*B36+C6*C36+D6*D36)/E6,"-") | G36: — | H36: Avg market rate for occupied beds from Rent Roll col G, selected period. Override B–D directly. T12 does not report market rates — col E blank by design.
A37: Gross Potential Rent (GPR) — base rent, 100% occupied at market rate | B37: =IFERROR(B6*B36*12,0) | C37: =IFERROR(C6*C36*12,0) | D37: =IFERROR(D6*D36*12,0) | E37: =IFERROR(IF(INDEX('T12 Raw Data'!R:R,MATCH("Gross Rent Revenue",'T12 Raw Data'!B:B,0))=0,"",INDEX('T12 Raw Data'!R:R,MATCH("Gross Rent Revenue",'T12 Raw Data'!B:B,0))),"") | F37: =SUM(B37:D37) | G37: =IFERROR(IF(E37="","",E37-F37),"") | H37: T12 col: pulled from T12 Raw Data — blank if no GPR line reported. RR Projection: licensed beds × avg market rate (rent roll) × 12. Delta: T12 minus RR.
A38: Less: Physical vacancy loss | B38: =IFERROR((B6-B7)*B36*12,0) | C38: =IFERROR((C6-C7)*C36*12,0) | D38: =IFERROR((D6-D7)*D36*12,0) | E38: =IFERROR(IF(ABS('T12 Raw Data'!$R$61)>0,ABS('T12 Raw Data'!$R$61),F38),F38) | F38: =SUM(B38:D38) | G38: =IFERROR(IF(E38="","",E38-F38),"") | H38: =IF(AND(E37<>"",ABS('T12 Raw Data'!$R$61)>0),"T12 check: GPR−Vacancy−Collected = "&TEXT(E37-E38-E16,"$#,##0")&" (0=clean)","T12 vacancy not reported — using RR projection")
A39: Physical vacancy rate % | B39: =IFERROR((B6-B7)/B6,"-") | C39: =IFERROR((C6-C7)/C6,"-") | D39: =IFERROR((D6-D7)/D6,"-") | E39: =IFERROR(IF(AND(E37<>"",ABS('T12 Raw Data'!$R$61)>0),E38/E37,IFERROR((E6-E7)/E6,"-")),IFERROR((E6-E7)/E6,"-")) | F39: =IFERROR((E6-E11)/E6,"-") | G39: =IFERROR(IF(ISNUMBER(E39),F39-E39,"-"),"-") | H39: T12: (licensed − avg occupied) / licensed. RR Projection: (licensed − stabilized target) / licensed. Flag if >20%.
A40: Less: Loss to lease (occupied beds priced below market rate) | B40: =IFERROR(B37-B38-B16,0) | C40: =IFERROR(C37-C38-C16,0) | D40: =IFERROR(D37-D38-D16,0) | E40: =IFERROR(IF(ABS('T12 Raw Data'!$R$62)>0,ABS('T12 Raw Data'!$R$62),F37-F38-E16),F37-F38-E16) | F40: =SUM(B40:D40) | G40: =IFERROR(IF(E40="","",E40-F40),"") | H40: ⚠ RR: occupied beds × market rate × 12 minus T12 collected base rent. Captures concessions, rate-lock, and below-market pricing. T12 col requires GPR line.
A41: Loss to lease as % of GPR | B41: =IFERROR(B40/B37,"-") | C41: =IFERROR(C40/C37,"-") | D41: =IFERROR(D40/D37,"-") | E41: =IFERROR(IF(E37<>"",E40/E37,IF(F37>0,E40/F37,"-")),"-") | F41: =IFERROR(F40/F37,"-") | G41: =IFERROR(E41-F41,"") | H41: ⚠ Flag if RR projection >5% — below-market pricing or heavy concessions. T12 col requires GPR line.
A45: Other Revenue — Normalization Bridge | K45: =IF('Rent Roll Recon'!D67=0,"Property has no AL acuity data — flat-rate AL or unpopulated.",IF(MAX('Rent Roll Recon'!D59:D66)/'Rent Roll Recon'!D67>0.5,"⚠ Acuity skewed: top tier > 50% of AL care charges — verify staffing model.","✓ Acuity distribution within normal range."))
A46: Revenue Item | E46: T12 Actual | F46: Normalized | G46: Delta | H46: Flag / Note | K46: (hidden helper — rate buckets for V2 chart)
A47: Community / move-in fees | E47: =IFERROR(INDEX('T12 Raw Data'!R:R,MATCH("Community / move-in fees",'T12 Raw Data'!B:B,0)),0) | F47: 0 | G47: =F47-E47 | H47: ⚠ ONE-TIME — normalize to $0; model separately if absorption schedule exists | K47: Bucket | L47: IL | M47: AL | N47: MC
A48: Concessions & move-in specials | E48: =IFERROR(INDEX('T12 Raw Data'!R:R,MATCH("Concessions & specials",'T12 Raw Data'!B:B,0)),0) | F48: 0 | G48: =F48-E48 | H48: ⚠ BURN-OFF — normalize to $0 at stabilized occupancy | K48: $0 – $1,999 | L48: =COUNTIFS('Rent Roll Input'!$S$7:$S$606,'Rent Roll Recon'!$B$2,'Rent Roll Input'!$E$7:$E$606,"<>Vacant",'Rent Roll Input'!$E$7:$E$606,"<>Eviction",'Rent Roll Input'!$H$7:$H$606,">="&0,'Rent Roll Input'!$H$7:$H$606,"<="&1999.99,'Rent Roll Input'!$D$7:$D$606,"IL") | M48: =COUNTIFS('Rent Roll Input'!$S$7:$S$606,'Rent Roll Recon'!$B$2,'Rent Roll Input'!$E$7:$E$606,"<>Vacant",'Rent Roll Input'!$E$7:$E$606,"<>Eviction",'Rent Roll Input'!$H$7:$H$606,">="&0,'Rent Roll Input'!$H$7:$H$606,"<="&1999.99,'Rent Roll Input'!$D$7:$D$606,"AL") | N48: =COUNTIFS('Rent Roll Input'!$S$7:$S$606,'Rent Roll Recon'!$B$2,'Rent Roll Input'!$E$7:$E$606,"<>Vacant",'Rent Roll Input'!$E$7:$E$606,"<>Eviction",'Rent Roll Input'!$H$7:$H$606,">="&0,'Rent Roll Input'!$H$7:$H$606,"<="&1999.99,'Rent Roll Input'!$D$7:$D$606,"MC")
A49: Respite care | E49: =IFERROR(INDEX('T12 Raw Data'!R:R,MATCH("Respite care",'T12 Raw Data'!B:B,0)),0) | F49: 0 | G49: =F49-E49 | H49: ⚠ VOLATILE — assess program; include only if documented & consistent | K49: $2,000 – $3,999 | L49: =COUNTIFS('Rent Roll Input'!$S$7:$S$606,'Rent Roll Recon'!$B$2,'Rent Roll Input'!$E$7:$E$606,"<>Vacant",'Rent Roll Input'!$E$7:$E$606,"<>Eviction",'Rent Roll Input'!$H$7:$H$606,">="&2000,'Rent Roll Input'!$H$7:$H$606,"<="&3999.99,'Rent Roll Input'!$D$7:$D$606,"IL") | M49: =COUNTIFS('Rent Roll Input'!$S$7:$S$606,'Rent Roll Recon'!$B$2,'Rent Roll Input'!$E$7:$E$606,"<>Vacant",'Rent Roll Input'!$E$7:$E$606,"<>Eviction",'Rent Roll Input'!$H$7:$H$606,">="&2000,'Rent Roll Input'!$H$7:$H$606,"<="&3999.99,'Rent Roll Input'!$D$7:$D$606,"AL") | N49: =COUNTIFS('Rent Roll Input'!$S$7:$S$606,'Rent Roll Recon'!$B$2,'Rent Roll Input'!$E$7:$E$606,"<>Vacant",'Rent Roll Input'!$E$7:$E$606,"<>Eviction",'Rent Roll Input'!$H$7:$H$606,">="&2000,'Rent Roll Input'!$H$7:$H$606,"<="&3999.99,'Rent Roll Input'!$D$7:$D$606,"MC")
A50: Other community revenue | E50: =IFERROR(INDEX('T12 Raw Data'!R:R,MATCH("Other community revenue",'T12 Raw Data'!B:B,0)),0) | F50: 0 | G50: =F50-E50 | H50: Beautician, utility reimbursement, admin fees, finance charges | K50: $4,000 – $5,999 | L50: =COUNTIFS('Rent Roll Input'!$S$7:$S$606,'Rent Roll Recon'!$B$2,'Rent Roll Input'!$E$7:$E$606,"<>Vacant",'Rent Roll Input'!$E$7:$E$606,"<>Eviction",'Rent Roll Input'!$H$7:$H$606,">="&4000,'Rent Roll Input'!$H$7:$H$606,"<="&5999.99,'Rent Roll Input'!$D$7:$D$606,"IL") | M50: =COUNTIFS('Rent Roll Input'!$S$7:$S$606,'Rent Roll Recon'!$B$2,'Rent Roll Input'!$E$7:$E$606,"<>Vacant",'Rent Roll Input'!$E$7:$E$606,"<>Eviction",'Rent Roll Input'!$H$7:$H$606,">="&4000,'Rent Roll Input'!$H$7:$H$606,"<="&5999.99,'Rent Roll Input'!$D$7:$D$606,"AL") | N50: =COUNTIFS('Rent Roll Input'!$S$7:$S$606,'Rent Roll Recon'!$B$2,'Rent Roll Input'!$E$7:$E$606,"<>Vacant",'Rent Roll Input'!$E$7:$E$606,"<>Eviction",'Rent Roll Input'!$H$7:$H$606,">="&4000,'Rent Roll Input'!$H$7:$H$606,"<="&5999.99,'Rent Roll Input'!$D$7:$D$606,"MC")
...

Sheet T12 Input
A1: T12 Input — Paste T12 data here | AZ1: T12 raw paste area (MRI / Yardi / normalizer output)
AZ2: input
A3: How to use — no setup, no refresh, instant results | AZ3: visible
A4: 1. Upload this Analyzer + your raw T12 to the Streamlit app. | AZ4: v0.2.7
A5: 2. Map any UNMATCHED descriptions in-app before downloading.
A6: 3. Open the populated Analyzer — Coverage Check (col P) confirms all rows mapped.
A7: 4. Mappings persist in Description_Map for next upload.
A9: Layout: Account # (col A, optional, populated for Yardi-style T12s only), Description (col B, required), 12 months (cols C-N), T12 Total (col O). Headers in row 11 reflect the source T12 period.
A11: Account # | B11: Description | O11: T12 Total | P11: Coverage Check
P12: =IF(TRIM(B12)<>"",IFERROR(INDEX(DescMap_Label,MATCH(TRIM(B12),DescMap_Description,0)),"UNMATCHED"),"")
P13: =IF(TRIM(B13)<>"",IFERROR(INDEX(DescMap_Label,MATCH(TRIM(B13),DescMap_Description,0)),"UNMATCHED"),"")
P14: =IF(TRIM(B14)<>"",IFERROR(INDEX(DescMap_Label,MATCH(TRIM(B14),DescMap_Description,0)),"UNMATCHED"),"")
P15: =IF(TRIM(B15)<>"",IFERROR(INDEX(DescMap_Label,MATCH(TRIM(B15),DescMap_Description,0)),"UNMATCHED"),"")
P16: =IF(TRIM(B16)<>"",IFERROR(INDEX(DescMap_Label,MATCH(TRIM(B16),DescMap_Description,0)),"UNMATCHED"),"")
P17: =IF(TRIM(B17)<>"",IFERROR(INDEX(DescMap_Label,MATCH(TRIM(B17),DescMap_Description,0)),"UNMATCHED"),"")
P18: =IF(TRIM(B18)<>"",IFERROR(INDEX(DescMap_Label,MATCH(TRIM(B18),DescMap_Description,0)),"UNMATCHED"),"")
P19: =IF(TRIM(B19)<>"",IFERROR(INDEX(DescMap_Label,MATCH(TRIM(B19),DescMap_Description,0)),"UNMATCHED"),"")
P20: =IF(TRIM(B20)<>"",IFERROR(INDEX(DescMap_Label,MATCH(TRIM(B20),DescMap_Description,0)),"UNMATCHED"),"")
P21: =IF(TRIM(B21)<>"",IFERROR(INDEX(DescMap_Label,MATCH(TRIM(B21),DescMap_Description,0)),"UNMATCHED"),"")
P22: =IF(TRIM(B22)<>"",IFERROR(INDEX(DescMap_Label,MATCH(TRIM(B22),DescMap_Description,0)),"UNMATCHED"),"")
P23: =IF(TRIM(B23)<>"",IFERROR(INDEX(DescMap_Label,MATCH(TRIM(B23),DescMap_Description,0)),"UNMATCHED"),"")
... P511: =IF(TRIM(B511)<>"",IFERROR(INDEX(DescMap_Label,MATCH(TRIM(B511),DescMap_Description,0)),"UNMATCHED"),"")

Sheet T12 Raw Data
A1: T12 Raw Data — auto-calculated from T12 Input descriptions | AZ1: Description→Label rollup with monthly trending
A2: Matches T12 Input col B descriptions against Description_Map. UNMATCHED rows in T12 Input col P are not included here. Add missing descriptions to Description_Map tab to capture them. | AZ2: aggregator
AZ3: visible
A4: Section | B4: Label | C4: Care | D4: Flag | E4: Matched Descriptions | F4: M01 | G4: M02 | H4: M03 | I4: M04 | J4: M05 | K4: M06 | L4: M07 | M4: M08 | N4: M09 | O4: M10 | P4: M11 | Q4: M12 | R4: T12_Total | AZ4: v0.2.7
A6: Revenue | B6: Base rent — IL | C6: IL | E6: IL Base Rate Income | Independent Living Base Rate | F6: =SUMIF(T12_Calc!$N$1:$N$505,"Base rent — IL",T12_Calc!$B$1:$B$505) | G6: =SUMIF(T12_Calc!$N$1:$N$505,"Base rent — IL",T12_Calc!$C$1:$C$505) | H6: =SUMIF(T12_Calc!$N$1:$N$505,"Base rent — IL",T12_Calc!$D$1:$D$505) | I6: =SUMIF(T12_Calc!$N$1:$N$505,"Base rent — IL",T12_Calc!$E$1:$E$505) | J6: =SUMIF(T12_Calc!$N$1:$N$505,"Base rent — IL",T12_Calc!$F$1:$F$505) | K6: =SUMIF(T12_Calc!$N$1:$N$505,"Base rent — IL",T12_Calc!$G$1:$G$505) | L6: =SUMIF(T12_Calc!$N$1:$N$505,"Base rent — IL",T12_Calc!$H$1:$H$505) | M6: =SUMIF(T12_Calc!$N$1:$N$505,"Base rent — IL",T12_Calc!$I$1:$I$505) | N6: =SUMIF(T12_Calc!$N$1:$N$505,"Base rent — IL",T12_Calc!$J$1:$J$505) | O6: =SUMIF(T12_Calc!$N$1:$N$505,"Base rent — IL",T12_Calc!$K$1:$K$505) | P6: =SUMIF(T12_Calc!$N$1:$N$505,"Base rent — IL",T12_Calc!$L$1:$L$505) | Q6: =SUMIF(T12_Calc!$N$1:$N$505,"Base rent — IL",T12_Calc!$M$1:$M$505) | R6: =SUM(F6:Q6)
A7: Revenue | B7: Base rent — AL | C7: AL | E7: AL Base Rate Income | AL Base Rate | Assisted Living Base Rate | Assisted Living Revenue | F7: =SUMIF(T12_Calc!$N$1:$N$505,"Base rent — AL",T12_Calc!$B$1:$B$505) | G7: =SUMIF(T12_Calc!$N$1:$N$505,"Base rent — AL",T12_Calc!$C$1:$C$505) | H7: =SUMIF(T12_Calc!$N$1:$N$505,"Base rent — AL",T12_Calc!$D$1:$D$505) | I7: =SUMIF(T12_Calc!$N$1:$N$505,"Base rent — AL",T12_Calc!$E$1:$E$505) | J7: =SUMIF(T12_Calc!$N$1:$N$505,"Base rent — AL",T12_Calc!$F$1:$F$505) | K7: =SUMIF(T12_Calc!$N$1:$N$505,"Base rent — AL",T12_Calc!$G$1:$G$505) | L7: =SUMIF(T12_Calc!$N$1:$N$505,"Base rent — AL",T12_Calc!$H$1:$H$505) | M7: =SUMIF(T12_Calc!$N$1:$N$505,"Base rent — AL",T12_Calc!$I$1:$I$505) | N7: =SUMIF(T12_Calc!$N$1:$N$505,"Base rent — AL",T12_Calc!$J$1:$J$505) | O7: =SUMIF(T12_Calc!$N$1:$N$505,"Base rent — AL",T12_Calc!$K$1:$K$505) | P7: =SUMIF(T12_Calc!$N$1:$N$505,"Base rent — AL",T12_Calc!$L$1:$L$505) | Q7: =SUMIF(T12_Calc!$N$1:$N$505,"Base rent — AL",T12_Calc!$M$1:$M$505) | R7: =SUM(F7:Q7)
A8: Revenue | B8: Base rent — MC | C8: MC | E8: ALZ Base Rate Income | Memory Care Base Rate Income | MC Base Rate Income | Memory Care Revenue | F8: =SUMIF(T12_Calc!$N$1:$N$505,"Base rent — MC",T12_Calc!$B$1:$B$505) | G8: =SUMIF(T12_Calc!$N$1:$N$505,"Base rent — MC",T12_Calc!$C$1:$C$505) | H8: =SUMIF(T12_Calc!$N$1:$N$505,"Base rent — MC",T12_Calc!$D$1:$D$505) | I8: =SUMIF(T12_Calc!$N$1:$N$505,"Base rent — MC",T12_Calc!$E$1:$E$505) | J8: =SUMIF(T12_Calc!$N$1:$N$505,"Base rent — MC",T12_Calc!$F$1:$F$505) | K8: =SUMIF(T12_Calc!$N$1:$N$505,"Base rent — MC",T12_Calc!$G$1:$G$505) | L8: =SUMIF(T12_Calc!$N$1:$N$505,"Base rent — MC",T12_Calc!$H$1:$H$505) | M8: =SUMIF(T12_Calc!$N$1:$N$505,"Base rent — MC",T12_Calc!$I$1:$I$505) | N8: =SUMIF(T12_Calc!$N$1:$N$505,"Base rent — MC",T12_Calc!$J$1:$J$505) | O8: =SUMIF(T12_Calc!$N$1:$N$505,"Base rent — MC",T12_Calc!$K$1:$K$505) | P8: =SUMIF(T12_Calc!$N$1:$N$505,"Base rent — MC",T12_Calc!$L$1:$L$505) | Q8: =SUMIF(T12_Calc!$N$1:$N$505,"Base rent — MC",T12_Calc!$M$1:$M$505) | R8: =SUM(F8:Q8)
A9: Revenue | B9: LOC revenue — IL | C9: IL | E9: IL Care Rate Income | IL Level of Care Income | F9: =SUMIF(T12_Calc!$N$1:$N$505,"LOC revenue — IL",T12_Calc!$B$1:$B$505) | G9: =SUMIF(T12_Calc!$N$1:$N$505,"LOC revenue — IL",T12_Calc!$C$1:$C$505) | H9: =SUMIF(T12_Calc!$N$1:$N$505,"LOC revenue — IL",T12_Calc!$D$1:$D$505) | I9: =SUMIF(T12_Calc!$N$1:$N$505,"LOC revenue — IL",T12_Calc!$E$1:$E$505) | J9: =SUMIF(T12_Calc!$N$1:$N$505,"LOC revenue — IL",T12_Calc!$F$1:$F$505) | K9: =SUMIF(T12_Calc!$N$1:$N$505,"LOC revenue — IL",T12_Calc!$G$1:$G$505) | L9: =SUMIF(T12_Calc!$N$1:$N$505,"LOC revenue — IL",T12_Calc!$H$1:$H$505) | M9: =SUMIF(T12_Calc!$N$1:$N$505,"LOC revenue — IL",T12_Calc!$I$1:$I$505) | N9: =SUMIF(T12_Calc!$N$1:$N$505,"LOC revenue — IL",T12_Calc!$J$1:$J$505) | O9: =SUMIF(T12_Calc!$N$1:$N$505,"LOC revenue — IL",T12_Calc!$K$1:$K$505) | P9: =SUMIF(T12_Calc!$N$1:$N$505,"LOC revenue — IL",T12_Calc!$L$1:$L$505) | Q9: =SUMIF(T12_Calc!$N$1:$N$505,"LOC revenue — IL",T12_Calc!$M$1:$M$505) | R9: =SUM(F9:Q9)
A10: Revenue | B10: LOC revenue — AL | C10: AL | E10: AL Care Rate Income | AL Level of Care Income | AL Care Level Income | F10: =SUMIF(T12_Calc!$N$1:$N$505,"LOC revenue — AL",T12_Calc!$B$1:$B$505) | G10: =SUMIF(T12_Calc!$N$1:$N$505,"LOC revenue — AL",T12_Calc!$C$1:$C$505) | H10: =SUMIF(T12_Calc!$N$1:$N$505,"LOC revenue — AL",T12_Calc!$D$1:$D$505) | I10: =SUMIF(T12_Calc!$N$1:$N$505,"LOC revenue — AL",T12_Calc!$E$1:$E$505) | J10: =SUMIF(T12_Calc!$N$1:$N$505,"LOC revenue — AL",T12_Calc!$F$1:$F$505) | K10: =SUMIF(T12_Calc!$N$1:$N$505,"LOC revenue — AL",T12_Calc!$G$1:$G$505) | L10: =SUMIF(T12_Calc!$N$1:$N$505,"LOC revenue — AL",T12_Calc!$H$1:$H$505) | M10: =SUMIF(T12_Calc!$N$1:$N$505,"LOC revenue — AL",T12_Calc!$I$1:$I$505) | N10: =SUMIF(T12_Calc!$N$1:$N$505,"LOC revenue — AL",T12_Calc!$J$1:$J$505) | O10: =SUMIF(T12_Calc!$N$1:$N$505,"LOC revenue — AL",T12_Calc!$K$1:$K$505) | P10: =SUMIF(T12_Calc!$N$1:$N$505,"LOC revenue — AL",T12_Calc!$L$1:$L$505) | Q10: =SUMIF(T12_Calc!$N$1:$N$505,"LOC revenue — AL",T12_Calc!$M$1:$M$505) | R10: =SUM(F10:Q10)
A11: Revenue | B11: LOC revenue — MC | C11: MC | E11: ALZ Care Rate Income | Memory Care Level of Care | MC Care Rate Income | F11: =SUMIF(T12_Calc!$N$1:$N$505,"LOC revenue — MC",T12_Calc!$B$1:$B$505) | G11: =SUMIF(T12_Calc!$N$1:$N$505,"LOC revenue — MC",T12_Calc!$C$1:$C$505) | H11: =SUMIF(T12_Calc!$N$1:$N$505,"LOC revenue — MC",T12_Calc!$D$1:$D$505) | I11: =SUMIF(T12_Calc!$N$1:$N$505,"LOC revenue — MC",T12_Calc!$E$1:$E$505) | J11: =SUMIF(T12_Calc!$N$1:$N$505,"LOC revenue — MC",T12_Calc!$F$1:$F$505) | K11: =SUMIF(T12_Calc!$N$1:$N$505,"LOC revenue — MC",T12_Calc!$G$1:$G$505) | L11: =SUMIF(T12_Calc!$N$1:$N$505,"LOC revenue — MC",T12_Calc!$H$1:$H$505) | M11: =SUMIF(T12_Calc!$N$1:$N$505,"LOC revenue — MC",T12_Calc!$I$1:$I$505) | N11: =SUMIF(T12_Calc!$N$1:$N$505,"LOC revenue — MC",T12_Calc!$J$1:$J$505) | O11: =SUMIF(T12_Calc!$N$1:$N$505,"LOC revenue — MC",T12_Calc!$K$1:$K$505) | P11: =SUMIF(T12_Calc!$N$1:$N$505,"LOC revenue — MC",T12_Calc!$L$1:$L$505) | Q11: =SUMIF(T12_Calc!$N$1:$N$505,"LOC revenue — MC",T12_Calc!$M$1:$M$505) | R11: =SUM(F11:Q11)
A12: Revenue | B12: Community / move-in fees | C12: - | D12: Normalize to $0 | E12: Community Fees | Move-In Fees | F12: =SUMIF(T12_Calc!$N$1:$N$505,"Community / move-in fees",T12_Calc!$B$1:$B$505) | G12: =SUMIF(T12_Calc!$N$1:$N$505,"Community / move-in fees",T12_Calc!$C$1:$C$505) | H12: =SUMIF(T12_Calc!$N$1:$N$505,"Community / move-in fees",T12_Calc!$D$1:$D$505) | I12: =SUMIF(T12_Calc!$N$1:$N$505,"Community / move-in fees",T12_Calc!$E$1:$E$505) | J12: =SUMIF(T12_Calc!$N$1:$N$505,"Community / move-in fees",T12_Calc!$F$1:$F$505) | K12: =SUMIF(T12_Calc!$N$1:$N$505,"Community / move-in fees",T12_Calc!$G$1:$G$505) | L12: =SUMIF(T12_Calc!$N$1:$N$505,"Community / move-in fees",T12_Calc!$H$1:$H$505) | M12: =SUMIF(T12_Calc!$N$1:$N$505,"Community / move-in fees",T12_Calc!$I$1:$I$505) | N12: =SUMIF(T12_Calc!$N$1:$N$505,"Community / move-in fees",T12_Calc!$J$1:$J$505) | O12: =SUMIF(T12_Calc!$N$1:$N$505,"Community / move-in fees",T12_Calc!$K$1:$K$505) | P12: =SUMIF(T12_Calc!$N$1:$N$505,"Community / move-in fees",T12_Calc!$L$1:$L$505) | Q12: =SUMIF(T12_Calc!$N$1:$N$505,"Community / move-in fees",T12_Calc!$M$1:$M$505) | R12: =SUM(F12:Q12)
A13: Revenue | B13: Concessions & specials | C13: - | D13: Normalize to $0 | E13: Concessions | Move In Specials and Discounts | Move-In Specials | F13: =SUMIF(T12_Calc!$N$1:$N$505,"Concessions & specials",T12_Calc!$B$1:$B$505) | G13: =SUMIF(T12_Calc!$N$1:$N$505,"Concessions & specials",T12_Calc!$C$1:$C$505) | H13: =SUMIF(T12_Calc!$N$1:$N$505,"Concessions & specials",T12_Calc!$D$1:$D$505) | I13: =SUMIF(T12_Calc!$N$1:$N$505,"Concessions & specials",T12_Calc!$E$1:$E$505) | J13: =SUMIF(T12_Calc!$N$1:$N$505,"Concessions & specials",T12_Calc!$F$1:$F$505) | K13: =SUMIF(T12_Calc!$N$1:$N$505,"Concessions & specials",T12_Calc!$G$1:$G$505) | L13: =SUMIF(T12_Calc!$N$1:$N$505,"Concessions & specials",T12_Calc!$H$1:$H$505) | M13: =SUMIF(T12_Calc!$N$1:$N$505,"Concessions & specials",T12_Calc!$I$1:$I$505) | N13: =SUMIF(T12_Calc!$N$1:$N$505,"Concessions & specials",T12_Calc!$J$1:$J$505) | O13: =SUMIF(T12_Calc!$N$1:$N$505,"Concessions & specials",T12_Calc!$K$1:$K$505) | P13: =SUMIF(T12_Calc!$N$1:$N$505,"Concessions & specials",T12_Calc!$L$1:$L$505) | Q13: =SUMIF(T12_Calc!$N$1:$N$505,"Concessions & specials",T12_Calc!$M$1:$M$505) | R13: =SUM(F13:Q13)
A14: Revenue | B14: Respite care | C14: - | D14: Volatile | E14: Respite Care Income | Respite Care | F14: =SUMIF(T12_Calc!$N$1:$N$505,"Respite care",T12_Calc!$B$1:$B$505) | G14: =SUMIF(T12_Calc!$N$1:$N$505,"Respite care",T12_Calc!$C$1:$C$505) | H14: =SUMIF(T12_Calc!$N$1:$N$505,"Respite care",T12_Calc!$D$1:$D$505) | I14: =SUMIF(T12_Calc!$N$1:$N$505,"Respite care",T12_Calc!$E$1:$E$505) | J14: =SUMIF(T12_Calc!$N$1:$N$505,"Respite care",T12_Calc!$F$1:$F$505) | K14: =SUMIF(T12_Calc!$N$1:$N$505,"Respite care",T12_Calc!$G$1:$G$505) | L14: =SUMIF(T12_Calc!$N$1:$N$505,"Respite care",T12_Calc!$H$1:$H$505) | M14: =SUMIF(T12_Calc!$N$1:$N$505,"Respite care",T12_Calc!$I$1:$I$505) | N14: =SUMIF(T12_Calc!$N$1:$N$505,"Respite care",T12_Calc!$J$1:$J$505) | O14: =SUMIF(T12_Calc!$N$1:$N$505,"Respite care",T12_Calc!$K$1:$K$505) | P14: =SUMIF(T12_Calc!$N$1:$N$505,"Respite care",T12_Calc!$L$1:$L$505) | Q14: =SUMIF(T12_Calc!$N$1:$N$505,"Respite care",T12_Calc!$M$1:$M$505) | R14: =SUM(F14:Q14)
A15: Revenue | B15: 2nd Person Revenue | F15: =SUMIF(T12_Calc!$N$1:$N$505,"2nd Person Revenue",T12_Calc!$B$1:$B$505) | G15: =SUMIF(T12_Calc!$N$1:$N$505,"2nd Person Revenue",T12_Calc!$C$1:$C$505) | H15: =SUMIF(T12_Calc!$N$1:$N$505,"2nd Person Revenue",T12_Calc!$D$1:$D$505) | I15: =SUMIF(T12_Calc!$N$1:$N$505,"2nd Person Revenue",T12_Calc!$E$1:$E$505) | J15: =SUMIF(T12_Calc!$N$1:$N$505,"2nd Person Revenue",T12_Calc!$F$1:$F$505) | K15: =SUMIF(T12_Calc!$N$1:$N$505,"2nd Person Revenue",T12_Calc!$G$1:$G$505) | L15: =SUMIF(T12_Calc!$N$1:$N$505,"2nd Person Revenue",T12_Calc!$H$1:$H$505) | M15: =SUMIF(T12_Calc!$N$1:$N$505,"2nd Person Revenue",T12_Calc!$I$1:$I$505) | N15: =SUMIF(T12_Calc!$N$1:$N$505,"2nd Person Revenue",T12_Calc!$J$1:$J$505) | O15: =SUMIF(T12_Calc!$N$1:$N$505,"2nd Person Revenue",T12_Calc!$K$1:$K$505) | P15: =SUMIF(T12_Calc!$N$1:$N$505,"2nd Person Revenue",T12_Calc!$L$1:$L$505) | Q15: =SUMIF(T12_Calc!$N$1:$N$505,"2nd Person Revenue",T12_Calc!$M$1:$M$505) | R15: =SUM(F15:Q15)
A16: Revenue | B16: Meal Income | F16: =SUMIF(T12_Calc!$N$1:$N$505,"Meal Income",T12_Calc!$B$1:$B$505) | G16: =SUMIF(T12_Calc!$N$1:$N$505,"Meal Income",T12_Calc!$C$1:$C$505) | H16: =SUMIF(T12_Calc!$N$1:$N$505,"Meal Income",T12_Calc!$D$1:$D$505) | I16: =SUMIF(T12_Calc!$N$1:$N$505,"Meal Income",T12_Calc!$E$1:$E$505) | J16: =SUMIF(T12_Calc!$N$1:$N$505,"Meal Income",T12_Calc!$F$1:$F$505) | K16: =SUMIF(T12_Calc!$N$1:$N$505,"Meal Income",T12_Calc!$G$1:$G$505) | L16: =SUMIF(T12_Calc!$N$1:$N$505,"Meal Income",T12_Calc!$H$1:$H$505) | M16: =SUMIF(T12_Calc!$N$1:$N$505,"Meal Income",T12_Calc!$I$1:$I$505) | N16: =SUMIF(T12_Calc!$N$1:$N$505,"Meal Income",T12_Calc!$J$1:$J$505) | O16: =SUMIF(T12_Calc!$N$1:$N$505,"Meal Income",T12_Calc!$K$1:$K$505) | P16: =SUMIF(T12_Calc!$N$1:$N$505,"Meal Income",T12_Calc!$L$1:$L$505) | Q16: =SUMIF(T12_Calc!$N$1:$N$505,"Meal Income",T12_Calc!$M$1:$M$505) | R16: =SUM(F16:Q16)
A17: Revenue | B17: Housekeeping Income | F17: =SUMIF(T12_Calc!$N$1:$N$505,"Housekeeping Income",T12_Calc!$B$1:$B$505) | G17: =SUMIF(T12_Calc!$N$1:$N$505,"Housekeeping Income",T12_Calc!$C$1:$C$505) | H17: =SUMIF(T12_Calc!$N$1:$N$505,"Housekeeping Income",T12_Calc!$D$1:$D$505) | I17: =SUMIF(T12_Calc!$N$1:$N$505,"Housekeeping Income",T12_Calc!$E$1:$E$505) | J17: =SUMIF(T12_Calc!$N$1:$N$505,"Housekeeping Income",T12_Calc!$F$1:$F$505) | K17: =SUMIF(T12_Calc!$N$1:$N$505,"Housekeeping Income",T12_Calc!$G$1:$G$505) | L17: =SUMIF(T12_Calc!$N$1:$N$505,"Housekeeping Income",T12_Calc!$H$1:$H$505) | M17: =SUMIF(T12_Calc!$N$1:$N$505,"Housekeeping Income",T12_Calc!$I$1:$I$505) | N17: =SUMIF(T12_Calc!$N$1:$N$505,"Housekeeping Income",T12_Calc!$J$1:$J$505) | O17: =SUMIF(T12_Calc!$N$1:$N$505,"Housekeeping Income",T12_Calc!$K$1:$K$505) | P17: =SUMIF(T12_Calc!$N$1:$N$505,"Housekeeping Income",T12_Calc!$L$1:$L$505) | Q17: =SUMIF(T12_Calc!$N$1:$N$505,"Housekeeping Income",T12_Calc!$M$1:$M$505) | R17: =SUM(F17:Q17)
A18: Revenue | B18: Laundry Income | F18: =SUMIF(T12_Calc!$N$1:$N$505,"Laundry Income",T12_Calc!$B$1:$B$505) | G18: =SUMIF(T12_Calc!$N$1:$N$505,"Laundry Income",T12_Calc!$C$1:$C$505) | H18: =SUMIF(T12_Calc!$N$1:$N$505,"Laundry Income",T12_Calc!$D$1:$D$505) | I18: =SUMIF(T12_Calc!$N$1:$N$505,"Laundry Income",T12_Calc!$E$1:$E$505) | J18: =SUMIF(T12_Calc!$N$1:$N$505,"Laundry Income",T12_Calc!$F$1:$F$505) | K18: =SUMIF(T12_Calc!$N$1:$N$505,"Laundry Income",T12_Calc!$G$1:$G$505) | L18: =SUMIF(T12_Calc!$N$1:$N$505,"Laundry Income",T12_Calc!$H$1:$H$505) | M18: =SUMIF(T12_Calc!$N$1:$N$505,"Laundry Income",T12_Calc!$I$1:$I$505) | N18: =SUMIF(T12_Calc!$N$1:$N$505,"Laundry Income",T12_Calc!$J$1:$J$505) | O18: =SUMIF(T12_Calc!$N$1:$N$505,"Laundry Income",T12_Calc!$K$1:$K$505) | P18: =SUMIF(T12_Calc!$N$1:$N$505,"Laundry Income",T12_Calc!$L$1:$L$505) | Q18: =SUMIF(T12_Calc!$N$1:$N$505,"Laundry Income",T12_Calc!$M$1:$M$505) | R18: =SUM(F18:Q18)
A19: Revenue | B19: Scooter Fee Revenue | F19: =SUMIF(T12_Calc!$N$1:$N$505,"Scooter Fee Revenue",T12_Calc!$B$1:$B$505) | G19: =SUMIF(T12_Calc!$N$1:$N$505,"Scooter Fee Revenue",T12_Calc!$C$1:$C$505) | H19: =SUMIF(T12_Calc!$N$1:$N$505,"Scooter Fee Revenue",T12_Calc!$D$1:$D$505) | I19: =SUMIF(T12_Calc!$N$1:$N$505,"Scooter Fee Revenue",T12_Calc!$E$1:$E$505) | J19: =SUMIF(T12_Calc!$N$1:$N$505,"Scooter Fee Revenue",T12_Calc!$F$1:$F$505) | K19: =SUMIF(T12_Calc!$N$1:$N$505,"Scooter Fee Revenue",T12_Calc!$G$1:$G$505) | L19: =SUMIF(T12_Calc!$N$1:$N$505,"Scooter Fee Revenue",T12_Calc!$H$1:$H$505) | M19: =SUMIF(T12_Calc!$N$1:$N$505,"Scooter Fee Revenue",T12_Calc!$I$1:$I$505) | N19: =SUMIF(T12_Calc!$N$1:$N$505,"Scooter Fee Revenue",T12_Calc!$J$1:$J$505) | O19: =SUMIF(T12_Calc!$N$1:$N$505,"Scooter Fee Revenue",T12_Calc!$K$1:$K$505) | P19: =SUMIF(T12_Calc!$N$1:$N$505,"Scooter Fee Revenue",T12_Calc!$L$1:$L$505) | Q19: =SUMIF(T12_Calc!$N$1:$N$505,"Scooter Fee Revenue",T12_Calc!$M$1:$M$505) | R19: =SUM(F19:Q19)
A20: Revenue | B20: Transfer Fee Revenue | F20: =SUMIF(T12_Calc!$N$1:$N$505,"Transfer Fee Revenue",T12_Calc!$B$1:$B$505) | G20: =SUMIF(T12_Calc!$N$1:$N$505,"Transfer Fee Revenue",T12_Calc!$C$1:$C$505) | H20: =SUMIF(T12_Calc!$N$1:$N$505,"Transfer Fee Revenue",T12_Calc!$D$1:$D$505) | I20: =SUMIF(T12_Calc!$N$1:$N$505,"Transfer Fee Revenue",T12_Calc!$E$1:$E$505) | J20: =SUMIF(T12_Calc!$N$1:$N$505,"Transfer Fee Revenue",T12_Calc!$F$1:$F$505) | K20: =SUMIF(T12_Calc!$N$1:$N$505,"Transfer Fee Revenue",T12_Calc!$G$1:$G$505) | L20: =SUMIF(T12_Calc!$N$1:$N$505,"Transfer Fee Revenue",T12_Calc!$H$1:$H$505) | M20: =SUMIF(T12_Calc!$N$1:$N$505,"Transfer Fee Revenue",T12_Calc!$I$1:$I$505) | N20: =SUMIF(T12_Calc!$N$1:$N$505,"Transfer Fee Revenue",T12_Calc!$J$1:$J$505) | O20: =SUMIF(T12_Calc!$N$1:$N$505,"Transfer Fee Revenue",T12_Calc!$K$1:$K$505) | P20: =SUMIF(T12_Calc!$N$1:$N$505,"Transfer Fee Revenue",T12_Calc!$L$1:$L$505) | Q20: =SUMIF(T12_Calc!$N$1:$N$505,"Transfer Fee Revenue",T12_Calc!$M$1:$M$505) | R20: =SUM(F20:Q20)
A21: Revenue | B21: Other community revenue | C21: - | E21: Guest Meals | Beautician Income | Utility Income | Incontinence Supplies Income | Personal Purchases | Administrative Fees | Finance Charges Revenue | F21: =SUMIF(T12_Calc!$N$1:$N$505,"Other community revenue",T12_Calc!$B$1:$B$505) | G21: =SUMIF(T12_Calc!$N$1:$N$505,"Other community revenue",T12_Calc!$C$1:$C$505) | H21: =SUMIF(T12_Calc!$N$1:$N$505,"Other community revenue",T12_Calc!$D$1:$D$505) | I21: =SUMIF(T12_Calc!$N$1:$N$505,"Other community revenue",T12_Calc!$E$1:$E$505) | J21: =SUMIF(T12_Calc!$N$1:$N$505,"Other community revenue",T12_Calc!$F$1:$F$505) | K21: =SUMIF(T12_Calc!$N$1:$N$505,"Other community revenue",T12_Calc!$G$1:$G$505) | L21: =SUMIF(T12_Calc!$N$1:$N$505,"Other community revenue",T12_Calc!$H$1:$H$505) | M21: =SUMIF(T12_Calc!$N$1:$N$505,"Other community revenue",T12_Calc!$I$1:$I$505) | N21: =SUMIF(T12_Calc!$N$1:$N$505,"Other community revenue",T12_Calc!$J$1:$J$505) | O21: =SUMIF(T12_Calc!$N$1:$N$505,"Other community revenue",T12_Calc!$K$1:$K$505) | P21: =SUMIF(T12_Calc!$N$1:$N$505,"Other community revenue",T12_Calc!$L$1:$L$505) | Q21: =SUMIF(T12_Calc!$N$1:$N$505,"Other community revenue",T12_Calc!$M$1:$M$505) | R21: =SUM(F21:Q21)
A22: Labor | B22: Care staff labor | C22: - | E22: Care Staff Labor | Direct Care Labor | Other Labor | F22: =SUMIF(T12_Calc!$N$1:$N$505,"Care staff labor",T12_Calc!$B$1:$B$505) | G22: =SUMIF(T12_Calc!$N$1:$N$505,"Care staff labor",T12_Calc!$C$1:$C$505) | H22: =SUMIF(T12_Calc!$N$1:$N$505,"Care staff labor",T12_Calc!$D$1:$D$505) | I22: =SUMIF(T12_Calc!$N$1:$N$505,"Care staff labor",T12_Calc!$E$1:$E$505) | J22: =SUMIF(T12_Calc!$N$1:$N$505,"Care staff labor",T12_Calc!$F$1:$F$505) | K22: =SUMIF(T12_Calc!$N$1:$N$505,"Care staff labor",T12_Calc!$G$1:$G$505) | L22: =SUMIF(T12_Calc!$N$1:$N$505,"Care staff labor",T12_Calc!$H$1:$H$505) | M22: =SUMIF(T12_Calc!$N$1:$N$505,"Care staff labor",T12_Calc!$I$1:$I$505) | N22: =SUMIF(T12_Calc!$N$1:$N$505,"Care staff labor",T12_Calc!$J$1:$J$505) | O22: =SUMIF(T12_Calc!$N$1:$N$505,"Care staff labor",T12_Calc!$K$1:$K$505) | P22: =SUMIF(T12_Calc!$N$1:$N$505,"Care staff labor",T12_Calc!$L$1:$L$505) | Q22: =SUMIF(T12_Calc!$N$1:$N$505,"Care staff labor",T12_Calc!$M$1:$M$505) | R22: =SUM(F22:Q22)
A23: Labor | B23: Wellness / care coordinators | C23: - | E23: Wellness/Care Coordinators Labor | Wellness/Care Coordinator Labor | Care Coordinator Labor | F23: =SUMIF(T12_Calc!$N$1:$N$505,"Wellness / care coordinators",T12_Calc!$B$1:$B$505) | G23: =SUMIF(T12_Calc!$N$1:$N$505,"Wellness / care coordinators",T12_Calc!$C$1:$C$505) | H23: =SUMIF(T12_Calc!$N$1:$N$505,"Wellness / care coordinators",T12_Calc!$D$1:$D$505) | I23: =SUMIF(T12_Calc!$N$1:$N$505,"Wellness / care coordinators",T12_Calc!$E$1:$E$505) | J23: =SUMIF(T12_Calc!$N$1:$N$505,"Wellness / care coordinators",T12_Calc!$F$1:$F$505) | K23: =SUMIF(T12_Calc!$N$1:$N$505,"Wellness / care coordinators",T12_Calc!$G$1:$G$505) | L23: =SUMIF(T12_Calc!$N$1:$N$505,"Wellness / care coordinators",T12_Calc!$H$1:$H$505) | M23: =SUMIF(T12_Calc!$N$1:$N$505,"Wellness / care coordinators",T12_Calc!$I$1:$I$505) | N23: =SUMIF(T12_Calc!$N$1:$N$505,"Wellness / care coordinators",T12_Calc!$J$1:$J$505) | O23: =SUMIF(T12_Calc!$N$1:$N$505,"Wellness / care coordinators",T12_Calc!$K$1:$K$505) | P23: =SUMIF(T12_Calc!$N$1:$N$505,"Wellness / care coordinators",T12_Calc!$L$1:$L$505) | Q23: =SUMIF(T12_Calc!$N$1:$N$505,"Wellness / care coordinators",T12_Calc!$M$1:$M$505) | R23: =SUM(F23:Q23)
A24: Labor | B24: Contract / agency labor | C24: - | D24: Normalize at stabilization | E24: Contract Labor - Care | Contract Labor | Agency Labor | F24: =SUMIF(T12_Calc!$N$1:$N$505,"Contract / agency labor",T12_Calc!$B$1:$B$505) | G24: =SUMIF(T12_Calc!$N$1:$N$505,"Contract / agency labor",T12_Calc!$C$1:$C$505) | H24: =SUMIF(T12_Calc!$N$1:$N$505,"Contract / agency labor",T12_Calc!$D$1:$D$505) | I24: =SUMIF(T12_Calc!$N$1:$N$505,"Contract / agency labor",T12_Calc!$E$1:$E$505) | J24: =SUMIF(T12_Calc!$N$1:$N$505,"Contract / agency labor",T12_Calc!$F$1:$F$505) | K24: =SUMIF(T12_Calc!$N$1:$N$505,"Contract / agency labor",T12_Calc!$G$1:$G$505) | L24: =SUMIF(T12_Calc!$N$1:$N$505,"Contract / agency labor",T12_Calc!$H$1:$H$505) | M24: =SUMIF(T12_Calc!$N$1:$N$505,"Contract / agency labor",T12_Calc!$I$1:$I$505) | N24: =SUMIF(T12_Calc!$N$1:$N$505,"Contract / agency labor",T12_Calc!$J$1:$J$505) | O24: =SUMIF(T12_Calc!$N$1:$N$505,"Contract / agency labor",T12_Calc!$K$1:$K$505) | P24: =SUMIF(T12_Calc!$N$1:$N$505,"Contract / agency labor",T12_Calc!$L$1:$L$505) | Q24: =SUMIF(T12_Calc!$N$1:$N$505,"Contract / agency labor",T12_Calc!$M$1:$M$505) | R24: =SUM(F24:Q24)
A25: Labor | B25: Activities labor | C25: - | E25: Activities Labor | F25: =SUMIF(T12_Calc!$N$1:$N$505,"Activities labor",T12_Calc!$B$1:$B$505) | G25: =SUMIF(T12_Calc!$N$1:$N$505,"Activities labor",T12_Calc!$C$1:$C$505) | H25: =SUMIF(T12_Calc!$N$1:$N$505,"Activities labor",T12_Calc!$D$1:$D$505) | I25: =SUMIF(T12_Calc!$N$1:$N$505,"Activities labor",T12_Calc!$E$1:$E$505) | J25: =SUMIF(T12_Calc!$N$1:$N$505,"Activities labor",T12_Calc!$F$1:$F$505) | K25: =SUMIF(T12_Calc!$N$1:$N$505,"Activities labor",T12_Calc!$G$1:$G$505) | L25: =SUMIF(T12_Calc!$N$1:$N$505,"Activities labor",T12_Calc!$H$1:$H$505) | M25: =SUMIF(T12_Calc!$N$1:$N$505,"Activities labor",T12_Calc!$I$1:$I$505) | N25: =SUMIF(T12_Calc!$N$1:$N$505,"Activities labor",T12_Calc!$J$1:$J$505) | O25: =SUMIF(T12_Calc!$N$1:$N$505,"Activities labor",T12_Calc!$K$1:$K$505) | P25: =SUMIF(T12_Calc!$N$1:$N$505,"Activities labor",T12_Calc!$L$1:$L$505) | Q25: =SUMIF(T12_Calc!$N$1:$N$505,"Activities labor",T12_Calc!$M$1:$M$505) | R25: =SUM(F25:Q25)
A26: Labor | B26: Dining / food service labor | C26: - | E26: Food Service Labor | Dietary Labor | Dining Labor | F26: =SUMIF(T12_Calc!$N$1:$N$505,"Dining / food service labor",T12_Calc!$B$1:$B$505) | G26: =SUMIF(T12_Calc!$N$1:$N$505,"Dining / food service labor",T12_Calc!$C$1:$C$505) | H26: =SUMIF(T12_Calc!$N$1:$N$505,"Dining / food service labor",T12_Calc!$D$1:$D$505) | I26: =SUMIF(T12_Calc!$N$1:$N$505,"Dining / food service labor",T12_Calc!$E$1:$E$505) | J26: =SUMIF(T12_Calc!$N$1:$N$505,"Dining / food service labor",T12_Calc!$F$1:$F$505) | K26: =SUMIF(T12_Calc!$N$1:$N$505,"Dining / food service labor",T12_Calc!$G$1:$G$505) | L26: =SUMIF(T12_Calc!$N$1:$N$505,"Dining / food service labor",T12_Calc!$H$1:$H$505) | M26: =SUMIF(T12_Calc!$N$1:$N$505,"Dining / food service labor",T12_Calc!$I$1:$I$505) | N26: =SUMIF(T12_Calc!$N$1:$N$505,"Dining / food service labor",T12_Calc!$J$1:$J$505) | O26: =SUMIF(T12_Calc!$N$1:$N$505,"Dining / food service labor",T12_Calc!$K$1:$K$505) | P26: =SUMIF(T12_Calc!$N$1:$N$505,"Dining / food service labor",T12_Calc!$L$1:$L$505) | Q26: =SUMIF(T12_Calc!$N$1:$N$505,"Dining / food service labor",T12_Calc!$M$1:$M$505) | R26: =SUM(F26:Q26)
A27: Labor | B27: Maint. & housekeeping labor | C27: - | E27: Maintenance/Housekeeping Labor | Maintenance Labor | Housekeeping Labor | F27: =SUMIF(T12_Calc!$N$1:$N$505,"Maint. & housekeeping labor",T12_Calc!$B$1:$B$505) | G27: =SUMIF(T12_Calc!$N$1:$N$505,"Maint. & housekeeping labor",T12_Calc!$C$1:$C$505) | H27: =SUMIF(T12_Calc!$N$1:$N$505,"Maint. & housekeeping labor",T12_Calc!$D$1:$D$505) | I27: =SUMIF(T12_Calc!$N$1:$N$505,"Maint. & housekeeping labor",T12_Calc!$E$1:$E$505) | J27: =SUMIF(T12_Calc!$N$1:$N$505,"Maint. & housekeeping labor",T12_Calc!$F$1:$F$505) | K27: =SUMIF(T12_Calc!$N$1:$N$505,"Maint. & housekeeping labor",T12_Calc!$G$1:$G$505) | L27: =SUMIF(T12_Calc!$N$1:$N$505,"Maint. & housekeeping labor",T12_Calc!$H$1:$H$505) | M27: =SUMIF(T12_Calc!$N$1:$N$505,"Maint. & housekeeping labor",T12_Calc!$I$1:$I$505) | N27: =SUMIF(T12_Calc!$N$1:$N$505,"Maint. & housekeeping labor",T12_Calc!$J$1:$J$505) | O27: =SUMIF(T12_Calc!$N$1:$N$505,"Maint. & housekeeping labor",T12_Calc!$K$1:$K$505) | P27: =SUMIF(T12_Calc!$N$1:$N$505,"Maint. & housekeeping labor",T12_Calc!$L$1:$L$505) | Q27: =SUMIF(T12_Calc!$N$1:$N$505,"Maint. & housekeeping labor",T12_Calc!$M$1:$M$505) | R27: =SUM(F27:Q27)
A28: Labor | B28: Administrative labor | C28: - | E28: Administration Labor | Administrative Labor | F28: =SUMIF(T12_Calc!$N$1:$N$505,"Administrative labor",T12_Calc!$B$1:$B$505) | G28: =SUMIF(T12_Calc!$N$1:$N$505,"Administrative labor",T12_Calc!$C$1:$C$505) | H28: =SUMIF(T12_Calc!$N$1:$N$505,"Administrative labor",T12_Calc!$D$1:$D$505) | I28: =SUMIF(T12_Calc!$N$1:$N$505,"Administrative labor",T12_Calc!$E$1:$E$505) | J28: =SUMIF(T12_Calc!$N$1:$N$505,"Administrative labor",T12_Calc!$F$1:$F$505) | K28: =SUMIF(T12_Calc!$N$1:$N$505,"Administrative labor",T12_Calc!$G$1:$G$505) | L28: =SUMIF(T12_Calc!$N$1:$N$505,"Administrative labor",T12_Calc!$H$1:$H$505) | M28: =SUMIF(T12_Calc!$N$1:$N$505,"Administrative labor",T12_Calc!$I$1:$I$505) | N28: =SUMIF(T12_Calc!$N$1:$N$505,"Administrative labor",T12_Calc!$J$1:$J$505) | O28: =SUMIF(T12_Calc!$N$1:$N$505,"Administrative labor",T12_Calc!$K$1:$K$505) | P28: =SUMIF(T12_Calc!$N$1:$N$505,"Administrative labor",T12_Calc!$L$1:$L$505) | Q28: =SUMIF(T12_Calc!$N$1:$N$505,"Administrative labor",T12_Calc!$M$1:$M$505) | R28: =SUM(F28:Q28)
A29: Labor | B29: Bonus wages | C29: - | D29: Stabilize annually | E29: Bonus Wages | F29: =SUMIF(T12_Calc!$N$1:$N$505,"Bonus wages",T12_Calc!$B$1:$B$505) | G29: =SUMIF(T12_Calc!$N$1:$N$505,"Bonus wages",T12_Calc!$C$1:$C$505) | H29: =SUMIF(T12_Calc!$N$1:$N$505,"Bonus wages",T12_Calc!$D$1:$D$505) | I29: =SUMIF(T12_Calc!$N$1:$N$505,"Bonus wages",T12_Calc!$E$1:$E$505) | J29: =SUMIF(T12_Calc!$N$1:$N$505,"Bonus wages",T12_Calc!$F$1:$F$505) | K29: =SUMIF(T12_Calc!$N$1:$N$505,"Bonus wages",T12_Calc!$G$1:$G$505) | L29: =SUMIF(T12_Calc!$N$1:$N$505,"Bonus wages",T12_Calc!$H$1:$H$505) | M29: =SUMIF(T12_Calc!$N$1:$N$505,"Bonus wages",T12_Calc!$I$1:$I$505) | N29: =SUMIF(T12_Calc!$N$1:$N$505,"Bonus wages",T12_Calc!$J$1:$J$505) | O29: =SUMIF(T12_Calc!$N$1:$N$505,"Bonus wages",T12_Calc!$K$1:$K$505) | P29: =SUMIF(T12_Calc!$N$1:$N$505,"Bonus wages",T12_Calc!$L$1:$L$505) | Q29: =SUMIF(T12_Calc!$N$1:$N$505,"Bonus wages",T12_Calc!$M$1:$M$505) | R29: =SUM(F29:Q29)
A30: Labor | B30: Overtime wages | C30: - | D30: Flag if >5% of wages | E30: Overtime | Overtime Wages | OT Wages | F30: =SUMIF(T12_Calc!$N$1:$N$505,"Overtime wages",T12_Calc!$B$1:$B$505) | G30: =SUMIF(T12_Calc!$N$1:$N$505,"Overtime wages",T12_Calc!$C$1:$C$505) | H30: =SUMIF(T12_Calc!$N$1:$N$505,"Overtime wages",T12_Calc!$D$1:$D$505) | I30: =SUMIF(T12_Calc!$N$1:$N$505,"Overtime wages",T12_Calc!$E$1:$E$505) | J30: =SUMIF(T12_Calc!$N$1:$N$505,"Overtime wages",T12_Calc!$F$1:$F$505) | K30: =SUMIF(T12_Calc!$N$1:$N$505,"Overtime wages",T12_Calc!$G$1:$G$505) | L30: =SUMIF(T12_Calc!$N$1:$N$505,"Overtime wages",T12_Calc!$H$1:$H$505) | M30: =SUMIF(T12_Calc!$N$1:$N$505,"Overtime wages",T12_Calc!$I$1:$I$505) | N30: =SUMIF(T12_Calc!$N$1:$N$505,"Overtime wages",T12_Calc!$J$1:$J$505) | O30: =SUMIF(T12_Calc!$N$1:$N$505,"Overtime wages",T12_Calc!$K$1:$K$505) | P30: =SUMIF(T12_Calc!$N$1:$N$505,"Overtime wages",T12_Calc!$L$1:$L$505) | Q30: =SUMIF(T12_Calc!$N$1:$N$505,"Overtime wages",T12_Calc!$M$1:$M$505) | R30: =SUM(F30:Q30)
A31: Labor | B31: PTO wages | C31: - | D31: Annualize | E31: PTO Wages | PTO | F31: =SUMIF(T12_Calc!$N$1:$N$505,"PTO wages",T12_Calc!$B$1:$B$505) | G31: =SUMIF(T12_Calc!$N$1:$N$505,"PTO wages",T12_Calc!$C$1:$C$505) | H31: =SUMIF(T12_Calc!$N$1:$N$505,"PTO wages",T12_Calc!$D$1:$D$505) | I31: =SUMIF(T12_Calc!$N$1:$N$505,"PTO wages",T12_Calc!$E$1:$E$505) | J31: =SUMIF(T12_Calc!$N$1:$N$505,"PTO wages",T12_Calc!$F$1:$F$505) | K31: =SUMIF(T12_Calc!$N$1:$N$505,"PTO wages",T12_Calc!$G$1:$G$505) | L31: =SUMIF(T12_Calc!$N$1:$N$505,"PTO wages",T12_Calc!$H$1:$H$505) | M31: =SUMIF(T12_Calc!$N$1:$N$505,"PTO wages",T12_Calc!$I$1:$I$505) | N31: =SUMIF(T12_Calc!$N$1:$N$505,"PTO wages",T12_Calc!$J$1:$J$505) | O31: =SUMIF(T12_Calc!$N$1:$N$505,"PTO wages",T12_Calc!$K$1:$K$505) | P31: =SUMIF(T12_Calc!$N$1:$N$505,"PTO wages",T12_Calc!$L$1:$L$505) | Q31: =SUMIF(T12_Calc!$N$1:$N$505,"PTO wages",T12_Calc!$M$1:$M$505) | R31: =SUM(F31:Q31)
A32: Labor | B32: Payroll taxes | C32: - | E32: Payroll Taxes | F32: =SUMIF(T12_Calc!$N$1:$N$505,"Payroll taxes",T12_Calc!$B$1:$B$505) | G32: =SUMIF(T12_Calc!$N$1:$N$505,"Payroll taxes",T12_Calc!$C$1:$C$505) | H32: =SUMIF(T12_Calc!$N$1:$N$505,"Payroll taxes",T12_Calc!$D$1:$D$505) | I32: =SUMIF(T12_Calc!$N$1:$N$505,"Payroll taxes",T12_Calc!$E$1:$E$505) | J32: =SUMIF(T12_Calc!$N$1:$N$505,"Payroll taxes",T12_Calc!$F$1:$F$505) | K32: =SUMIF(T12_Calc!$N$1:$N$505,"Payroll taxes",T12_Calc!$G$1:$G$505) | L32: =SUMIF(T12_Calc!$N$1:$N$505,"Payroll taxes",T12_Calc!$H$1:$H$505) | M32: =SUMIF(T12_Calc!$N$1:$N$505,"Payroll taxes",T12_Calc!$I$1:$I$505) | N32: =SUMIF(T12_Calc!$N$1:$N$505,"Payroll taxes",T12_Calc!$J$1:$J$505) | O32: =SUMIF(T12_Calc!$N$1:$N$505,"Payroll taxes",T12_Calc!$K$1:$K$505) | P32: =SUMIF(T12_Calc!$N$1:$N$505,"Payroll taxes",T12_Calc!$L$1:$L$505) | Q32: =SUMIF(T12_Calc!$N$1:$N$505,"Payroll taxes",T12_Calc!$M$1:$M$505) | R32: =SUM(F32:Q32)
A33: Labor | B33: Employee benefits | C33: - | E33: Employee Benefits - Insurance | Employee Benefits | F33: =SUMIF(T12_Calc!$N$1:$N$505,"Employee benefits",T12_Calc!$B$1:$B$505) | G33: =SUMIF(T12_Calc!$N$1:$N$505,"Employee benefits",T12_Calc!$C$1:$C$505) | H33: =SUMIF(T12_Calc!$N$1:$N$505,"Employee benefits",T12_Calc!$D$1:$D$505) | I33: =SUMIF(T12_Calc!$N$1:$N$505,"Employee benefits",T12_Calc!$E$1:$E$505) | J33: =SUMIF(T12_Calc!$N$1:$N$505,"Employee benefits",T12_Calc!$F$1:$F$505) | K33: =SUMIF(T12_Calc!$N$1:$N$505,"Employee benefits",T12_Calc!$G$1:$G$505) | L33: =SUMIF(T12_Calc!$N$1:$N$505,"Employee benefits",T12_Calc!$H$1:$H$505) | M33: =SUMIF(T12_Calc!$N$1:$N$505,"Employee benefits",T12_Calc!$I$1:$I$505) | N33: =SUMIF(T12_Calc!$N$1:$N$505,"Employee benefits",T12_Calc!$J$1:$J$505) | O33: =SUMIF(T12_Calc!$N$1:$N$505,"Employee benefits",T12_Calc!$K$1:$K$505) | P33: =SUMIF(T12_Calc!$N$1:$N$505,"Employee benefits",T12_Calc!$L$1:$L$505) | Q33: =SUMIF(T12_Calc!$N$1:$N$505,"Employee benefits",T12_Calc!$M$1:$M$505) | R33: =SUM(F33:Q33)
A34: Labor | B34: Workers' comp insurance | C34: - | E34: Worker's Comp Insurance | Workers Comp Insurance | Workers' Compensation | F34: =SUMIF(T12_Calc!$N$1:$N$505,"Workers' comp insurance",T12_Calc!$B$1:$B$505) | G34: =SUMIF(T12_Calc!$N$1:$N$505,"Workers' comp insurance",T12_Calc!$C$1:$C$505) | H34: =SUMIF(T12_Calc!$N$1:$N$505,"Workers' comp insurance",T12_Calc!$D$1:$D$505) | I34: =SUMIF(T12_Calc!$N$1:$N$505,"Workers' comp insurance",T12_Calc!$E$1:$E$505) | J34: =SUMIF(T12_Calc!$N$1:$N$505,"Workers' comp insurance",T12_Calc!$F$1:$F$505) | K34: =SUMIF(T12_Calc!$N$1:$N$505,"Workers' comp insurance",T12_Calc!$G$1:$G$505) | L34: =SUMIF(T12_Calc!$N$1:$N$505,"Workers' comp insurance",T12_Calc!$H$1:$H$505) | M34: =SUMIF(T12_Calc!$N$1:$N$505,"Workers' comp insurance",T12_Calc!$I$1:$I$505) | N34: =SUMIF(T12_Calc!$N$1:$N$505,"Workers' comp insurance",T12_Calc!$J$1:$J$505) | O34: =SUMIF(T12_Calc!$N$1:$N$505,"Workers' comp insurance",T12_Calc!$K$1:$K$505) | P34: =SUMIF(T12_Calc!$N$1:$N$505,"Workers' comp insurance",T12_Calc!$L$1:$L$505) | Q34: =SUMIF(T12_Calc!$N$1:$N$505,"Workers' comp insurance",T12_Calc!$M$1:$M$505) | R34: =SUM(F34:Q34)
A35: Labor | B35: Employee 401(k) | C35: - | E35: Employee 401(K) | Employee 401(k) | F35: =SUMIF(T12_Calc!$N$1:$N$505,"Employee 401(k)",T12_Calc!$B$1:$B$505) | G35: =SUMIF(T12_Calc!$N$1:$N$505,"Employee 401(k)",T12_Calc!$C$1:$C$505) | H35: =SUMIF(T12_Calc!$N$1:$N$505,"Employee 401(k)",T12_Calc!$D$1:$D$505) | I35: =SUMIF(T12_Calc!$N$1:$N$505,"Employee 401(k)",T12_Calc!$E$1:$E$505) | J35: =SUMIF(T12_Calc!$N$1:$N$505,"Employee 401(k)",T12_Calc!$F$1:$F$505) | K35: =SUMIF(T12_Calc!$N$1:$N$505,"Employee 401(k)",T12_Calc!$G$1:$G$505) | L35: =SUMIF(T12_Calc!$N$1:$N$505,"Employee 401(k)",T12_Calc!$H$1:$H$505) | M35: =SUMIF(T12_Calc!$N$1:$N$505,"Employee 401(k)",T12_Calc!$I$1:$I$505) | N35: =SUMIF(T12_Calc!$N$1:$N$505,"Employee 401(k)",T12_Calc!$J$1:$J$505) | O35: =SUMIF(T12_Calc!$N$1:$N$505,"Employee 401(k)",T12_Calc!$K$1:$K$505) | P35: =SUMIF(T12_Calc!$N$1:$N$505,"Employee 401(k)",T12_Calc!$L$1:$L$505) | Q35: =SUMIF(T12_Calc!$N$1:$N$505,"Employee 401(k)",T12_Calc!$M$1:$M$505) | R35: =SUM(F35:Q35)
