Workbook
Name Beds: 'Prop Info'!$B$15
Name EGI: Scenarios!$F$50
Name Total_LPA_Equity: Scenarios!$F$33
Name Total_Payroll: 'Staffing Matrix'!$M$67
Name Units: Scenarios!$B$8

Sheet Cover
A1: ASSISTED LIVING FACILITY — INVESTMENT SUMMARY
A2: Confidential — For Authorized Recipients Only
A3: Template Version 11.0 · Updated 2026-06-16 (RR Analysis hide-zero display + formula strip; dynamic Section R unit-type matrix IL/AL/MC/OTH x6; Prop Info OM/Market-Research/Links reformat) · versioning: whole number = structural, .## = non-structural
A4: PROPERTY INFORMATION
A5: Property Name | B5: ='Prop Info'!B4 -> 0
A6: Location | B6: ='Prop Info'!B5 -> 0
A7: Year Built | B7: ='Prop Info'!B9 -> 0
A8: Total Units (physical rooms) | B8: =Scenarios!F8 -> 0 | C8: =IFERROR('Prop Info'!$B$15,0) -> 0
A9: Gross Sq Ft | B9: ='Prop Info'!B11 -> 0
A10: Asset Class | B10: ='Prop Info'!B13 -> 0
A11: Active Scenario | B11: =Scenarios!B2 -> Actuals (T-12)
A12: Licensed Beds / Occupied Beds (Y1) | B12: =IFERROR('Prop Info'!$B$15,0) -> 0 | C12: / | D12: =IFERROR(Scenarios!F51,0) -> 0 | E12: =IFERROR(Scenarios!F51/'Prop Info'!$B$15,0) -> 0
A13: KEY DEAL METRICS
A14: Metric | B14: Value | C14: / Beds | D14: Returns Metric | E14: Value
A15: Purchase Price | B15: =Scenarios!F7 -> 0 | D15: LP IRR | E15: =Waterfall!B69 -> 0
A16: Price Per Room / Per Bed | B16: =Scenarios!F9 | C16: =IFERROR(Scenarios!F7/'Prop Info'!$B$15,0) -> 0 | D16: GP IRR | E16: =Waterfall!E66 -> 0
A17: Total Acquisition Cost | B17: =Scenarios!F17 | D17: LP Equity Multiple | E17: =IFERROR(Waterfall!B67,0) -> 0
A18: Loan Amount (Total) | B18: =Loans!E4 -> 0 | D18: Y1 Cash-on-Cash | E18: ='P&L'!D126 -> 0
A19: LTV | B19: =IFERROR(Scenarios!F150/Scenarios!F7,0) -> 0 | D19: Year 5 NOI | E19: =IFERROR(INDEX('P&L'!D115:M116,1,Scenarios!F86),0)+IFERROR(INDEX('P&L'!D112:M113,1,Scenarios!F86),0) -> 0
A20: LTC | B20: =IFERROR(Scenarios!F150/Scenarios!F17,0) -> 0 | D20: Exit Year | E20: =Scenarios!F86 -> 0
A21: Equity Required | B21: =Scenarios!F31 -> 0 | D21: Exit Cap Rate | E21: =Waterfall!B6 -> 0
A22: Down Payment % | B22: =Scenarios!F10 -> 0 | D22: Gross Sale Price | E22: =Waterfall!B32 -> 0
A23: Entry Cap Rate | B23: =IFERROR('P&L'!D97/Scenarios!F7,0) -> 0 | D23: Net to Equity (Exit) | E23: =Waterfall!B35 -> 0
A24: Stabilized Cap Rate (Y5) | B24: =IFERROR((IFERROR(INDEX('P&L'!D115:M116,1,Scenarios!F86),0)+IFERROR(INDEX('P&L'!D112:M113,1,Scenarios!F86),0))/Scenarios!F7,0) -> 0 | D24: Avg Annual Return (LP) | E24: =IFERROR((Waterfall!M54-(Waterfall!B9+Waterfall!B10))/(Waterfall!B9+Waterfall!B10)/Scenarios!F86,0) -> 0
A26: CAPITAL STACK
A27: Tranche | B27: Amount | C27: % | D27: Rate | E27: Term (yrs) | F27: Amort (yrs)
A28: Senior Loan (1st) | B28: =Scenarios!F92 -> 0 | C28: =IFERROR(Scenarios!F92/Scenarios!F17,0) -> 0 | D28: =Scenarios!F93 -> 0 | E28: =Scenarios!F124 -> 0 | F28: =Scenarios!F94 -> 0
A29: 2nd Loan | B29: =Scenarios!F128 -> 0 | C29: =IFERROR(Scenarios!F128/Scenarios!F17,0) -> 0 | D29: =Scenarios!F129 -> 0 | E29: =Scenarios!F131 -> 0 | F29: =Scenarios!F130 -> 0
A30: Supplemental | B30: =Scenarios!F135 -> 0 | C30: =IFERROR(Scenarios!F135/Scenarios!F17,0) -> 0 | D30: =Scenarios!F136 -> 0 | E30: =Scenarios!F138 -> 0 | F30: =Scenarios!F137 -> 0
A31: GP Equity | B31: =Scenarios!F32 -> 0 | C31: =Scenarios!F28 -> 0.6 | D31: — | E31: — | F31: —
A32: Class A LP Equity | B32: =Scenarios!F33 -> 0 | C32: =Scenarios!F29 -> 0.4 | D32: =Scenarios!F35 -> 0 | E32: — | F32: —
A33: Class B LP Equity | B33: =Scenarios!F34 -> 0 | C33: =Scenarios!F30 -> 0 | D33: — | E33: — | F33: —
A34: TOTAL | B34: =Scenarios!F31 -> 0 | C34: =IFERROR(Scenarios!F31/Scenarios!F17,0) -> 0 | D34: — | E34: — | F34: —
A36: INVESTOR RETURNS SUMMARY
A37: Metric | B37: Class A LP | C37: Class B LP | D37: LP Combined | E37: GP | F37: Notes
A38: Total Equity Invested | B38: =Waterfall!B9 -> 0 | C38: =Waterfall!B10 -> 0 | D38: =Waterfall!B9+Waterfall!B10 -> 0 | E38: =Waterfall!B8 -> 0 | F38: Capital contributed by each party
A39: Total Distributions | B39: =Waterfall!M55 -> 0 | C39: =Waterfall!M56 -> 0 | D39: =Waterfall!M57 -> 0 | E39: =Waterfall!M58 -> 0 | F39: Operating CF + exit proceeds
A40: Net Profit | B40: =Waterfall!M55-Waterfall!B9 -> 0 | C40: =IFERROR(Waterfall!M56-Waterfall!B10,0) -> 0 | D40: =Waterfall!M57-(Waterfall!B9+Waterfall!B10) -> 0 | E40: =Waterfall!M58-Waterfall!B8 -> 0
A41: Equity Multiple (EM) | B41: =IFERROR(Waterfall!B67,0) -> 0 | C41: =IFERROR(Waterfall!C67,0) -> 0 | D41: =IFERROR(Waterfall!D67,0) -> 0 | E41: =IFERROR(Waterfall!E67,0) -> 0 | F41: Total value returned / capital in
A42: IRR | B42: =Waterfall!B69 -> 0 | C42: =Waterfall!C69 -> 0 | D42: =Waterfall!D69 -> 0 | E42: =Waterfall!E69 -> 0 | F42: Includes exit proceeds
...

Sheet Prop Info
A1: PROPERTY INFORMATION & MARKET DATA
A2: Blue = manual input. Use the AI Market Research tool (separate app) to auto-populate market fields.
A3: PROPERTY DETAILS | B3: OM Data
A4: Property Name
A5: Location / Address
A6: # Units
A7: # Buildings
A8: Height (stories)
A9: Year Built
A10: Lot Size (acres)
A11: Gross Sq Ft
A12: Parking Spaces
A13: Asset Class (IL/AL/MC/Other/Mix) | C13: Other Care Type name (deal/state):
A14: License Type
A15: Licensed Bed Count
A16: IL Units
A17: AL Units
A18: MC Units
A19: ="Other Care ("&$D$13&") Units" -> Other Care () Units
A20: Occupied Beds — Total | B20: =SUM(B21:B24) -> 0
A21: Occupied Beds — IL
A22: Occupied Beds — AL
A23: Occupied Beds — MC
A24: ="Occupied Beds — Other Care ("&$D$13&")" -> Occupied Beds — Other Care ()
A25: MARKET DATA | B25: OM Data | C25: Market Research Data | D25: Links
A26: City / Market
A27: MSA Name
A28: MSA Population
A29: City Population
A30: MSA Population Growth Rate
A31: City Population Growth Rate
A32: Senior 65+ Population
A33: Senior 65+ Growth Rate
A34: Avg Household Income
A35: Median Income
A36: School Ratings (1-10)
A37: COMPETITIVE MARKET | B37: OM Data | C37: Market Research Data | D37: Links
A38: Avg Monthly Base Rent — IL
A39: Avg Monthly Base Rent — AL
A40: Avg Monthly Base Rent — MC
...

Sheet Scenarios
A1: SIDE-BY-SIDE SCENARIO ANALYSIS — "The 10-Minute Offer"
A2: Active Scenario → | B2: Actuals (T-12)
A3: Selecting an active scenario drives P&L, Cover Sheet, and Waterfall calculations. All 4 columns always visible for comparison.
A4: Line Item | B4: Actuals (T-12) | C4: 2. My Version | D4: 3. Projected | E4: 4. Best Scenario | F4: Active Scenario | G4: Licensed Beds / $/Bed | H4: Benchmark
A5: ACQUISITION
A6: Asking Price | C6: =B6 -> 0 | D6: =C6 -> 0 | E6: =D6 -> 0 | F6: =CHOOSE(MATCH(B$2,$B$4:$E$4,0),B6,C6,D6,E6) -> 0 | G6: =IFERROR(F6/F$8,0) -> 0 | H6: $8–16M typical 60-unit AL/MC
A7: Purchase Price / Offer | C7: =B7 -> 0 | D7: =C7 -> 0 | E7: =D7 -> 0 | F7: =CHOOSE(MATCH(B$2,$B$4:$E$4,0),B7,C7,D7,E7) -> 0 | G7: =IFERROR(F7/F$8,0) -> 0 | H7: Offer 5–15% below ask; value-add
A8: # Units (rooms) / Licensed Beds | C8: =Units -> 0 | D8: =C8 -> 0 | E8: =D8 -> 0 | F8: =CHOOSE(MATCH(B$2,$B$4:$E$4,0),B8,C8,D8,E8) -> 0 | G8: ='Prop Info'!$B$15 -> 0 | H8: Licensed beds from Prop Info — drives GPR. Units = physical rooms.
A9: Price Per Unit (physical room) | B9: =IFERROR(B7/B8,"") | C9: =IFERROR(C7/C8,"") | D9: =IFERROR(D7/D8,"") | E9: =IFERROR(E7/E8,"") | F9: =IFERROR(CHOOSE(MATCH(B$2,$B$4:$E$4,0),B9,C9,D9,E9),"") | G9: =IFERROR(F7/'Prop Info'!$B$15,"") | H9: Price per licensed bed = purchase price ÷ licensed beds
A10: Down Payment % | C10: =B10 -> 0 | D10: =C10 -> 0 | E10: =D10 -> 0 | F10: =CHOOSE(MATCH(B$2,$B$4:$E$4,0),B10,C10,D10,E10) -> 0 | H10: 25–35% down; 65–75% LTV target
A11: Down Payment $ | B11: =B10*B7 -> 0 | C11: =C10*C7 -> 0 | D11: =D10*D7 -> 0 | E11: =E10*E7 -> 0 | F11: =CHOOSE(MATCH(B$2,$B$4:$E$4,0),B11,C11,D11,E11) -> 0 | G11: =IFERROR(F11/F$8,0) -> 0 | H11: Auto-calculated from down payment
A12: Repairs / CapEx at Close | B12: =Capex!$D$51 -> 0 | C12: =B12 -> 0 | D12: =Capex!$D$51 -> 0 | E12: =Capex!$D$51 -> 0 | F12: =CHOOSE(MATCH(B$2,$B$4:$E$4,0),B12,C12,D12,E12) -> 0 | G12: =IFERROR(F12/F$8,0) -> 0 | H12: Get contractor bid at LOI stage
A13: Operating Reserves | B13: =(B124/12)*$G$13 -> 0 | C13: =B13 -> 0 | D13: =C13 -> 0 | E13: =D13 -> 0 | F13: =CHOOSE(MATCH(B$2,$B$4:$E$4,0),B13,C13,D13,E13) -> 0 | G13: 1 | H13: 3–6 months operating expenses
A14: Est. Closing Costs | B14: ='Acquisition Costs'!$D$37 | C14: ='Acquisition Costs'!$D$37 | D14: ='Acquisition Costs'!$D$37 | E14: ='Acquisition Costs'!$D$37 | F14: =CHOOSE(MATCH(B$2,$B$4:$E$4,0),B14,C14,D14,E14) | G14: =IFERROR(F14/F7,"") | H14: 1.5–2.5% of purchase price
A15: Acquisition Fee (%) | B15: 0 | C15: =B15 -> 0 | D15: =C15 -> 0 | E15: =D15 -> 0 | F15: =CHOOSE(MATCH(B$2,$B$4:$E$4,0),B15,C15,D15,E15) -> 0 | H15: 0.5–1.5% acq fee standard
A16: Acquisition Fee ($) | B16: =B15*B7 -> 0 | C16: =C15*C7 -> 0 | D16: =D15*D7 -> 0 | E16: =E15*E7 -> 0 | F16: =CHOOSE(MATCH(B$2,$B$4:$E$4,0),B16,C16,D16,E16) -> 0 | G16: =IFERROR(F16/F$8,0) -> 0 | H16: Auto-calculated
A17: TOTAL ACQUISITION COST | B17: =IFERROR(B7+B12+B13+B14+B16,"") | C17: =IFERROR(C7+C12+C13+C14+C16,"") | D17: =IFERROR(D7+D12+D13+D14+D16,"") | E17: =IFERROR(E7+E12+E13+E14+E16,"") | F17: =IFERROR(CHOOSE(MATCH(B$2,$B$4:$E$4,0),B17,C17,D17,E17),"") | G17: =IFERROR(F17/F$8,"") | H17: Auto-calculated total cost
A19: DEBT STRUCTURE
A20: Loan Amount (1st) | B20: =B141 -> 0 | C20: =C141 -> 0 | D20: =D141 -> 0 | E20: =E141 -> 0 | F20: =CHOOSE(MATCH(B$2,$B$4:$E$4,0),B20,C20,D20,E20) -> 0 | H20: 60–70% LTV senior; 75% bridge max
A21: Loan Amount (2nd) | B21: =B148 -> 0 | C21: =C148 -> 0 | D21: =D148 -> 0 | E21: =E148 -> 0 | F21: =CHOOSE(MATCH(B$2,$B$4:$E$4,0),B21,C21,D21,E21) -> 0 | H21: $0 if no mezz; up to 10% of stack
A22: Supplemental Loan | B22: =B155 -> 0 | C22: =C155 -> 0 | D22: =D155 -> 0 | E22: =E155 -> 0 | F22: =CHOOSE(MATCH(B$2,$B$4:$E$4,0),B22,C22,D22,E22) -> 0 | H22: $0 supplemental; add if SBA/seller
A23: Total Debt | B23: =B20+B21+B22 -> 0 | C23: =C20+C21+C22 -> 0 | D23: =D20+D21+D22 -> 0 | E23: =E20+E21+E22 -> 0 | F23: =CHOOSE(MATCH(B$2,$B$4:$E$4,0),B23,C23,D23,E23) -> 0 | H23: Auto-calculated total debt
A24: LTV (Loan/Purchase Price) | B24: =IFERROR(B23/B7,0) -> 0 | C24: =IFERROR(C23/C7,0) -> 0 | D24: =IFERROR(D23/D7,0) -> 0 | E24: =IFERROR(E23/E7,0) -> 0 | F24: =CHOOSE(MATCH(B$2,$B$4:$E$4,0),B24,C24,D24,E24) -> 0 | H24: Target ≤70% LTV (senior only)
A25: LTC (Loan/Total Acq. Cost) | B25: =IFERROR(B23/B17,0) -> 0 | C25: =IFERROR(C23/C17,0) -> 0 | D25: =IFERROR(D23/D17,0) -> 0 | E25: =IFERROR(E23/E17,0) -> 0 | F25: =CHOOSE(MATCH(B$2,$B$4:$E$4,0),B25,C25,D25,E25) -> 0 | H25: Target ≤80–85% LTC (value-add)
A27: EQUITY STRUCTURE
A28: GP Ownership % | B28: 0.6 | C28: =B28 -> 0.6 | D28: =C28 -> 0.6 | E28: =D28 -> 0.6 | F28: =CHOOSE(MATCH(B$2,$B$4:$E$4,0),B28,C28,D28,E28) -> 0.6 | H28: GP co-invest 5–15% of total equity
A29: Class A LP % | B29: =1-B28 -> 0.4 | C29: =1-C28 -> 0.4 | D29: =1-D28 -> 0.4 | E29: =1-E28 -> 0.4 | F29: =CHOOSE(MATCH(B$2,$B$4:$E$4,0),B29,C29,D29,E29) -> 0.4 | H29: Class A LP 40–65% of total equity
A30: Class B LP % (auto) | B30: =1-B28-B29 -> 0 | C30: =1-C28-C29 -> 0 | D30: =1-D28-D29 -> 0 | E30: =1-E28-E29 -> 0 | F30: =CHOOSE(MATCH(B$2,$B$4:$E$4,0),B30,C30,D30,E30) -> 0 | H30: Class B LP 20–40% of total equity
A31: Total Equity (Acq Cost − Debt) | B31: =IFERROR(B17-B170,0) -> 0 | C31: =IFERROR(C17-C170,0) -> 0 | D31: =IFERROR(D17-D170,0) -> 0 | E31: =IFERROR(E17-E170,0) -> 0 | F31: =CHOOSE(MATCH(B$2,$B$4:$E$4,0),B31,C31,D31,E31) -> 0 | H31: Auto-calculated
A32: GP Equity ($) | C32: =B32 -> 0 | D32: =C32 -> 0 | E32: =D32 -> 0 | F32: =CHOOSE(MATCH(B$2,$B$4:$E$4,0),B32,C32,D32,E32) -> 0 | H32: Enter GP co-invest $ directly — not tied to GP Ownership %
A33: Class A LP Equity ($) | B33: =B31-B32 -> 0 | C33: =C31-C32 -> 0 | D33: =D31-D32 -> 0 | E33: =E31-E32 -> 0 | F33: =CHOOSE(MATCH(B$2,$B$4:$E$4,0),B33,C33,D33,E33) -> 0 | H33: Total Equity − GP co-invest. GP can be $0 (all-LP deal).
A34: Class B LP Equity ($) | B34: =B30*B31 -> 0 | C34: =C30*C31 -> 0 | D34: =D30*D31 -> 0 | E34: =E30*E31 -> 0 | F34: =CHOOSE(MATCH(B$2,$B$4:$E$4,0),B34,C34,D34,E34) -> 0 | H34: Auto-calculated
A35: Class A Preferred Return % | B35: 0 | C35: =B35 -> 0 | D35: =C35 -> 0 | E35: =D35 -> 0 | F35: =CHOOSE(MATCH(B$2,$B$4:$E$4,0),B35,C35,D35,E35) -> 0 | H35: Class A pref: 6–9% typical
A36: GP Promote % (defaults to GP% — edit to override) | B36: =B28 -> 0.6 | C36: =C28 -> 0.6 | D36: =D28 -> 0.6 | E36: =E28 -> 0.6 | F36: =CHOOSE(MATCH(B$2,$B$4:$E$4,0),B36,C36,D36,E36) -> 0.6 | H36: Promote: 20–30% GP typical. Edit directly.
A37: INCOME (YEAR 1 SNAPSHOT) — 4-Scenario Model
A38: ── INDEPENDENT LIVING (IL) ──
A39: Licensed Beds — IL | B39: 0 | C39: =B39 -> 0 | D39: =C39 -> 0 | E39: =D39 -> 0 | F39: =CHOOSE(MATCH(B$2,$B$4:$E$4,0),B39,C39,D39,E39) -> 0 | H39: Independent Living bed count
A40: Avg Monthly Rate — IL | B40: 0 | C40: =B40 -> 0 | D40: =C40 -> 0 | E40: =D40 -> 0 | F40: =CHOOSE(MATCH(B$2,$B$4:$E$4,0),B40,C40,D40,E40) -> 0 | H40: IL blended market rate — pull from rent roll
A41: GPR — IL | B41: =B39*B40*12 -> 0 | C41: =C39*C40*12 -> 0 | D41: =D39*D40*12 -> 0 | E41: =E39*E40*12 -> 0 | F41: =CHOOSE(MATCH(B$2,$B$4:$E$4,0),B41,C41,D41,E41) -> 0 | G41: =IFERROR(F41/F$63/12,0) -> 0 | H41: Annual gross potential rent at full IL occupancy
A42: Vacancy % — IL | B42: 0 | C42: =B42 -> 0 | D42: =C42 -> 0 | E42: =D42 -> 0 | F42: =CHOOSE(MATCH(B$2,$B$4:$E$4,0),B42,C42,D42,E42) -> 0 | H42: 10% typical stabilized
...

Sheet P&L
A1: P&L — 10-YEAR PRO FORMA PROJECTIONS (Active Scenario drives all inputs)
A2: Blue = input | Black = formula | Green = cross-sheet. Escalators auto-pulled from annual averages. Override any cell and highlight yellow.
A4: ESCALATORS & ASSUMPTIONS | D4: Year 1 | E4: Year 2 | F4: Year 3 | G4: Year 4 | H4: Year 5 | I4: Year 6 | J4: Year 7 | K4: Year 8 | L4: Year 9 | M4: Year 10
A5: Annual Revenue Escalator | C5: — | D5: 0.04 | E5: 0.04 | F5: 0.04 | G5: 0.04 | H5: =G5 -> 0.04 | I5: =H5 -> 0.04 | J5: =I5 -> 0.04 | K5: =J5 -> 0.04 | L5: =K5 -> 0.04 | M5: =L5 -> 0.04 | N5: Avg: | O5: =AVERAGE(D5:M5) -> 0.04
A6: Annual Expense Escalator | C6: — | D6: 0.03 | E6: 0.03 | F6: 0.03 | G6: 0.03 | H6: 0.03 | I6: =H6 -> 0.03 | J6: =I6 -> 0.03 | K6: =J6 -> 0.03 | L6: =K6 -> 0.03 | M6: =L6 -> 0.03 | N6: Avg: | O6: =AVERAGE(D6:M6) -> 0.03
A8: Line Item | C8: T-12 Actual | D8: Year 1 | E8: Year 2 | F8: Year 3 | G8: Year 4 | H8: Year 5 | I8: Year 6 | J8: Year 7 | K8: Year 8 | L8: Year 9 | M8: Year 10 | N8: Total (Y1–Y5) | O8: Total (Y1–Y10) | P8: Avg / Yr | Q8: Y1 % EGI / Y1 Value
A9: INCOME
A10: Avg. Rent / Bed | C10: =IFERROR((C43/C42)/12,0) -> 0 | D10: =IFERROR((D43/D42)/12,0) -> 0 | E10: =IFERROR((E43/E42)/12,0) -> 0 | F10: =IFERROR((F43/F42)/12,0) -> 0 | G10: =IFERROR((G43/G42)/12,0) -> 0 | H10: =IFERROR((H43/H42)/12,0) -> 0 | I10: =IFERROR((I43/I42)/12,0) -> 0 | J10: =IFERROR((J43/J42)/12,0) -> 0 | ... M10: =IFERROR((M43/M42)/12,0) -> 0
A11: ── INDEPENDENT LIVING (IL) ──
A12: Licensed Beds — IL | C12: =Scenarios!B39 -> 0 | D12: =Scenarios!F39 -> 0 | E12: =D12 -> 0 | F12: =E12 -> 0 | G12: =F12 -> 0 | H12: =G12 -> 0 | I12: =H12 -> 0 | J12: =I12 -> 0 | K12: =J12 -> 0 | L12: =K12 -> 0 | M12: =L12 -> 0
A13: Avg Monthly Rate — IL | C13: =Scenarios!B40 -> 0 | D13: =Scenarios!F40 -> 0 | E13: =D13*(1+E$5) -> 0 | F13: =E13*(1+F$5) -> 0 | G13: =F13*(1+G$5) -> 0 | H13: =G13*(1+H$5) -> 0 | I13: =H13*(1+I$5) -> 0 | J13: =I13*(1+J$5) -> 0 | K13: =J13*(1+K$5) -> 0 | L13: =K13*(1+L$5) -> 0 | M13: =L13*(1+M$5) -> 0
A14: GPR — IL | C14: =C12*C13*12 -> 0 | D14: =D12*D13*12 -> 0 | E14: =E12*E13*12 -> 0 | F14: =F12*F13*12 -> 0 | G14: =G12*G13*12 -> 0 | H14: =H12*H13*12 -> 0 | I14: =I12*I13*12 -> 0 | J14: =J12*J13*12 -> 0 | ... M14: =M12*M13*12 -> 0 | N14: =SUM(D14:H14) -> 0 | O14: =SUM(D14:M14) -> 0 | P14: =IFERROR(O14/10,0) -> 0 | Q14: =IFERROR(D14/$D$50,0) -> 0
A15: Vacancy % — IL | C15: =Scenarios!B42 -> 0 | D15: =Scenarios!F42 -> 0 | E15: =D15 -> 0 | F15: =E15 -> 0 | G15: =F15 -> 0 | H15: =G15 -> 0 | I15: =H15 -> 0 | J15: =I15 -> 0 | K15: =J15 -> 0 | L15: =K15 -> 0 | M15: =L15 -> 0
A16: Less: Vacancy — IL | C16: =IFERROR(-C15*C14,0) -> 0 | D16: =IFERROR(-D15*D14,0) -> 0 | E16: =IFERROR(-E15*E14,0) -> 0 | F16: =IFERROR(-F15*F14,0) -> 0 | G16: =IFERROR(-G15*G14,0) -> 0 | H16: =IFERROR(-H15*H14,0) -> 0 | I16: =IFERROR(-I15*I14,0) -> 0 | J16: =IFERROR(-J15*J14,0) -> 0 | ... M16: =IFERROR(-M15*M14,0) -> 0
A17: Loss to Lease % — IL | C17: =Scenarios!B68 -> 0 | D17: =Scenarios!F68 -> 0 | E17: =D17 -> 0 | F17: =E17 -> 0 | G17: =F17 -> 0 | H17: =G17 -> 0 | I17: =H17 -> 0 | J17: =I17 -> 0 | K17: =J17 -> 0 | L17: =K17 -> 0 | M17: =L17 -> 0
A18: Less: Loss to Lease — IL | C18: =IFERROR(-C17*C14,0) -> 0 | D18: =IFERROR(-D17*D14,0) -> 0 | E18: =IFERROR(-E17*E14,0) -> 0 | F18: =IFERROR(-F17*F14,0) -> 0 | G18: =IFERROR(-G17*G14,0) -> 0 | H18: =IFERROR(-H17*H14,0) -> 0 | I18: =IFERROR(-I17*I14,0) -> 0 | J18: =IFERROR(-J17*J14,0) -> 0 | ... M18: =IFERROR(-M17*M14,0) -> 0
A19: Bad Debt / Concessions % — IL | C19: =Scenarios!B70 -> 0 | D19: =Scenarios!F70 -> 0 | E19: =D19 -> 0 | F19: =E19 -> 0 | G19: =F19 -> 0 | H19: =G19 -> 0 | I19: =H19 -> 0 | J19: =I19 -> 0 | K19: =J19 -> 0 | L19: =K19 -> 0 | M19: =L19 -> 0
A20: Less: Concessions/Bad Debt — IL | C20: =IFERROR(-C19*C14,0) -> 0 | D20: =IFERROR(-D19*D14,0) -> 0 | E20: =IFERROR(-E19*E14,0) -> 0 | F20: =IFERROR(-F19*F14,0) -> 0 | G20: =IFERROR(-G19*G14,0) -> 0 | H20: =IFERROR(-H19*H14,0) -> 0 | I20: =IFERROR(-I19*I14,0) -> 0 | J20: =IFERROR(-J19*J14,0) -> 0 | ... M20: =IFERROR(-M19*M14,0) -> 0
A21: ── ASSISTED LIVING (AL) ──
A22: Licensed Beds — AL | C22: =Scenarios!B45 -> 0 | D22: =Scenarios!F45 -> 0 | E22: =D22 -> 0 | F22: =E22 -> 0 | G22: =F22 -> 0 | H22: =G22 -> 0 | I22: =H22 -> 0 | J22: =I22 -> 0 | K22: =J22 -> 0 | L22: =K22 -> 0 | M22: =L22 -> 0
A23: Avg Monthly Rate — AL | C23: =Scenarios!B46 -> 0 | D23: =Scenarios!F46 -> 0 | E23: =D23*(1+E$5) -> 0 | F23: =E23*(1+F$5) -> 0 | G23: =F23*(1+G$5) -> 0 | H23: =G23*(1+H$5) -> 0 | I23: =H23*(1+I$5) -> 0 | J23: =I23*(1+J$5) -> 0 | K23: =J23*(1+K$5) -> 0 | L23: =K23*(1+L$5) -> 0 | M23: =L23*(1+M$5) -> 0
A24: GPR — AL | C24: =C22*C23*12 -> 0 | D24: =D22*D23*12 -> 0 | E24: =E22*E23*12 -> 0 | F24: =F22*F23*12 -> 0 | G24: =G22*G23*12 -> 0 | H24: =H22*H23*12 -> 0 | I24: =I22*I23*12 -> 0 | J24: =J22*J23*12 -> 0 | ... M24: =M22*M23*12 -> 0 | N24: =SUM(D24:H24) -> 0 | O24: =SUM(D24:M24) -> 0 | P24: =IFERROR(O24/10,0) -> 0 | Q24: =IFERROR(D24/$D$50,0) -> 0
A25: Vacancy % — AL | C25: =Scenarios!B48 -> 0 | D25: =Scenarios!F48 -> 0 | E25: =D25 -> 0 | F25: =E25 -> 0 | G25: =F25 -> 0 | H25: =G25 -> 0 | I25: =H25 -> 0 | J25: =I25 -> 0 | K25: =J25 -> 0 | L25: =K25 -> 0 | M25: =L25 -> 0
A26: Less: Vacancy — AL | C26: =IFERROR(-C25*C24,0) -> 0 | D26: =IFERROR(-D25*D24,0) -> 0 | E26: =IFERROR(-E25*E24,0) -> 0 | F26: =IFERROR(-F25*F24,0) -> 0 | G26: =IFERROR(-G25*G24,0) -> 0 | H26: =IFERROR(-H25*H24,0) -> 0 | I26: =IFERROR(-I25*I24,0) -> 0 | J26: =IFERROR(-J25*J24,0) -> 0 | ... M26: =IFERROR(-M25*M24,0) -> 0
A27: Loss to Lease % — AL | C27: =Scenarios!B68 -> 0 | D27: =Scenarios!F68 -> 0 | E27: =D27 -> 0 | F27: =E27 -> 0 | G27: =F27 -> 0 | H27: =G27 -> 0 | I27: =H27 -> 0 | J27: =I27 -> 0 | K27: =J27 -> 0 | L27: =K27 -> 0 | M27: =L27 -> 0
A28: Less: Loss to Lease — AL | C28: =IFERROR(-C27*C24,0) -> 0 | D28: =IFERROR(-D27*D24,0) -> 0 | E28: =IFERROR(-E27*E24,0) -> 0 | F28: =IFERROR(-F27*F24,0) -> 0 | G28: =IFERROR(-G27*G24,0) -> 0 | H28: =IFERROR(-H27*H24,0) -> 0 | I28: =IFERROR(-I27*I24,0) -> 0 | J28: =IFERROR(-J27*J24,0) -> 0 | ... M28: =IFERROR(-M27*M24,0) -> 0
A29: Bad Debt / Concessions % — AL | C29: =Scenarios!B70 -> 0 | D29: =Scenarios!F70 -> 0 | E29: =D29 -> 0 | F29: =E29 -> 0 | G29: =F29 -> 0 | H29: =G29 -> 0 | I29: =H29 -> 0 | J29: =I29 -> 0 | K29: =J29 -> 0 | L29: =K29 -> 0 | M29: =L29 -> 0
A30: Less: Concessions/Bad Debt — AL | C30: =IFERROR(-C29*C24,0) -> 0 | D30: =IFERROR(-D29*D24,0) -> 0 | E30: =IFERROR(-E29*E24,0) -> 0 | F30: =IFERROR(-F29*F24,0) -> 0 | G30: =IFERROR(-G29*G24,0) -> 0 | H30: =IFERROR(-H29*H24,0) -> 0 | I30: =IFERROR(-I29*I24,0) -> 0 | J30: =IFERROR(-J29*J24,0) -> 0 | ... M30: =IFERROR(-M29*M24,0) -> 0
A31: ── MEMORY CARE (MC) ──
A32: Licensed Beds — MC | C32: =Scenarios!B51 -> 0 | D32: =Scenarios!F51 -> 0 | E32: =D32 -> 0 | F32: =E32 -> 0 | G32: =F32 -> 0 | H32: =G32 -> 0 | I32: =H32 -> 0 | J32: =I32 -> 0 | K32: =J32 -> 0 | L32: =K32 -> 0 | M32: =L32 -> 0
A33: Avg Monthly Rate — MC | C33: =Scenarios!B52 -> 0 | D33: =Scenarios!F52 -> 0 | E33: =D33*(1+E$5) -> 0 | F33: =E33*(1+F$5) -> 0 | G33: =F33*(1+G$5) -> 0 | H33: =G33*(1+H$5) -> 0 | I33: =H33*(1+I$5) -> 0 | J33: =I33*(1+J$5) -> 0 | K33: =J33*(1+K$5) -> 0 | L33: =K33*(1+L$5) -> 0 | M33: =L33*(1+M$5) -> 0
A34: GPR — MC | C34: =C32*C33*12 -> 0 | D34: =D32*D33*12 -> 0 | E34: =E32*E33*12 -> 0 | F34: =F32*F33*12 -> 0 | G34: =G32*G33*12 -> 0 | H34: =H32*H33*12 -> 0 | I34: =I32*I33*12 -> 0 | J34: =J32*J33*12 -> 0 | ... M34: =M32*M33*12 -> 0 | N34: =SUM(D34:H34) -> 0 | O34: =SUM(D34:M34) -> 0 | P34: =IFERROR(O34/10,0) -> 0 | Q34: =IFERROR(D34/$D$50,0) -> 0
A35: Vacancy % — MC | C35: =Scenarios!B54 -> 0 | D35: =Scenarios!F54 -> 0 | E35: =D35 -> 0 | F35: =E35 -> 0 | G35: =F35 -> 0 | H35: =G35 -> 0 | I35: =H35 -> 0 | J35: =I35 -> 0 | K35: =J35 -> 0 | L35: =K35 -> 0 | M35: =L35 -> 0
A36: Less: Vacancy — MC | C36: =IFERROR(-C35*C34,0) -> 0 | D36: =IFERROR(-D35*D34,0) -> 0 | E36: =IFERROR(-E35*E34,0) -> 0 | F36: =IFERROR(-F35*F34,0) -> 0 | G36: =IFERROR(-G35*G34,0) -> 0 | H36: =IFERROR(-H35*H34,0) -> 0 | I36: =IFERROR(-I35*I34,0) -> 0 | J36: =IFERROR(-J35*J34,0) -> 0 | ... M36: =IFERROR(-M35*M34,0) -> 0
A37: Loss to Lease % — MC | C37: =Scenarios!B68 -> 0 | D37: =Scenarios!F68 -> 0 | E37: =D37 -> 0 | F37: =E37 -> 0 | G37: =F37 -> 0 | H37: =G37 -> 0 | I37: =H37 -> 0 | J37: =I37 -> 0 | K37: =J37 -> 0 | L37: =K37 -> 0 | M37: =L37 -> 0
A38: Less: Loss to Lease — MC | C38: =IFERROR(-C37*C34,0) -> 0 | D38: =IFERROR(-D37*D34,0) -> 0 | E38: =IFERROR(-E37*E34,0) -> 0 | F38: =IFERROR(-F37*F34,0) -> 0 | G38: =IFERROR(-G37*G34,0) -> 0 | H38: =IFERROR(-H37*H34,0) -> 0 | I38: =IFERROR(-I37*I34,0) -> 0 | J38: =IFERROR(-J37*J34,0) -> 0 | ... M38: =IFERROR(-M37*M34,0) -> 0
A39: Bad Debt / Concessions % — MC | C39: =Scenarios!B70 -> 0 | D39: =Scenarios!F70 -> 0 | E39: =D39 -> 0 | F39: =E39 -> 0 | G39: =F39 -> 0 | H39: =G39 -> 0 | I39: =H39 -> 0 | J39: =I39 -> 0 | K39: =J39 -> 0 | L39: =K39 -> 0 | M39: =L39 -> 0
A40: Less: Concessions/Bad Debt — MC | C40: =IFERROR(-C39*C34,0) -> 0 | D40: =IFERROR(-D39*D34,0) -> 0 | E40: =IFERROR(-E39*E34,0) -> 0 | F40: =IFERROR(-F39*F34,0) -> 0 | G40: =IFERROR(-G39*G34,0) -> 0 | H40: =IFERROR(-H39*H34,0) -> 0 | I40: =IFERROR(-I39*I34,0) -> 0 | J40: =IFERROR(-J39*J34,0) -> 0 | ... M40: =IFERROR(-M39*M34,0) -> 0
A41: ── SUMMARY ROLLUP ──
A42: Total Licensed Beds | C42: =C12+C22+C32 -> 0 | D42: =D12+D22+D32 -> 0 | E42: =E12+E22+E32 -> 0 | F42: =F12+F22+F32 -> 0 | G42: =G12+G22+G32 -> 0 | H42: =H12+H22+H32 -> 0 | I42: =I12+I22+I32 -> 0 | J42: =J12+J22+J32 -> 0 | ... M42: =M12+M22+M32 -> 0 | N42: =D42 -> 0 | O42: =D42 -> 0 | P42: =D42 -> 0
...

Sheet T-12 Analysis
A1: T-12 ANALYSIS — Trailing 12 Diagnostic Layer (Senior Living)
A2: ANALYSIS on top. Standardized aggregation (Layer 3) and raw paste block (Layer 1) below — scroll down to access data. Per Bed/Month uses occupied beds from Rent Roll Analysis. Benchmarks calibrated to assisted/memory care community norms.
A4: B. RECONCILIATION CHECK — Are all raw lines mapped?
A5: EGI: | B5: =N80 -> 0 | C5: OpEx: | D5: =N132 -> 0 | E5: EBITDAR: | F5: =N135 -> 0 | G5: Unmapped $: | H5: 0 | I5: 🟢 all mapped | L5: EGI / Occ Bed / Mo: | M5: 0
A7: C. TREND ANALYSIS — T-3 vs. T-6 vs. T-12 (annualized)
A8: Metric | B8: T-12 Actual | C8: T-6 Annlzd | D8: T-3 Annlzd | E8: T-3 vs T-12 Δ$ | F8: T-3 vs T-12 Δ% | G8: Direction | H8: Read
A9: EGI | B9: =N80 -> 0 | C9: =(SUM(H58:M61)+SUM(H63:M66)+SUM(H68:M79))*2 -> 0 | D9: =(SUM(K58:M61)+SUM(K63:M66)+SUM(K68:M79))*4 -> 0 | E9: =D9-B9 -> 0 | F9: =IFERROR((D9-B9)/B9,0) -> 0 | G9: =IF(ABS(F9)<0.02,"→ stable",IF(F9>0,"↑ rising","↓ falling")) -> → stable | H9: =IF(ABS(F9)<0.05,"stable","review") -> stable
A10: Total OpEx | B10: =N132 -> 0 | C10: =SUM(H132:M132)*2 -> 0 | D10: =SUM(K132:M132)*4 -> 0 | E10: =D10-B10 -> 0 | F10: =IFERROR((D10-B10)/B10,0) -> 0 | G10: =IF(ABS(F10)<0.02,"→ stable",IF(F10>0,"↑ rising","↓ falling")) -> → stable | H10: =IF(ABS(F10)<0.05,"stable","review") -> stable
A11: EBITDAR | B11: =N80-N132 -> 0 | C11: =C9-C10 -> 0 | D11: =D9-D10 -> 0 | E11: =D11-B11 -> 0 | F11: =IFERROR((D11-B11)/B11,0) -> 0 | G11: =IF(ABS(F11)<0.02,"→ stable",IF(F11>0,"↑ rising","↓ falling")) -> → stable | H11: =IF(ABS(F11)<0.05,"stable","review") -> stable
A12: Bad Debt + Write-offs | B12: =-N79 -> 0 | C12: =-SUM(H79:M79)*2 -> 0 | D12: =-SUM(K79:M79)*4 -> 0 | E12: =D12-B12 -> 0 | F12: =IFERROR((D12-B12)/B12,0) -> 0 | G12: =IF(ABS(F12)<0.02,"→ stable",IF(F12>0,"↑ rising","↓ falling")) -> → stable | H12: =IF(ABS(F12)<0.05,"stable","review") -> stable
A13: Total Labor & Burden | B13: =N102 -> 0 | C13: =SUM(H102:M102)*2 -> 0 | D13: =SUM(K102:M102)*4 -> 0 | E13: =D13-B13 -> 0 | F13: =IFERROR((D13-B13)/B13,0) -> 0 | G13: =IF(ABS(F13)<0.02,"→ stable",IF(F13>0,"↑ rising","↓ falling")) -> → stable | H13: =IF(ABS(F13)<0.05,"stable","review") -> stable
A14: Food Cost | B14: =N104 -> 0 | C14: =SUM(H104:M104)*2 -> 0 | D14: =SUM(K104:M104)*4 -> 0 | E14: =D14-B14 -> 0 | F14: =IFERROR((D14-B14)/B14,0) -> 0 | G14: =IF(ABS(F14)<0.02,"→ stable",IF(F14>0,"↑ rising","↓ falling")) -> → stable | H14: =IF(ABS(F14)<0.05,"stable","review") -> stable
A15: Utilities | B15: =N113 -> 0 | C15: =SUM(H113:M113)*2 -> 0 | D15: =SUM(K113:M113)*4 -> 0 | E15: =D15-B15 -> 0 | F15: =IFERROR((D15-B15)/B15,0) -> 0 | G15: =IF(ABS(F15)<0.02,"→ stable",IF(F15>0,"↑ rising","↓ falling")) -> → stable | H15: =IF(ABS(F15)<0.05,"stable","review") -> stable
A16: Overtime Wages | B16: =N96 -> 0 | C16: =SUM(H96:M96)*2 -> 0 | D16: =SUM(K96:M96)*4 -> 0 | E16: =D16-B16 -> 0 | F16: =IFERROR((D16-B16)/B16,0) -> 0 | G16: =IF(ABS(F16)<0.02,"→ stable",IF(F16>0,"↑ rising","↓ falling")) -> → stable | H16: =IF(ABS(F16)<0.05,"stable","review") -> stable
A18: D. ECONOMIC vs. PHYSICAL OCCUPANCY RECONCILIATION
A19: Licensed Beds (IL + AL + MC)
A20: Physically Occupied Beds
A21: Physical Occupancy % | B21: =IFERROR(B20/B19,0) -> 0
A22: Gross Potential Rent / GPR (annual) | B22: =N83 -> 0
A23: Net Rent Revenue (billed) | B23: =N86 -> 0
A24: Total Revenue / EGI | B24: =N80 -> 0
A25: Economic Occupancy % (Net Rent / GPR) | B25: =IFERROR(B23/B22,0) -> 0
A26: Economic vs. Physical Gap | B26: =B21-B25 -> 0
A27: → Lost Revenue from Gap ($) | B27: =B22*B26 -> 0
A29: E. BAD DEBT & WRITE-OFF LAYERED ANALYSIS
A30: Component | B30: Amount | C30: % of GPR | D30: Per Bed/Mo | E30: Benchmark | F30: Read
A31: Vacancy Loss | B31: =-N77 -> 0 | C31: =IFERROR(B31/$B$22,0) -> 0 | D31: =IFERROR(B31/($B$19*12),0) -> 0 | E31: 5–10% GPR | F31: ok
A32: Bad Debt / Write-offs | B32: =-N79 -> 0 | C32: =IFERROR(B32/$B$22,0) -> 0 | D32: =IFERROR(B32/($B$19*12),0) -> 0 | E32: 1–3% GPR | F32: ok
A33: Concessions & Specials | B33: =-N78 -> 0 | C33: =IFERROR(B33/$B$22,0) -> 0 | D33: =IFERROR(B33/($B$19*12),0) -> 0 | E33: 0.5–2% GPR | F33: ok
A34: Delinquency Change | B34: 0 | C34: =IFERROR(B34/$B$22,0) -> 0 | D34: =IFERROR(B34/($B$19*12),0) -> 0 | E34: <2% GPR | F34: ok
A35: Total Rent Reductions | B35: =SUM(B31:B34) -> 0 | C35: =IFERROR(B35/$B$22,0) -> 0 | D35: =IFERROR(B35/($B$19*12),0) -> 0 | F35: ok
A37: F. TAX & INSURANCE ACCRUAL CHECK
A38: T-12 actuals rarely equal pro forma. Triangulate RE taxes with reassessment estimate; insurance with lender quote.
A40: Real Estate Taxes
A41: T-12 Actual | B41: =N120 -> 0
A42: Pro Forma Estimate | B42: ='P&L'!D86 -> 0
A43: Variance (Actual − PF) | B43: =B41-B42 -> 0
A44: Status | B44: =IF(B41=0,"⚠ not in T-12 — verify with operator / broker",IF(IFERROR(ABS(B43)/B42,1)>0.1,"⚠ variance >10% — review","✓ in range")) -> ⚠ not in T-12 — verify with operator / broker
A46: P&C Insurance
A47: T-12 Actual | B47: =N115 -> 0
...

Sheet Acquisition Costs
A1: ACQUISITION COSTS — USE OF CAPITAL
A3: USE OF CAPITAL SUMMARY
A4: Purchase Price | D4: =Scenarios!F7 -> 0
A5: Less: Total Loan Amount | D5: =-Scenarios!F23 -> 0
A6: Down Payment Required | D6: =D4+D5 -> 0
A7: Closing Costs | D7: =D37
A8: Acquisition Fee | B8: =Scenarios!F15 -> 0 | D8: =Scenarios!F16 -> 0
A9: Repair Escrow / CapEx | D9: =Scenarios!F12 -> 0
A10: Operating Reserves | D10: =Scenarios!F13 -> 0
A11: TOTAL CASH AT CLOSE | D11: =SUM(D6:D10) -> 0
A13: CLOSING COSTS DETAIL
A14: Item | B14: Rate/Factor | C14: Notes | D14: Amount
A15: LENDER FEES & THIRD-PARTY COSTS
A16: Environmental (EDR)
A17: Appraisal
A18: Structural Inspection
A19: Lender Legal Fees
A20: Bank Doc Prep Fee
A21: Origination Fee | B21: =Scenarios!F146 -> 0 | C21: Total origination fees — all tranches | D21: =Scenarios!F146*Scenarios!F141+Scenarios!F153*Scenarios!F148+Scenarios!F160*Scenarios!F155 -> 0
A22: TITLE & CLOSING COSTS
A23: Title Policy | B23: 0.003 | C23: 0.30% of purchase price | D23: =B23*Scenarios!F7 -> 0
A24: Survey
A25: Recording
A26: Transfer Taxes | B26: 0.0035 | C26: 0.35% of purchase price | D26: =B26*Scenarios!F7 -> 0
A27: Title Processing Fee
A28: Title Search
A29: Attorney Fees
A30: OTHER COSTS
A31: Legal (LLC, PPM, OA)
A32: Property Inspection
A33: Travel
A34: Miscellaneous
A35: RE Taxes | D35: =Scenarios!F114/4 -> 0
A36: Insurance | D36: =Scenarios!F110/4 -> 0
A37: TOTAL CLOSING & OTHER COSTS | D37: =IF(D4=0, "",SUM(D16:D36))
A38: Closing Costs excl. 1st-Loan Origination (LTC solver input) | D38: =IF(D4=0,0,SUM(D16:D20)+SUM(D22:D36)+Scenarios!F153*Scenarios!F148+Scenarios!F160*Scenarios!F155) -> 0

Sheet Staffing Matrix
A1: STAFFING MATRIX — PER-SHIFT | FTE BUILD | HPPD | TOTAL PAYROLL → P&L R28
A2: Blue=Input | Black=Formula | Green=Cross-sheet. Cell M69 (Total Payroll) feeds P&L!C28 automatically. Census pulled from Scenarios sheet.
A4: SECTION 1 — CENSUS & STAFFING RATE ASSUMPTIONS
A5: Total Units (physical rooms, from Scenarios) | C5: =IFERROR(Scenarios!F8,90) -> 0 | D5: Physical rooms ≠ licensed beds — see Prop Info for bed count
A6: AL Occupied Beds (Y1 census) | D6: Enter occupied bed count, not room count
A7: MC Occupied Beds (Y1 census) | D7: Enter occupied bed count, not room count
A8: IL Occupied Beds (Y1 census)
A9: Total Care Residents (AL + MC occupied beds) | C9: =C6+C7 -> 0
A10: Licensed Beds (from Prop Info — regulatory ceiling) | C10: =IFERROR('Prop Info'!$B$15,0) -> 0 | D10: Licensed beds = regulatory max. Occupied beds ≤ licensed beds.
A11: Rate & Cost Assumptions
A12: Benefits Load (FICA + health + 401k) | C12: 0.2 | D12: Typical 18–22%
A13: Overtime Load | C13: 0.05 | D13: 5% of base wages; AL/MC often higher
A14: Eve Differential ($/hr premium) | C14: 1.5 | D14: 3p–11p shift
A15: Night Differential ($/hr premium) | C15: 2.5 | D15: 11p–7a shift
A16: Weekend Premium ($/hr) | C16: 0.75 | D16: Added to shift differential
A18: Target Staffing Ratios (residents : 1 staff)
A19: Ratio-driven CNA rows auto-calculate headcount. Verify against your state DOH minimum requirements.
A20: AL — Day Shift (1:X residents per aide) | C20: 6 | D20: 1:6 day; increase MC urgency
A21: AL — Evening Shift (1:X) | C21: 7 | D21: 1:7 eve; lighter acuity overnight
A22: AL — Night Shift (1:X) | C22: 10 | D22: 1:10 night minimum
A23: MC — Day Shift (1:X) | C23: 5 | D23: 1:5 MC day; CMS recommends closer to 1:4
A24: MC — Evening Shift (1:X) | C24: 6 | D24: 1:6 MC eve
A25: MC — Night Shift (1:X) | C25: 8 | D25: 1:8 MC night
A27: SECTION 2 — PER-SHIFT HEADCOUNT MATRIX (staff per shift × 6 shifts)
C28: WEEKDAY | F28: WEEKEND | I28: Hrs/Wk | J28: FTEs | K28: Base $/hr | L28: Shift-Adj $/hr | M28: Annual Cost ($) | N28: % Total Payroll
A29: Position | B29: Dept | C29: Day 7a–3p | D29: Eve 3p–11p | E29: Night 11p–7a | F29: Day 7a–3p | G29: Eve 3p–11p | H29: Night 11p–7a
A30: Care Staff
A31: Director of Nursing | B31: Care | D31: 0 | E31: 0 | G31: 0 | H31: 0 | I31: =((C31+D31+E31)*5+(F31+G31+H31)*2)*8 -> 0 | J31: =IFERROR(I31*52/2080,0) -> 0 | L31: =IFERROR((C31*K31+D31*(K31+$C$14)+E31*(K31+$C$15)+F31*(K31+$C$16)+G31*(K31+$C$14+$C$16)+H31*(K31+$C$15+$C$16))/MAX(C31+D31+E31+F31+G31+H31,1),K31) -> 0 | M31: =IFERROR(J31*2080*L31*(1+$C$12)*(1+$C$13),0) -> 0 | N31: =IFERROR(M31/M67,0) -> 0
A32: RN / Asst DON | B32: Care | E32: 0 | G32: 0 | H32: 0 | I32: =((C32+D32+E32)*5+(F32+G32+H32)*2)*8 -> 0 | J32: =IFERROR(I32*52/2080,0) -> 0 | L32: =IFERROR((C32*K32+D32*(K32+$C$14)+E32*(K32+$C$15)+F32*(K32+$C$16)+G32*(K32+$C$14+$C$16)+H32*(K32+$C$15+$C$16))/MAX(C32+D32+E32+F32+G32+H32,1),K32) -> 0 | M32: =IFERROR(J32*2080*L32*(1+$C$12)*(1+$C$13),0) -> 0 | N32: =IFERROR(M32/M67,0) -> 0
A33: Med Tech / CMA | B33: Care | I33: =((C33+D33+E33)*5+(F33+G33+H33)*2)*8 -> 0 | J33: =IFERROR(I33*52/2080,0) -> 0 | L33: =IFERROR((C33*K33+D33*(K33+$C$14)+E33*(K33+$C$15)+F33*(K33+$C$16)+G33*(K33+$C$14+$C$16)+H33*(K33+$C$15+$C$16))/MAX(C33+D33+E33+F33+G33+H33,1),K33) -> 0 | M33: =IFERROR(J33*2080*L33*(1+$C$12)*(1+$C$13),0) -> 0 | N33: =IFERROR(M33/M67,0) -> 0
A34: CNA — Day (AL) | B34: Care | C34: =IFERROR(CEILING(C6/C20,1),0) -> 0 | D34: 0 | E34: 0 | F34: =IFERROR(CEILING(C6/C20,1),0) -> 0 | G34: 0 | H34: 0 | I34: =((C34+D34+E34)*5+(F34+G34+H34)*2)*8 -> 0 | J34: =IFERROR(I34*52/2080,0) -> 0 | L34: =IFERROR((C34*K34+D34*(K34+$C$14)+E34*(K34+$C$15)+F34*(K34+$C$16)+G34*(K34+$C$14+$C$16)+H34*(K34+$C$15+$C$16))/MAX(C34+D34+E34+F34+G34+H34,1),K34) -> 0 | M34: =IFERROR(J34*2080*L34*(1+$C$12)*(1+$C$13),0) -> 0 | N34: =IFERROR(M34/M67,0) -> 0
A35: CNA — Eve (AL) | B35: Care | C35: 0 | D35: =IFERROR(CEILING(C6/C21,1),0) -> 0 | E35: 0 | F35: 0 | G35: =IFERROR(CEILING(C6/C21,1),0) -> 0 | H35: 0 | I35: =((C35+D35+E35)*5+(F35+G35+H35)*2)*8 -> 0 | J35: =IFERROR(I35*52/2080,0) -> 0 | L35: =IFERROR((C35*K35+D35*(K35+$C$14)+E35*(K35+$C$15)+F35*(K35+$C$16)+G35*(K35+$C$14+$C$16)+H35*(K35+$C$15+$C$16))/MAX(C35+D35+E35+F35+G35+H35,1),K35) -> 0 | M35: =IFERROR(J35*2080*L35*(1+$C$12)*(1+$C$13),0) -> 0 | N35: =IFERROR(M35/M67,0) -> 0
A36: CNA — Night (AL) | B36: Care | C36: 0 | D36: 0 | E36: =IFERROR(CEILING(C6/C22,1),0) -> 0 | F36: 0 | G36: 0 | H36: =IFERROR(CEILING(C6/C22,1),0) -> 0 | I36: =((C36+D36+E36)*5+(F36+G36+H36)*2)*8 -> 0 | J36: =IFERROR(I36*52/2080,0) -> 0 | L36: =IFERROR((C36*K36+D36*(K36+$C$14)+E36*(K36+$C$15)+F36*(K36+$C$16)+G36*(K36+$C$14+$C$16)+H36*(K36+$C$15+$C$16))/MAX(C36+D36+E36+F36+G36+H36,1),K36) -> 0 | M36: =IFERROR(J36*2080*L36*(1+$C$12)*(1+$C$13),0) -> 0 | N36: =IFERROR(M36/M67,0) -> 0
A37: CNA — Day (MC) | B37: Care | C37: =IFERROR(CEILING(C7/C23,1),0) -> 0 | D37: 0 | E37: 0 | F37: =IFERROR(CEILING(C7/C23,1),0) -> 0 | G37: 0 | H37: 0 | I37: =((C37+D37+E37)*5+(F37+G37+H37)*2)*8 -> 0 | J37: =IFERROR(I37*52/2080,0) -> 0 | L37: =IFERROR((C37*K37+D37*(K37+$C$14)+E37*(K37+$C$15)+F37*(K37+$C$16)+G37*(K37+$C$14+$C$16)+H37*(K37+$C$15+$C$16))/MAX(C37+D37+E37+F37+G37+H37,1),K37) -> 0 | M37: =IFERROR(J37*2080*L37*(1+$C$12)*(1+$C$13),0) -> 0 | N37: =IFERROR(M37/M67,0) -> 0
A38: CNA — Eve (MC) | B38: Care | C38: 0 | D38: =IFERROR(CEILING(C7/C24,1),0) -> 0 | E38: 0 | F38: 0 | G38: =IFERROR(CEILING(C7/C24,1),0) -> 0 | H38: 0 | I38: =((C38+D38+E38)*5+(F38+G38+H38)*2)*8 -> 0 | J38: =IFERROR(I38*52/2080,0) -> 0 | L38: =IFERROR((C38*K38+D38*(K38+$C$14)+E38*(K38+$C$15)+F38*(K38+$C$16)+G38*(K38+$C$14+$C$16)+H38*(K38+$C$15+$C$16))/MAX(C38+D38+E38+F38+G38+H38,1),K38) -> 0 | M38: =IFERROR(J38*2080*L38*(1+$C$12)*(1+$C$13),0) -> 0 | N38: =IFERROR(M38/M67,0) -> 0
A39: CNA — Night (MC) | B39: Care | C39: 0 | D39: 0 | E39: =IFERROR(CEILING(C7/C25,1),0) -> 0 | F39: 0 | G39: 0 | H39: =IFERROR(CEILING(C7/C25,1),0) -> 0 | I39: =((C39+D39+E39)*5+(F39+G39+H39)*2)*8 -> 0 | J39: =IFERROR(I39*52/2080,0) -> 0 | L39: =IFERROR((C39*K39+D39*(K39+$C$14)+E39*(K39+$C$15)+F39*(K39+$C$16)+G39*(K39+$C$14+$C$16)+H39*(K39+$C$15+$C$16))/MAX(C39+D39+E39+F39+G39+H39,1),K39) -> 0 | M39: =IFERROR(J39*2080*L39*(1+$C$12)*(1+$C$13),0) -> 0 | N39: =IFERROR(M39/M67,0) -> 0
A40: Subtotal — Care Staff | C40: =SUM(C31:C39) -> 0 | D40: =SUM(D31:D39) -> 0 | E40: =SUM(E31:E39) -> 0 | F40: =SUM(F31:F39) -> 0 | G40: =SUM(G31:G39) -> 0 | H40: =SUM(H31:H39) -> 0 | I40: =SUM(I31:I39) -> 0 | J40: =SUM(J31:J39) -> 0 | M40: =SUM(M31:M39) -> 0
A42: Dining
A43: Dining Manager / Chef | B43: Dining | E43: 0 | H43: 0 | I43: =((C43+D43+E43)*5+(F43+G43+H43)*2)*8 -> 0 | J43: =IFERROR(I43*52/2080,0) -> 0 | L43: =IFERROR((C43*K43+D43*(K43+$C$14)+E43*(K43+$C$15)+F43*(K43+$C$16)+G43*(K43+$C$14+$C$16)+H43*(K43+$C$15+$C$16))/MAX(C43+D43+E43+F43+G43+H43,1),K43) -> 0 | M43: =IFERROR(J43*2080*L43*(1+$C$12)*(1+$C$13),0) -> 0 | N43: =IFERROR(M43/M67,0) -> 0
A44: Cook | B44: Dining | E44: 0 | H44: 0 | I44: =((C44+D44+E44)*5+(F44+G44+H44)*2)*8 -> 0 | J44: =IFERROR(I44*52/2080,0) -> 0 | L44: =IFERROR((C44*K44+D44*(K44+$C$14)+E44*(K44+$C$15)+F44*(K44+$C$16)+G44*(K44+$C$14+$C$16)+H44*(K44+$C$15+$C$16))/MAX(C44+D44+E44+F44+G44+H44,1),K44) -> 0 | M44: =IFERROR(J44*2080*L44*(1+$C$12)*(1+$C$13),0) -> 0 | N44: =IFERROR(M44/M67,0) -> 0
...

Sheet Rent Roll Analysis
A1: RENT ROLL ANALYSIS — Diagnostic Layer (Senior Living)
A2: ANALYSIS on top. Raw rent roll below — paste from RentrollApp-Cl output. AR aging columns Q–T blank (paste from Analyzer AR Input or operator AR aging report). Care level: IL = Independent Living · AL = Assisted Living · MC = Memory Care.
A4: B. HEALTH CHECK — RR vs. Prop Info reconciliation
A5: Date: | C5: Property: | D5: =TODAY() -> 46189 | E5: Lic Beds (Prop): | F5: ='Prop Info'!B15 -> 0 | G5: Lic Beds (RR): | H5: =COUNTA(B224:B623) -> 0 | I5: Match: | J5: =IF(F5=H5,"✓ match","⚠ mismatch: "&(H5-F5)) -> ✓ match | K5: Total AR: | L5: =SUM(M224:M623) -> 0 | N5: On Notice: | O5: =COUNTIF(E224:E623,"Notice") -> 0 | Q5: Occupied: | R5: =COUNTIF(E224:E623,"Occupied")+COUNTIF(E224:E623,"Notice") -> 0
D6: As of date for diagnostic
A7: C. CARE LEVEL CENSUS — Licensed beds, occupancy, and rate by level
A8: Care Level | B8: Licensed Beds | C8: Occupied Beds | D8: Occupancy % | E8: Avg Monthly Rate | F8: GPR (ann.) | G8: Avg LOC Rev/Bed | H8: Total Revenue
A9: IL — Independent Living | B9: =COUNTIF($C$224:$C$623,"IL") -> 0 | C9: =COUNTIFS($C$224:$C$623,"IL",$E$224:$E$623,"Occupied")+COUNTIFS($C$224:$C$623,"IL",$E$224:$E$623,"Notice") -> 0 | D9: =IFERROR(C9/B9,0) -> 0 | E9: =IFERROR(AVERAGEIFS($L$224:$L$623,$C$224:$C$623,"IL",$L$224:$L$623,">0"),0) -> 0 | F9: =IFERROR(B9*AVERAGEIFS($I$224:$I$623,$C$224:$C$623,"IL",$I$224:$I$623,">0")*12,0) -> 0 | G9: =IFERROR(SUMIFS($K$224:$K$623,$C$224:$C$623,"IL")/MAX(C9,1),0) -> 0 | H9: =SUMIFS($L$224:$L$623,$C$224:$C$623,"IL")*12 -> 0
A10: AL — Assisted Living | B10: =COUNTIF($C$224:$C$623,"AL") -> 0 | C10: =COUNTIFS($C$224:$C$623,"AL",$E$224:$E$623,"Occupied")+COUNTIFS($C$224:$C$623,"AL",$E$224:$E$623,"Notice") -> 0 | D10: =IFERROR(C10/B10,0) -> 0 | E10: =IFERROR(AVERAGEIFS($L$224:$L$623,$C$224:$C$623,"AL",$L$224:$L$623,">0"),0) -> 0 | F10: =IFERROR(B10*AVERAGEIFS($I$224:$I$623,$C$224:$C$623,"AL",$I$224:$I$623,">0")*12,0) -> 0 | G10: =IFERROR(SUMIFS($K$224:$K$623,$C$224:$C$623,"AL")/MAX(C10,1),0) -> 0 | H10: =SUMIFS($L$224:$L$623,$C$224:$C$623,"AL")*12 -> 0
A11: MC — Memory Care | B11: =COUNTIF($C$224:$C$623,"MC") -> 0 | C11: =COUNTIFS($C$224:$C$623,"MC",$E$224:$E$623,"Occupied")+COUNTIFS($C$224:$C$623,"MC",$E$224:$E$623,"Notice") -> 0 | D11: =IFERROR(C11/B11,0) -> 0 | E11: =IFERROR(AVERAGEIFS($L$224:$L$623,$C$224:$C$623,"MC",$L$224:$L$623,">0"),0) -> 0 | F11: =IFERROR(B11*AVERAGEIFS($I$224:$I$623,$C$224:$C$623,"MC",$I$224:$I$623,">0")*12,0) -> 0 | G11: =IFERROR(SUMIFS($K$224:$K$623,$C$224:$C$623,"MC")/MAX(C11,1),0) -> 0 | H11: =SUMIFS($L$224:$L$623,$C$224:$C$623,"MC")*12 -> 0
A12: ='Prop Info'!$D$13&" — Other Care" -> — Other Care | B12: =COUNTIF($C$224:$C$623,"OTH") -> 0 | C12: =COUNTIFS($C$224:$C$623,"OTH",$E$224:$E$623,"Occupied")+COUNTIFS($C$224:$C$623,"OTH",$E$224:$E$623,"Notice") -> 0 | D12: =IFERROR(C12/B12,0) -> 0 | E12: =IFERROR(AVERAGEIFS($L$224:$L$623,$C$224:$C$623,"OTH",$L$224:$L$623,">0"),0) -> 0 | F12: =IFERROR(B12*AVERAGEIFS($I$224:$I$623,$C$224:$C$623,"OTH",$I$224:$I$623,">0")*12,0) -> 0 | G12: =IFERROR(SUMIFS($K$224:$K$623,$C$224:$C$623,"OTH")/MAX(C12,1),0) -> 0 | H12: =SUMIFS($L$224:$L$623,$C$224:$C$623,"OTH")*12 -> 0
A13: TOTAL | B13: =SUM(B9:B12) -> 0 | C13: =SUM(C9:C12) -> 0 | D13: =IFERROR(C13/B13,0) -> 0 | E13: =IFERROR(SUMIFS($L$224:$L$623,$L$224:$L$623,">0")/COUNTIFS($L$224:$L$623,">0"),0) -> 0 | F13: =SUM(F9:F12) -> 0 | G13: =IFERROR(SUM(K224:K623)/MAX(C13,1),0) -> 0 | H13: =SUM(H9:H12) -> 0
A15: D. RESIDENT STATUS TAXONOMY — Where everyone stands
A16: Status Bucket | B16: # Beds | C16: % of Total | D16: Sched Charges ($/mo) | E16: Avg Rate/Bed | F16: AR Balance
A17: Occupied — Current (paying, no balance) | B17: =COUNTIFS($E$224:$E$623,"Occupied",$M$224:$M$623,"<=0")+COUNTIFS($E$224:$E$623,"Occupied",$M$224:$M$623,"") -> 0 | C17: =IFERROR(B17/$B$25,0) -> 0 | D17: =IFERROR(SUMIFS($L$224:$L$623,$E$224:$E$623,"Occupied",$M$224:$M$623,"<=0")+SUMIFS($L$224:$L$623,$E$224:$E$623,"Occupied",$M$224:$M$623,""),0) -> 0 | E17: =IFERROR(D17/MAX(B17,1),0) -> 0 | F17: 0
A18: Occupied — Delinquent (30+ days past due) | B18: =COUNTIFS($E$224:$E$623,"Occupied",$M$224:$M$623,">0")+COUNTIFS($E$224:$E$623,"Notice",$M$224:$M$623,">0") -> 0 | C18: =IFERROR(B18/$B$25,0) -> 0 | D18: =SUMIFS($L$224:$L$623,$E$224:$E$623,"Occupied",$M$224:$M$623,">0")+SUMIFS($L$224:$L$623,$E$224:$E$623,"Notice",$M$224:$M$623,">0") -> 0 | E18: =IFERROR(D18/MAX(B18,1),0) -> 0 | F18: =SUMIFS($M$224:$M$623,$E$224:$E$623,"Occupied",$M$224:$M$623,">0")+SUMIFS($M$224:$M$623,$E$224:$E$623,"Notice",$M$224:$M$623,">0") -> 0
A19: Occupied — On Notice (30-day notice given) | B19: =COUNTIF($E$224:$E$623,"Notice") -> 0 | C19: =IFERROR(B19/$B$25,0) -> 0 | D19: =SUMIFS($L$224:$L$623,$E$224:$E$623,"Notice") -> 0 | E19: =IFERROR(D19/MAX(B19,1),0) -> 0 | F19: =SUMIFS($M$224:$M$623,$E$224:$E$623,"Notice") -> 0
A20: Occupied — Respite / Short-term | B20: =COUNTIF($E$224:$E$623,"Respite") -> 0 | C20: =IFERROR(B20/$B$25,0) -> 0 | D20: =SUMIFS($L$224:$L$623,$E$224:$E$623,"Respite") -> 0 | E20: =IFERROR(D20/MAX(B20,1),0) -> 0 | F20: =SUMIFS($M$224:$M$623,$E$224:$E$623,"Respite") -> 0
A21: Occupied — Hospice | B21: =COUNTIF($E$224:$E$623,"Hospice") -> 0 | C21: =IFERROR(B21/$B$25,0) -> 0 | D21: =SUMIFS($L$224:$L$623,$E$224:$E$623,"Hospice") -> 0 | E21: =IFERROR(D21/MAX(B21,1),0) -> 0 | F21: =SUMIFS($M$224:$M$623,$E$224:$E$623,"Hospice") -> 0
A22: Vacant — Turned (ready) | B22: =COUNTIFS($E$224:$E$623,"Vacant",$H$224:$H$623,"<>") -> 0 | C22: =IFERROR(B22/$B$25,0) -> 0 | D22: 0 | E22: 0 | F22: 0
A23: Vacant — Not Turned | B23: =COUNTIFS($E$224:$E$623,"Vacant",$H$224:$H$623,"") -> 0 | C23: =IFERROR(B23/$B$25,0) -> 0 | D23: 0 | E23: 0 | F23: 0
A24: Reserved / Pre-Admitted (signed, not in) | B24: =COUNTIF($E$224:$E$623,"Reserved")+COUNTIFS($E$224:$E$623,"Vacant",$G$224:$G$623,">"&TODAY()) -> 0 | C24: =IFERROR(B24/$B$25,0) -> 0 | D24: =SUMIFS($L$224:$L$623,$E$224:$E$623,"Reserved") -> 0 | E24: =IFERROR(D24/MAX(B24,1),0) -> 0 | F24: 0
A25: TOTAL | B25: =COUNTA($B$224:$B$623) -> 0 | C25: =SUM(C17:C24) -> 0 | D25: =SUM(D17:D24) -> 0 | E25: =IFERROR(D25/MAX(B25,1),0) -> 0 | F25: =SUM(F17:F24) -> 0
A26: Tie-out: Occ + Vacant + Reserved = Licensed Beds | Occ Mkt + Vac Loss should tie to Section E GPR
A28: E. GPR RECONCILIATION — Three views of potential revenue
A29: Metric | B29: Annual Amount | C29: Per Bed/Mo | D29: Notes
A30: Market GPR (all licensed beds × market rate × 12) | B30: =SUM(I224:I623)*12 -> 0 | C30: =IFERROR(B30/12/MAX(B13,1),0) -> 0 | D30: Max revenue at 100% occupancy
A31: Scheduled GPR (occupied × sched charges × 12) | B31: {=SUMPRODUCT((($E$224:$E$623="Occupied")+($E$224:$E$623="Notice"))*$L$224:$L$623)*12} -> 0 | C31: =IFERROR(B31/12/MAX(C13,1),0) -> 0 | D31: Contracted charges on occupied beds
A32: Loss to Lease (achievable rate − in-place scheduled, occupied) | B32: {=(SUMPRODUCT((($C$224:$C$623="IL")*(($E$224:$E$623="Occupied")+($E$224:$E$623="Notice")))*(_xlfn.MAXIFS($L$224:$L$623,$C$224:$C$623,"IL",$E$224:$E$623,"Occupied")-$L$224:$L$623))+SUMPRODUCT((($C$224:$C$623="AL")*(($E$224:$E$623="Occupied")+($E$224:$E$623="Notice")))*(_xlfn.MAXIFS($L$224:$L$623,$C$224:$C$623,"AL",$E$224:$E$623,"Occupied")-$L$224:$L$623))+SUMPRODUCT((($C$224:$C$623="MC")*(($E$224:$E$623="Occupied")+($E$224:$E$623="Notice")))*(_xlfn.MAXIFS($L$224:$L$623,$C$224:$C$623,"MC",$E$224:$E$623,"Occupied")-$L$224:$L$623)))*12} -> 0 | C32: =IFERROR(B32/12/MAX(C13,1),0) -> 0 | D32: Achievable = max scheduled rate within same care level (peer ceiling per CL)
A33: Loss to Lease % | B33: =IFERROR(B32/B31,0) -> 0 | D33: LTL as % of scheduled GPR
A34: Vacancy Loss (vacant beds × market rate × 12) | B34: =SUMIFS($I$224:$I$623,$E$224:$E$623,"Vacant")*12 -> 0 | C34: =IFERROR(B34/12/MAX(COUNTIF($E$224:$E$623,"Vacant"),1),0) -> 0 | D34: Lost revenue from empty beds
A35: Bad Debt Risk (delinquent + on-notice × sched × 12) | B35: =F18*12+F19*12 -> 0 | C35: =IFERROR(B35/12/MAX(B18+B19,1),0) -> 0 | D35: Annualized at-risk revenue
A36: LOC / Care Services Revenue (Analyzer UW Output) | B36: =SUM(K224:K623)*12 -> 0 | C36: =IFERROR(B36/12/MAX(C13,1),0) -> 0 | D36: Add-on care charges — source from Analyzer
A37: Economic GPR (Market − LTL − Vac − Bad Debt + LOC) | B37: =B30-B32-B34-B35+B36 -> 0 | C37: =IFERROR(B37/12/MAX(B13,1),0) -> 0 | D37: Realistic collected revenue estimate
A38: Economic Occupancy % (Econ GPR / Market GPR) | B38: =IFERROR(B37/B30,0) -> 0 | D38: Compare to physical occupancy above
A39: Current RR GPR — Occupied Scheduled (point-in-time) | B39: {=SUMPRODUCT((($E$224:$E$623="Occupied")+($E$224:$E$623="Notice"))*$L$224:$L$623)*12} -> 0 | C39: =IFERROR(B39/12/MAX(C13,1),0) -> 0 | D39: Scheduled rent × occupied beds × 12
A40: Market vs Actual Collected (operator posted rate − actual charges, occupied) | B40: {=SUMPRODUCT((($E$224:$E$623="Occupied")+($E$224:$E$623="Notice"))*($I$224:$I$623-$J$224:$J$623))*12} -> 0 | C40: =IFERROR(B40/12/MAX(C13,1),0) -> 0 | D40: Negative = collecting MORE than posted market (over-billing or care fees in I). Positive = collecting LESS than posted market (concessions / discounts in actuals).
A41: F. LENGTH OF STAY COHORT — How long residents have been here
A42: Tenure | B42: # Residents | C42: % Occupied | D42: Avg Sched Rate | E42: Avg Market Rate | F42: LTL/mo/bed | G42: Read
A43: 0–6 months | B43: {=SUMPRODUCT((($E$224:$E$623="Occupied")+($E$224:$E$623="Notice"))*($G$224:$G$623>=TODAY()-180)*($G$224:$G$623<>""))} -> 0 | C43: =IFERROR(B43/MAX($C$13,1),0) -> 0 | D43: {=IFERROR(SUMPRODUCT((($E$224:$E$623="Occupied")+($E$224:$E$623="Notice"))*($G$224:$G$623>=TODAY()-180)*($G$224:$G$623<>"")*$L$224:$L$623)/MAX(B43,1),0)} -> 0 | E43: {=IFERROR(SUMPRODUCT((($E$224:$E$623="Occupied")+($E$224:$E$623="Notice"))*($G$224:$G$623>=TODAY()-180)*($G$224:$G$623<>"")*$I$224:$I$623)/MAX(B43,1),0)} -> 0 | F43: =IFERROR(E43-D43,0) -> 0 | G43: Recent admissions — high care needs assessment period
...

Sheet Rental Comps
A1: RENTAL COMPS — BY CARE LEVEL | P1: UNIT MIX & TARGET RENT ANALYSIS — Reference only. Blue = input · Green = formula · Target defaults to comp avg for care level.
A2: Enter up to 12 comps per care level. Summary auto-calculates averages and rate position vs. subject property. | N2: Rent Basis: | O2: Average | P2: Unit Type | Q2: Sq Ft | R2: # Units | S2: Current Rent | V2: Target Rent | AA2: Notes
A3: SUBJECT PROPERTY → | E3: ='Prop Info'!B2 -> 0 | F3: =Scenarios!F38 -> 0 | G3: =Scenarios!F38 -> 0 | H3: =Scenarios!F38 -> 0 | P3: Type | Q3: Sq Ft | R3: # Units | S3: Avg / mo | T3: Total / mo | U3: $ / Sq Ft | V3: Target / mo | W3: Delta % | X3: Delta $ | Y3: Total / mo | Z3: $ / Sq Ft | AA3: Notes
P4: IL — INDEPENDENT LIVING
A5: INDEPENDENT LIVING (IL) COMPS | P5: IL Studio | Q5: =IFERROR(AVERAGEIFS('Rent Roll Analysis'!T:T,'Rent Roll Analysis'!Y:Y,"IL|Studio",'Rent Roll Analysis'!T:T,">0"),0) -> 0 | R5: =COUNTIF('Rent Roll Analysis'!Y:Y,"IL|Studio") -> 0 | S5: =IFERROR(IF($O$2="Max",_xlfn.MAXIFS('Rent Roll Analysis'!I:I,'Rent Roll Analysis'!X:X,"IL|Studio"),AVERAGEIFS('Rent Roll Analysis'!I:I,'Rent Roll Analysis'!X:X,"IL|Studio",'Rent Roll Analysis'!I:I,">0")),0) -> 0 | T5: =IFERROR(S5*R5,0) -> 0 | U5: =IFERROR(S5/Q5,0) -> 0 | V5: =IFERROR(H19,0) -> 0 | W5: =IFERROR(V5/S5-1,"") | X5: =IFERROR(V5-S5,"") -> 0 | Y5: =IFERROR(V5*R5,0) -> 0 | Z5: =IFERROR(V5/Q5,0) -> 0
A6: Distance (mi) | B6: Vintage | C6: Units | D6: Type | E6: Property Name | F6: Base Rent/mo | G6: Care Fee/mo | H6: All-In Rate | I6: Occupancy % | J6: Sq Ft | K6: $/Sq Ft | L6: Notes | P6: IL 1-Bed | Q6: =IFERROR(AVERAGEIFS('Rent Roll Analysis'!T:T,'Rent Roll Analysis'!Y:Y,"IL|1 Bedroom",'Rent Roll Analysis'!T:T,">0"),0) -> 0 | R6: =COUNTIF('Rent Roll Analysis'!Y:Y,"IL|1 Bedroom") -> 0 | S6: =IFERROR(IF($O$2="Max",_xlfn.MAXIFS('Rent Roll Analysis'!I:I,'Rent Roll Analysis'!X:X,"IL|1 Bedroom"),AVERAGEIFS('Rent Roll Analysis'!I:I,'Rent Roll Analysis'!X:X,"IL|1 Bedroom",'Rent Roll Analysis'!I:I,">0")),0) -> 0 | T6: =IFERROR(S6*R6,0) -> 0 | U6: =IFERROR(S6/Q6,0) -> 0 | V6: =IFERROR(H19,0) -> 0 | W6: =IFERROR(V6/S6-1,"") | X6: =IFERROR(V6-S6,"") -> 0 | Y6: =IFERROR(V6*R6,0) -> 0 | Z6: =IFERROR(V6/Q6,0) -> 0
H7: =IFERROR(F7+G7,0) -> 0 | K7: =IFERROR(F7/J7,0) -> 0 | P7: IL 2-Bed | Q7: =IFERROR(AVERAGEIFS('Rent Roll Analysis'!T:T,'Rent Roll Analysis'!Y:Y,"IL|2 Bedroom",'Rent Roll Analysis'!T:T,">0"),0) -> 0 | R7: =COUNTIF('Rent Roll Analysis'!Y:Y,"IL|2 Bedroom") -> 0 | S7: =IFERROR(IF($O$2="Max",_xlfn.MAXIFS('Rent Roll Analysis'!I:I,'Rent Roll Analysis'!X:X,"IL|2 Bedroom"),AVERAGEIFS('Rent Roll Analysis'!I:I,'Rent Roll Analysis'!X:X,"IL|2 Bedroom",'Rent Roll Analysis'!I:I,">0")),0) -> 0 | T7: =IFERROR(S7*R7,0) -> 0 | U7: =IFERROR(S7/Q7,0) -> 0 | V7: =IFERROR(H19,0) -> 0 | W7: =IFERROR(V7/S7-1,"") | X7: =IFERROR(V7-S7,"") -> 0 | Y7: =IFERROR(V7*R7,0) -> 0 | Z7: =IFERROR(V7/Q7,0) -> 0
H8: =IFERROR(F8+G8,0) -> 0 | K8: =IFERROR(F8/J8,0) -> 0 | P8: AL — ASSISTED LIVING
H9: =IFERROR(F9+G9,0) -> 0 | K9: =IFERROR(F9/J9,0) -> 0 | P9: AL Studio (Pvt) | Q9: =IFERROR(AVERAGEIFS('Rent Roll Analysis'!T:T,'Rent Roll Analysis'!Y:Y,"AL|Studio",'Rent Roll Analysis'!T:T,">0"),0) -> 0 | R9: =COUNTIF('Rent Roll Analysis'!Y:Y,"AL|Studio") -> 0 | S9: =IFERROR(IF($O$2="Max",_xlfn.MAXIFS('Rent Roll Analysis'!I:I,'Rent Roll Analysis'!X:X,"AL|Studio"),AVERAGEIFS('Rent Roll Analysis'!I:I,'Rent Roll Analysis'!X:X,"AL|Studio",'Rent Roll Analysis'!I:I,">0")),0) -> 0 | T9: =IFERROR(S9*R9,0) -> 0 | U9: =IFERROR(S9/Q9,0) -> 0 | V9: =IFERROR(H36,0) -> 0 | W9: =IFERROR(V9/S9-1,"") | X9: =IFERROR(V9-S9,"") -> 0 | Y9: =IFERROR(V9*R9,0) -> 0 | Z9: =IFERROR(V9/Q9,0) -> 0
H10: =IFERROR(F10+G10,0) -> 0 | K10: =IFERROR(F10/J10,0) -> 0 | P10: AL Semi-Private | Q10: =IFERROR(AVERAGEIFS('Rent Roll Analysis'!T:T,'Rent Roll Analysis'!Y:Y,"AL|Semi-Private",'Rent Roll Analysis'!T:T,">0"),0) -> 0 | R10: =COUNTIF('Rent Roll Analysis'!Y:Y,"AL|Semi-Private") -> 0 | S10: =IFERROR(IF($O$2="Max",_xlfn.MAXIFS('Rent Roll Analysis'!I:I,'Rent Roll Analysis'!X:X,"AL|Semi-Private"),AVERAGEIFS('Rent Roll Analysis'!I:I,'Rent Roll Analysis'!X:X,"AL|Semi-Private",'Rent Roll Analysis'!I:I,">0")),0) -> 0 | T10: =IFERROR(S10*R10,0) -> 0 | U10: =IFERROR(S10/Q10,0) -> 0 | V10: =IFERROR(H36,0) -> 0 | W10: =IFERROR(V10/S10-1,"") | X10: =IFERROR(V10-S10,"") -> 0 | Y10: =IFERROR(V10*R10,0) -> 0 | Z10: =IFERROR(V10/Q10,0) -> 0
H11: =IFERROR(F11+G11,0) -> 0 | K11: =IFERROR(F11/J11,0) -> 0 | P11: AL 1-Bed | Q11: =IFERROR(AVERAGEIFS('Rent Roll Analysis'!T:T,'Rent Roll Analysis'!Y:Y,"AL|1 Bedroom",'Rent Roll Analysis'!T:T,">0"),0) -> 0 | R11: =COUNTIF('Rent Roll Analysis'!Y:Y,"AL|1 Bedroom") -> 0 | S11: =IFERROR(IF($O$2="Max",_xlfn.MAXIFS('Rent Roll Analysis'!I:I,'Rent Roll Analysis'!X:X,"AL|1 Bedroom"),AVERAGEIFS('Rent Roll Analysis'!I:I,'Rent Roll Analysis'!X:X,"AL|1 Bedroom",'Rent Roll Analysis'!I:I,">0")),0) -> 0 | T11: =IFERROR(S11*R11,0) -> 0 | U11: =IFERROR(S11/Q11,0) -> 0 | V11: =IFERROR(H36,0) -> 0 | W11: =IFERROR(V11/S11-1,"") | X11: =IFERROR(V11-S11,"") -> 0 | Y11: =IFERROR(V11*R11,0) -> 0 | Z11: =IFERROR(V11/Q11,0) -> 0
H12: =IFERROR(F12+G12,0) -> 0 | K12: =IFERROR(F12/J12,0) -> 0 | P12: MC — MEMORY CARE
H13: =IFERROR(F13+G13,0) -> 0 | K13: =IFERROR(F13/J13,0) -> 0 | P13: MC Studio (Pvt) | Q13: =IFERROR(AVERAGEIFS('Rent Roll Analysis'!T:T,'Rent Roll Analysis'!Y:Y,"MC|Studio",'Rent Roll Analysis'!T:T,">0"),0) -> 0 | R13: =COUNTIF('Rent Roll Analysis'!Y:Y,"MC|Studio") -> 0 | S13: =IFERROR(IF($O$2="Max",_xlfn.MAXIFS('Rent Roll Analysis'!I:I,'Rent Roll Analysis'!X:X,"MC|Studio"),AVERAGEIFS('Rent Roll Analysis'!I:I,'Rent Roll Analysis'!X:X,"MC|Studio",'Rent Roll Analysis'!I:I,">0")),0) -> 0 | T13: =IFERROR(S13*R13,0) -> 0 | U13: =IFERROR(S13/Q13,0) -> 0 | V13: =IFERROR(H53,0) -> 0 | W13: =IFERROR(V13/S13-1,"") | X13: =IFERROR(V13-S13,"") -> 0 | Y13: =IFERROR(V13*R13,0) -> 0 | Z13: =IFERROR(V13/Q13,0) -> 0
H14: =IFERROR(F14+G14,0) -> 0 | K14: =IFERROR(F14/J14,0) -> 0 | P14: MC Semi-Private | Q14: =IFERROR(AVERAGEIFS('Rent Roll Analysis'!T:T,'Rent Roll Analysis'!Y:Y,"MC|Semi-Private",'Rent Roll Analysis'!T:T,">0"),0) -> 0 | R14: =COUNTIF('Rent Roll Analysis'!Y:Y,"MC|Semi-Private") -> 0 | S14: =IFERROR(IF($O$2="Max",_xlfn.MAXIFS('Rent Roll Analysis'!I:I,'Rent Roll Analysis'!X:X,"MC|Semi-Private"),AVERAGEIFS('Rent Roll Analysis'!I:I,'Rent Roll Analysis'!X:X,"MC|Semi-Private",'Rent Roll Analysis'!I:I,">0")),0) -> 0 | T14: =IFERROR(S14*R14,0) -> 0 | U14: =IFERROR(S14/Q14,0) -> 0 | V14: =IFERROR(H53,0) -> 0 | W14: =IFERROR(V14/S14-1,"") | X14: =IFERROR(V14-S14,"") -> 0 | Y14: =IFERROR(V14*R14,0) -> 0 | Z14: =IFERROR(V14/Q14,0) -> 0
H15: =IFERROR(F15+G15,0) -> 0 | K15: =IFERROR(F15/J15,0) -> 0 | P15: Other | Q15: =IFERROR(AVERAGEIFS('Rent Roll Analysis'!$T$224:$T$623,'Rent Roll Analysis'!$Y$224:$Y$623,"<>",'Rent Roll Analysis'!$Y$224:$Y$623,"<>IL|Studio",'Rent Roll Analysis'!$Y$224:$Y$623,"<>IL|1 Bedroom",'Rent Roll Analysis'!$Y$224:$Y$623,"<>IL|2 Bedroom",'Rent Roll Analysis'!$Y$224:$Y$623,"<>AL|Studio",'Rent Roll Analysis'!$Y$224:$Y$623,"<>AL|Semi-Private",'Rent Roll Analysis'!$Y$224:$Y$623,"<>AL|1 Bedroom",'Rent Roll Analysis'!$Y$224:$Y$623,"<>MC|Studio",'Rent Roll Analysis'!$Y$224:$Y$623,"<>MC|Semi-Private",'Rent Roll Analysis'!$T$224:$T$623,">0"),0) -> 0 | R15: =COUNTIF('Rent Roll Analysis'!$Y$224:$Y$623,"?*")-R5-R6-R7-R9-R10-R11-R13-R14 -> 0 | S15: =IFERROR(IF($O$2="Max",_xlfn.MAXIFS('Rent Roll Analysis'!$I$224:$I$623,'Rent Roll Analysis'!$X$224:$X$623,"<>",'Rent Roll Analysis'!$X$224:$X$623,"<>IL|Studio",'Rent Roll Analysis'!$X$224:$X$623,"<>IL|1 Bedroom",'Rent Roll Analysis'!$X$224:$X$623,"<>IL|2 Bedroom",'Rent Roll Analysis'!$X$224:$X$623,"<>AL|Studio",'Rent Roll Analysis'!$X$224:$X$623,"<>AL|Semi-Private",'Rent Roll Analysis'!$X$224:$X$623,"<>AL|1 Bedroom",'Rent Roll Analysis'!$X$224:$X$623,"<>MC|Studio",'Rent Roll Analysis'!$X$224:$X$623,"<>MC|Semi-Private"),AVERAGEIFS('Rent Roll Analysis'!$I$224:$I$623,'Rent Roll Analysis'!$X$224:$X$623,"<>",'Rent Roll Analysis'!$X$224:$X$623,"<>IL|Studio",'Rent Roll Analysis'!$X$224:$X$623,"<>IL|1 Bedroom",'Rent Roll Analysis'!$X$224:$X$623,"<>IL|2 Bedroom",'Rent Roll Analysis'!$X$224:$X$623,"<>AL|Studio",'Rent Roll Analysis'!$X$224:$X$623,"<>AL|Semi-Private",'Rent Roll Analysis'!$X$224:$X$623,"<>AL|1 Bedroom",'Rent Roll Analysis'!$X$224:$X$623,"<>MC|Studio",'Rent Roll Analysis'!$X$224:$X$623,"<>MC|Semi-Private",'Rent Roll Analysis'!$I$224:$I$623,">0")),0) -> 0 | T15: =IFERROR(S15*R15,0) -> 0 | U15: =IFERROR(S15/Q15,0) -> 0 | V15: =IFERROR(AVERAGE(H19,H36,H53),0) -> 0 | W15: =IFERROR(V15/S15-1,"") | X15: =IFERROR(V15-S15,"") -> 0 | Y15: =IFERROR(V15*R15,0) -> 0 | Z15: =IFERROR(V15/Q15,0) -> 0
H16: =IFERROR(F16+G16,0) -> 0 | K16: =IFERROR(F16/J16,0) -> 0 | P16: Total / Average | Q16: =IFERROR((Q5*R5+Q6*R6+Q7*R7+Q9*R9+Q10*R10+Q11*R11+Q13*R13+Q14*R14+Q15*R15)/(R5+R6+R7+R9+R10+R11+R13+R14+R15),0) -> 0 | R16: =IFERROR(R5+R6+R7+R9+R10+R11+R13+R14+R15,0) -> 0 | S16: =IFERROR((R5*S5+R6*S6+R7*S7+R9*S9+R10*S10+R11*S11+R13*S13+R14*S14+R15*S15)/(R5+R6+R7+R9+R10+R11+R13+R14+R15),0) -> 0 | T16: =IFERROR(T5+T6+T7+T9+T10+T11+T13+T14+T15,0) -> 0 | U16: =IFERROR(T16/Q16,0) -> 0 | V16: =IFERROR((R5*V5+R6*V6+R7*V7+R9*V9+R10*V10+R11*V11+R13*V13+R14*V14+R15*V15)/(R5+R6+R7+R9+R10+R11+R13+R14+R15),0) -> 0 | W16: =IFERROR(V16/S16-1,"") | X16: =IFERROR(V16-S16,"") -> 0 | Y16: =IFERROR(Y5+Y6+Y7+Y9+Y10+Y11+Y13+Y14+Y15,0) -> 0 | Z16: =IFERROR(Y16/Q16,0) -> 0
H17: =IFERROR(F17+G17,0) -> 0 | K17: =IFERROR(F17/J17,0) -> 0 | P17: VALUE-ADD UNITS (manual inputs — negative R = removed, positive R = added)
H18: =IFERROR(F18+G18,0) -> 0 | K18: =IFERROR(F18/J18,0) -> 0 | P18: IL — Value-Add
A19: AVG — IN | F19: =IFERROR(AVERAGEIF(F7:F18,">"&0),0) -> 0 | G19: =IFERROR(AVERAGEIF(G7:G18,">"&0),0) -> 0 | H19: =IFERROR(AVERAGEIF(H7:H18,">"&0),0) -> 0 | I19: =IFERROR(AVERAGEIF(I7:I18,">"&0),0) -> 0 | P19: Add row 1 (label me) | T19: =IFERROR(S19*R19,0) -> 0 | U19: =IFERROR(S19/Q19,0) -> 0 | V19: =IFERROR(H19,0) -> 0 | W19: =IFERROR(V19/S19-1,"") | X19: =IFERROR(V19-S19,"") -> 0 | Y19: =IFERROR(V19*R19,0) -> 0 | Z19: =IFERROR(V19/Q19,0) -> 0
A20: Subj. vs. Avg IN Rent | F20: =Scenarios!F38-F19 -> 0 | P20: Add row 2 (label me) | T20: =IFERROR(S20*R20,0) -> 0 | U20: =IFERROR(S20/Q20,0) -> 0 | V20: =IFERROR(H19,0) -> 0 | W20: =IFERROR(V20/S20-1,"") | X20: =IFERROR(V20-S20,"") -> 0 | Y20: =IFERROR(V20*R20,0) -> 0 | Z20: =IFERROR(V20/Q20,0) -> 0
P21: AL — Value-Add
A22: ASSISTED LIVING (AL) COMPS | P22: Add row 1 (label me) | T22: =IFERROR(S22*R22,0) -> 0 | U22: =IFERROR(S22/Q22,0) -> 0 | V22: =IFERROR(H36,0) -> 0 | W22: =IFERROR(V22/S22-1,"") | X22: =IFERROR(V22-S22,"") -> 0 | Y22: =IFERROR(V22*R22,0) -> 0 | Z22: =IFERROR(V22/Q22,0) -> 0
A23: Distance (mi) | B23: Vintage | C23: Units | D23: Type | E23: Property Name | F23: Base Rent/mo | G23: Care Fee/mo | H23: All-In Rate | I23: Occupancy % | J23: Sq Ft | K23: $/Sq Ft | L23: Notes | P23: Add row 2 (label me) | T23: =IFERROR(S23*R23,0) -> 0 | U23: =IFERROR(S23/Q23,0) -> 0 | V23: =IFERROR(H36,0) -> 0 | W23: =IFERROR(V23/S23-1,"") | X23: =IFERROR(V23-S23,"") -> 0 | Y23: =IFERROR(V23*R23,0) -> 0 | Z23: =IFERROR(V23/Q23,0) -> 0
H24: =IFERROR(F24+G24,0) -> 0 | K24: =IFERROR(F24/J24,0) -> 0 | P24: MC — Value-Add
H25: =IFERROR(F25+G25,0) -> 0 | K25: =IFERROR(F25/J25,0) -> 0 | P25: Add row 1 (label me) | T25: =IFERROR(S25*R25,0) -> 0 | U25: =IFERROR(S25/Q25,0) -> 0 | V25: =IFERROR(H53,0) -> 0 | W25: =IFERROR(V25/S25-1,"") | X25: =IFERROR(V25-S25,"") -> 0 | Y25: =IFERROR(V25*R25,0) -> 0 | Z25: =IFERROR(V25/Q25,0) -> 0
H26: =IFERROR(F26+G26,0) -> 0 | K26: =IFERROR(F26/J26,0) -> 0 | P26: Subtotal — Value-Add | Q26: {=IFERROR(SUMPRODUCT(Q19:Q25,ABS(R19:R25))/SUMPRODUCT(ABS(R19:R25)),0)} -> 0 | R26: =SUM(R19:R25) -> 0 | S26: {=IFERROR(SUMPRODUCT(S19:S25,ABS(R19:R25))/SUMPRODUCT(ABS(R19:R25)),0)} -> 0 | T26: =SUM(T19:T25) -> 0 | U26: =IFERROR(T26/(Q26*R26),0) -> 0 | V26: {=IFERROR(SUMPRODUCT(V19:V25,ABS(R19:R25))/SUMPRODUCT(ABS(R19:R25)),0)} -> 0 | W26: =IFERROR(V26/S26-1,"") | X26: =IFERROR(V26-S26,"") -> 0 | Y26: =SUM(Y19:Y25) -> 0 | Z26: =IFERROR(Y26/(Q26*R26),0) -> 0
H27: =IFERROR(F27+G27,0) -> 0 | K27: =IFERROR(F27/J27,0) -> 0 | P27: TOTAL — STABILIZED (In-Place + Value-Add) | Q27: =IFERROR((Q16*R16+Q26*R26)/(R16+R26),0) -> 0 | R27: =R16+R26 -> 0 | S27: =IFERROR((S16*R16+S26*R26)/(R16+R26),0) -> 0 | T27: =T16+T26 -> 0 | U27: =IFERROR(T27/(Q27*R27),0) -> 0 | V27: =IFERROR((V16*R16+V26*R26)/(R16+R26),0) -> 0 | W27: =IFERROR(V27/S27-1,"") | X27: =IFERROR(V27-S27,"") -> 0 | Y27: =Y16+Y26 -> 0 | Z27: =IFERROR(Y27/(Q27*R27),0) -> 0
H28: =IFERROR(F28+G28,0) -> 0 | K28: =IFERROR(F28/J28,0) -> 0
H29: =IFERROR(F29+G29,0) -> 0 | K29: =IFERROR(F29/J29,0) -> 0 | P29: SUMMARY | Q29: Toggle Avg/Max at O2 to flex Current rents
H30: =IFERROR(F30+G30,0) -> 0 | K30: =IFERROR(F30/J30,0) -> 0 | S30: Current (In-Place) | V30: Target (Comp Repriced) | Y30: Projected (Stabilized) | AB30: T-12 Actual
