Workbook
Name Beds: 'Prop Info'!$B$15
Name EGI: Scenarios!$F$50
Name Total_LPA_Equity: Scenarios!$F$33
Name Total_Payroll: 'Staffing Matrix'!$M$67
Name Units: Scenarios!$B$8

Sheet Cover
A1: ASSISTED LIVING FACILITY — INVESTMENT SUMMARY
A2: Confidential — For Authorized Recipients Only
A4: PROPERTY INFORMATION
A5: Property Name | B5: ='Prop Info'!B4
A6: Location | B6: ='Prop Info'!B5
A7: Year Built | B7: ='Prop Info'!B9
A8: Total Units (physical rooms) | B8: =Scenarios!F8 | C8: =IFERROR('Prop Info'!$B$15,0)
A9: Gross Sq Ft | B9: ='Prop Info'!B11
A10: Asset Class | B10: ='Prop Info'!B13
A11: Active Scenario | B11: =Scenarios!B2
A12: Licensed Beds / Occupied Beds (Y1) | B12: =IFERROR('Prop Info'!$B$15,0) | C12: / | D12: =IFERROR(Scenarios!F51,0) | E12: =IFERROR(Scenarios!F51/'Prop Info'!$B$15,0)
A13: KEY DEAL METRICS
A14: Metric | B14: Value | C14: / Beds | D14: Returns Metric | E14: Value
A15: Purchase Price | B15: =Scenarios!F7 | D15: LP IRR | E15: =Waterfall!B69
A16: Price Per Room / Per Bed | B16: =Scenarios!F9 | C16: =IFERROR(Scenarios!F7/'Prop Info'!$B$15,0) | D16: GP IRR | E16: =Waterfall!E66
A17: Total Acquisition Cost | B17: =Scenarios!F17 | D17: LP Equity Multiple | E17: =IFERROR(Waterfall!B67,0)
A18: Loan Amount (Total) | B18: =Loans!E4 | D18: Y1 Cash-on-Cash | E18: ='P&L'!D126
A19: LTV | B19: =IFERROR(Scenarios!F144/Scenarios!F7,0) | D19: Year 5 NOI | E19: =IFERROR(INDEX('P&L'!D115:M116,1,Scenarios!F80),0)+IFERROR(INDEX('P&L'!D112:M113,1,Scenarios!F80),0)
A20: LTC | B20: =IFERROR(Scenarios!F144/Scenarios!F17,0) | D20: Exit Year | E20: =Scenarios!F80
A21: Equity Required | B21: =Scenarios!F31 | D21: Exit Cap Rate | E21: =Waterfall!B6
A22: Down Payment % | B22: =Scenarios!F10 | D22: Gross Sale Price | E22: =Waterfall!B32
A23: Entry Cap Rate | B23: =IFERROR('P&L'!D97/Scenarios!F7,0) | D23: Net to Equity (Exit) | E23: =Waterfall!B35
A24: Stabilized Cap Rate (Y5) | B24: =IFERROR((IFERROR(INDEX('P&L'!D115:M116,1,Scenarios!F80),0)+IFERROR(INDEX('P&L'!D112:M113,1,Scenarios!F80),0))/Scenarios!F7,0) | D24: Avg Annual Return (LP) | E24: =IFERROR((Waterfall!M54-(Waterfall!B9+Waterfall!B10))/(Waterfall!B9+Waterfall!B10)/Scenarios!F80,0)
A26: CAPITAL STACK
A27: Tranche | B27: Amount | C27: % | D27: Rate | E27: Term (yrs) | F27: Amort (yrs)
A28: Senior Loan (1st) | B28: =Scenarios!F86 | C28: =IFERROR(Scenarios!F86/Scenarios!F17,0) | D28: =Scenarios!F87 | E28: =Scenarios!F118 | F28: =Scenarios!F88
A29: 2nd Loan | B29: =Scenarios!F122 | C29: =IFERROR(Scenarios!F122/Scenarios!F17,0) | D29: =Scenarios!F123 | E29: =Scenarios!F125 | F29: =Scenarios!F124
A30: Supplemental | B30: =Scenarios!F129 | C30: =IFERROR(Scenarios!F129/Scenarios!F17,0) | D30: =Scenarios!F130 | E30: =Scenarios!F132 | F30: =Scenarios!F131
A31: GP Equity | B31: =Scenarios!F32 | C31: =Scenarios!F28 | D31: — | E31: — | F31: —
A32: Class A LP Equity | B32: =Scenarios!F33 | C32: =Scenarios!F29 | D32: =Scenarios!F35 | E32: — | F32: —
A33: Class B LP Equity | B33: =Scenarios!F34 | C33: =Scenarios!F30 | D33: — | E33: — | F33: —
A34: TOTAL | B34: =Scenarios!F31 | C34: =IFERROR(Scenarios!F31/Scenarios!F17,0) | D34: — | E34: — | F34: —
A36: INVESTOR RETURNS SUMMARY
A37: Metric | B37: Class A LP | C37: Class B LP | D37: LP Combined | E37: GP | F37: Notes
A38: Total Equity Invested | B38: =Waterfall!B9 | C38: =Waterfall!B10 | D38: =Waterfall!B9+Waterfall!B10 | E38: =Waterfall!B8 | F38: Capital contributed by each party
A39: Total Distributions | B39: =Waterfall!M55 | C39: =Waterfall!M56 | D39: =Waterfall!M57 | E39: =Waterfall!M58 | F39: Operating CF + exit proceeds
A40: Net Profit | B40: =Waterfall!M55-Waterfall!B9 | C40: =IFERROR(Waterfall!M56-Waterfall!B10,0) | D40: =Waterfall!M57-(Waterfall!B9+Waterfall!B10) | E40: =Waterfall!M58-Waterfall!B8
A41: Equity Multiple (EM) | B41: =IFERROR(Waterfall!B67,0) | C41: =IFERROR(Waterfall!C67,0) | D41: =IFERROR(Waterfall!D67,0) | E41: =IFERROR(Waterfall!E67,0) | F41: Total value returned / capital in
A42: IRR | B42: =Waterfall!B69 | C42: =Waterfall!C69 | D42: =Waterfall!D69 | E42: =Waterfall!E69 | F42: Includes exit proceeds
A43: Avg Annual Return (simple, incl. exit) | B43: =IFERROR((Waterfall!M55-Waterfall!B9)/Waterfall!B9/Scenarios!F80,0) | C43: =IFERROR((Waterfall!M56-Waterfall!B10)/Waterfall!B10/Scenarios!F80,0) | D43: =IFERROR((Waterfall!M57-(Waterfall!B9+Waterfall!B10))/(Waterfall!B9+Waterfall!B10)/Scenarios!F80,0) | E43: =IFERROR(IF(Waterfall!B8=0,"N/A",(Waterfall!M58-Waterfall!B8)/Waterfall!B8/Scenarios!F80),0) | F43: Simple: (total distributions − equity) ÷ equity ÷ hold yrs. Not compounded.
...

Sheet Prop Info
A1: PROPERTY INFORMATION & MARKET DATA
A2: Blue = manual input. Use the AI Market Research tool (separate app) to auto-populate market fields.
A3: PROPERTY DETAILS
A4: Property Name
A5: Location / Address
A6: # Units
A7: # Buildings
A8: Height (stories)
A9: Year Built
A10: Lot Size (acres)
A11: Gross Sq Ft
A12: Parking Spaces
... A18: MC Units
A19: Occupied Beds — Total | B19: =SUM(B20:B22)
A20: Occupied Beds — IL
A21: Occupied Beds — AL
A22: Occupied Beds — MC
A23: MARKET DATA
A24: City / Market
A25: MSA Name
A26: MSA Population
A27: City Population
A28: Population Growth Rate
A29: Senior 65+ Population
A30: Senior 65+ Growth Rate
A31: Avg Household Income
... A51: Value-Add Thesis

Sheet Scenarios
A1: SIDE-BY-SIDE SCENARIO ANALYSIS — "The 10-Minute Offer"
A2: Active Scenario → | B2: Actuals (T-12)
A3: Selecting an active scenario drives P&L, Cover Sheet, and Waterfall calculations. All 4 columns always visible for comparison.
A4: Line Item | B4: Actuals (T-12) | C4: 2. My Version | D4: 3. Projected | E4: 4. Best Scenario | F4: Active Scenario | G4: Licensed Beds / $/Bed | H4: Benchmark
A5: ACQUISITION
A6: Asking Price | C6: =B6 | D6: =C6 | E6: =D6 | F6: =CHOOSE(MATCH(B$2,{"Actuals (T-12)","2. My Version","3. Projected","4. Offer"},0),B6,C6,D6,E6) | G6: =IFERROR(F6/F$8,0) | H6: $8–16M typical 60-unit AL/MC
A7: Purchase Price / Offer | C7: =B7 | D7: =C7 | E7: =D7 | F7: =CHOOSE(MATCH(B$2,{"Actuals (T-12)","2. My Version","3. Projected","4. Offer"},0),B7,C7,D7,E7) | G7: =IFERROR(F7/F$8,0) | H7: Offer 5–15% below ask; value-add
A8: # Units (rooms) / Licensed Beds | C8: =Units | D8: =C8 | E8: =D8 | F8: =CHOOSE(MATCH(B$2,{"Actuals (T-12)","2. My Version","3. Projected","4. Offer"},0),B8,C8,D8,E8) | G8: ='Prop Info'!$B$15 | H8: Licensed beds from Prop Info — drives GPR. Units = physical rooms.
A9: Price Per Unit (physical room) | B9: =B7/B8 | C9: =C7/C8 | D9: =D7/D8 | E9: =E7/E8 | F9: =CHOOSE(MATCH(B$2,{"Actuals (T-12)","2. My Version","3. Projected","4. Offer"},0),B9,C9,D9,E9) | G9: =IFERROR(F7/'Prop Info'!$B$15,0) | H9: Price per licensed bed = purchase price ÷ licensed beds
A10: Down Payment % | C10: =B10 | D10: =C10 | E10: =D10 | F10: =CHOOSE(MATCH(B$2,{"Actuals (T-12)","2. My Version","3. Projected","4. Offer"},0),B10,C10,D10,E10) | H10: 25–35% down; 65–75% LTV target
A11: Down Payment $ | B11: =B10*B7 | C11: =B11 | D11: =D10*D7 | E11: =E10*E7 | F11: =CHOOSE(MATCH(B$2,{"Actuals (T-12)","2. My Version","3. Projected","4. Offer"},0),B11,C11,D11,E11) | G11: =IFERROR(F11/F$8,0) | H11: Auto-calculated from down payment
A12: Repairs / CapEx at Close | B12: =Capex!$D$51 | C12: =B12 | D12: =Capex!$D$51 | E12: =Capex!$D$51 | F12: =CHOOSE(MATCH(B$2,{"Actuals (T-12)","2. My Version","3. Projected","4. Offer"},0),B12,C12,D12,E12) | G12: =IFERROR(F12/F$8,0) | H12: Get contractor bid at LOI stage
A13: Operating Reserves | B13: =(B118/12)*1 | C13: =B13 | D13: =C13 | E13: =D13 | F13: =CHOOSE(MATCH(B$2,{"Actuals (T-12)","2. My Version","3. Projected","4. Offer"},0),B13,C13,D13,E13) | G13: =IFERROR(F13/(F$118/12),0) | H13: 3–6 months operating expenses
A14: Est. Closing Costs | B14: ='Acquisition Costs'!$D$37 | C14: ='Acquisition Costs'!$D$37 | D14: ='Acquisition Costs'!$D$37 | E14: ='Acquisition Costs'!$D$37 | F14: =CHOOSE(MATCH(B$2,{"Actuals (T-12)","2. My Version","3. Projected","4. Offer"},0),B14,C14,D14,E14) | G14: =F14/F7 | H14: 1.5–2.5% of purchase price
A15: Acquisition Fee (%) | B15: 0 | C15: =B15 | D15: =C15 | E15: =D15 | F15: =CHOOSE(MATCH(B$2,{"Actuals (T-12)","2. My Version","3. Projected","4. Offer"},0),B15,C15,D15,E15) | H15: 0.5–1.5% acq fee standard
A16: Acquisition Fee ($) | B16: =B15*B7 | C16: =C15*C7 | D16: =D15*D7 | E16: =E15*E7 | F16: =CHOOSE(MATCH(B$2,{"Actuals (T-12)","2. My Version","3. Projected","4. Offer"},0),B16,C16,D16,E16) | G16: =IFERROR(F16/F$8,0) | H16: Auto-calculated
A17: TOTAL ACQUISITION COST | B17: =B7+B12+B13+B14+B16 | C17: =C7+C12+C13+C14+C16 | D17: =D7+D12+D13+D14+D16 | E17: =E7+E12+E13+E14+E16 | F17: =CHOOSE(MATCH(B$2,{"Actuals (T-12)","2. My Version","3. Projected","4. Offer"},0),B17,C17,D17,E17) | G17: =IFERROR(F17/F$8,0) | H17: Auto-calculated total cost
A19: DEBT STRUCTURE
A20: Loan Amount (1st) | B20: =B135 | C20: =C135 | D20: =D135 | E20: =E135 | F20: =CHOOSE(MATCH(B$2,{"Actuals (T-12)","2. My Version","3. Projected","4. Offer"},0),B20,C20,D20,E20) | H20: 60–70% LTV senior; 75% bridge max
A21: Loan Amount (2nd) | B21: =B142 | C21: =C142 | D21: =D142 | E21: =E142 | F21: =CHOOSE(MATCH(B$2,{"Actuals (T-12)","2. My Version","3. Projected","4. Offer"},0),B21,C21,D21,E21) | H21: $0 if no mezz; up to 10% of stack
A22: Supplemental Loan | B22: =B149 | C22: =C149 | D22: =D149 | E22: =E149 | F22: =CHOOSE(MATCH(B$2,{"Actuals (T-12)","2. My Version","3. Projected","4. Offer"},0),B22,C22,D22,E22) | H22: $0 supplemental; add if SBA/seller
A23: Total Debt | B23: =B20+B21+B22 | C23: =C20+C21+C22 | D23: =D20+D21+D22 | E23: =E20+E21+E22 | F23: =CHOOSE(MATCH(B$2,{"Actuals (T-12)","2. My Version","3. Projected","4. Offer"},0),B23,C23,D23,E23) | H23: Auto-calculated total debt
A24: LTV (Loan/Purchase Price) | B24: =IFERROR(B23/B7,0) | C24: =IFERROR(C23/C7,0) | D24: =IFERROR(D23/D7,0) | E24: =IFERROR(E23/E7,0) | F24: =CHOOSE(MATCH(B$2,{"Actuals (T-12)","2. My Version","3. Projected","4. Offer"},0),B24,C24,D24,E24) | H24: Target ≤70% LTV (senior only)
A25: LTC (Loan/Total Acq. Cost) | B25: =IFERROR(B23/B17,0) | C25: =IFERROR(C23/C17,0) | D25: =IFERROR(D23/D17,0) | E25: =IFERROR(E23/E17,0) | F25: =CHOOSE(MATCH(B$2,{"Actuals (T-12)","2. My Version","3. Projected","4. Offer"},0),B25,C25,D25,E25) | H25: Target ≤80–85% LTC (value-add)
A27: EQUITY STRUCTURE
A28: GP Ownership % | B28: 0.6 | C28: =B28 | D28: =C28 | E28: =D28 | F28: =CHOOSE(MATCH(B$2,{"Actuals (T-12)","2. My Version","3. Projected","4. Offer"},0),B28,C28,D28,E28) | H28: GP co-invest 5–15% of total equity
A29: Class A LP % | B29: =1-B28 | C29: =1-C28 | D29: =1-D28 | E29: =1-E28 | F29: =CHOOSE(MATCH(B$2,{"Actuals (T-12)","2. My Version","3. Projected","4. Offer"},0),B29,C29,D29,E29) | H29: Class A LP 40–65% of total equity
A30: Class B LP % (auto) | B30: =1-B28-B29 | C30: =1-C28-C29 | D30: =1-D28-D29 | E30: =1-E28-E29 | F30: =CHOOSE(MATCH(B$2,{"Actuals (T-12)","2. My Version","3. Projected","4. Offer"},0),B30,C30,D30,E30) | H30: Class B LP 20–40% of total equity
A31: Total Equity (Acq Cost − Debt) | B31: =IFERROR(B17-B164,0) | C31: =IFERROR(C17-C164,0) | D31: =IFERROR(D17-D164,0) | E31: =IFERROR(E17-E164,0) | F31: =CHOOSE(MATCH(B$2,{"Actuals (T-12)","2. My Version","3. Projected","4. Offer"},0),B31,C31,D31,E31) | H31: Auto-calculated
A32: GP Equity ($) | C32: =B32 | D32: =C32 | E32: =D32 | F32: =CHOOSE(MATCH(B$2,{"Actuals (T-12)","2. My Version","3. Projected","4. Offer"},0),B32,C32,D32,E32) | H32: Enter GP co-invest $ directly — not tied to GP Ownership %
A33: Class A LP Equity ($) | B33: =B31-B32 | C33: =C31-C32 | D33: =D31-D32 | E33: =E31-E32 | F33: =CHOOSE(MATCH(B$2,{"Actuals (T-12)","2. My Version","3. Projected","4. Offer"},0),B33,C33,D33,E33) | H33: Total Equity − GP co-invest. GP can be $0 (all-LP deal).
A34: Class B LP Equity ($) | B34: =B30*B31 | C34: =C30*C31 | D34: =D30*D31 | E34: =E30*E31 | F34: =CHOOSE(MATCH(B$2,{"Actuals (T-12)","2. My Version","3. Projected","4. Offer"},0),B34,C34,D34,E34) | H34: Auto-calculated
A35: Class A Preferred Return % | B35: 0 | C35: =B35 | D35: =C35 | E35: =D35 | F35: =CHOOSE(MATCH(B$2,{"Actuals (T-12)","2. My Version","3. Projected","4. Offer"},0),B35,C35,D35,E35) | H35: Class A pref: 6–9% typical
A36: GP Promote % (defaults to GP% — edit to override) | B36: =B28 | C36: =C28 | D36: =D28 | E36: =E28 | F36: =CHOOSE(MATCH(B$2,{"Actuals (T-12)","2. My Version","3. Projected","4. Offer"},0),B36,C36,D36,E36) | H36: Promote: 20–30% GP typical. Edit directly.
A37: INCOME (YEAR 1 SNAPSHOT) — 4-Scenario Model
A38: ── LICENSED BEDS BY CARE LEVEL ──
A39: Licensed Beds — IL | C39: =B39 | D39: =C39 | E39: =D39 | F39: =CHOOSE(MATCH(B$2,{"Actuals (T-12)","2. My Version","3. Projected","4. Offer"},0),B39,C39,D39,E39) | H39: Independent Living bed count
A40: Licensed Beds — AL | C40: =B40 | D40: =C40 | E40: =D40 | F40: =CHOOSE(MATCH(B$2,{"Actuals (T-12)","2. My Version","3. Projected","4. Offer"},0),B40,C40,D40,E40) | H40: Assisted Living bed count
A41: Licensed Beds — MC | C41: =B41 | D41: =C41 | E41: =D41 | F41: =CHOOSE(MATCH(B$2,{"Actuals (T-12)","2. My Version","3. Projected","4. Offer"},0),B41,C41,D41,E41) | H41: Memory Care bed count
A42: Total Licensed Beds | B42: =B39+B40+B41 | C42: =C39+C40+C41 | D42: =D39+D40+D41 | E42: =E39+E40+E41 | F42: =CHOOSE(MATCH(B$2,{"Actuals (T-12)","2. My Version","3. Projected","4. Offer"},0),B42,C42,D42,E42) | H42: Sum of IL+AL+MC licensed beds — must match Prop Info!B15
...

Sheet P&L
A1: P&L — 10-YEAR PRO FORMA PROJECTIONS (Active Scenario drives all inputs)
A2: Blue = input | Black = formula | Green = cross-sheet. Escalators auto-pulled from annual averages. Override any cell and highlight yellow.
A4: ESCALATORS & ASSUMPTIONS | D4: Year 1 | E4: Year 2 | F4: Year 3 | G4: Year 4 | H4: Year 5 | I4: Year 6 | J4: Year 7 | K4: Year 8 | L4: Year 9 | M4: Year 10
A5: Annual Revenue Escalator | C5: — | D5: 0.04 | E5: 0.04 | F5: 0.04 | G5: 0.04 | H5: =G5 | I5: =H5 | J5: =I5 | K5: =J5 | L5: =K5 | M5: =L5 | N5: Avg: | O5: =AVERAGE(D5:M5)
A6: Annual Expense Escalator | C6: — | D6: 0.03 | E6: 0.03 | F6: 0.03 | G6: 0.03 | H6: 0.03 | I6: =H6 | J6: =I6 | K6: =J6 | L6: =K6 | M6: =L6 | N6: Avg: | O6: =AVERAGE(D6:M6)
A8: Line Item | C8: T-12 Actual | D8: Year 1 | E8: Year 2 | F8: Year 3 | G8: Year 4 | H8: Year 5 | I8: Year 6 | J8: Year 7 | K8: Year 8 | L8: Year 9 | M8: Year 10 | N8: Total (Y1–Y5) | O8: Total (Y1–Y10) | P8: Avg / Yr | Q8: Y1 % EGI / Y1 Value
A9: INCOME
A10: Avg. Rent / Bed | C10: =IFERROR((C43/C42)/12,0) | D10: =IFERROR((D43/D42)/12,0) | E10: =IFERROR((E43/E42)/12,0) | F10: =IFERROR((F43/F42)/12,0) | G10: =IFERROR((G43/G42)/12,0) | H10: =IFERROR((H43/H42)/12,0) | I10: =IFERROR((I43/I42)/12,0) | J10: =IFERROR((J43/J42)/12,0) | ... M10: =IFERROR((M43/M42)/12,0)
A11: ── INDEPENDENT LIVING (IL) ──
A12: Licensed Beds — IL | C12: =Scenarios!B39 | D12: =Scenarios!F39 | E12: =D12 | F12: =E12 | G12: =F12 | H12: =G12 | I12: =H12 | J12: =I12 | K12: =J12 | L12: =K12 | M12: =L12
A13: Avg Monthly Rate — IL | C13: =Scenarios!B44 | D13: =Scenarios!F44 | E13: =D13*(1+E$5) | F13: =E13*(1+F$5) | G13: =F13*(1+G$5) | H13: =G13*(1+H$5) | I13: =H13*(1+I$5) | J13: =I13*(1+J$5) | K13: =J13*(1+K$5) | L13: =K13*(1+L$5) | M13: =L13*(1+M$5)
A14: GPR — IL | C14: =C12*C13*12 | D14: =D12*D13*12 | E14: =E12*E13*12 | F14: =F12*F13*12 | G14: =G12*G13*12 | H14: =H12*H13*12 | I14: =I12*I13*12 | J14: =J12*J13*12 | ... M14: =M12*M13*12 | N14: =SUM(D14:H14) | O14: =SUM(D14:M14) | P14: =IFERROR(O14/10,0) | Q14: =IFERROR(D14/$D$50,0)
A15: Vacancy % — IL | C15: =Scenarios!B53 | D15: =Scenarios!F53 | E15: =D15 | F15: =E15 | G15: =F15 | H15: =G15 | I15: =H15 | J15: =I15 | K15: =J15 | L15: =K15 | M15: =L15
A16: Less: Vacancy — IL | C16: =IFERROR(-C15*C14,0) | D16: =IFERROR(-D15*D14,0) | E16: =IFERROR(-E15*E14,0) | F16: =IFERROR(-F15*F14,0) | G16: =IFERROR(-G15*G14,0) | H16: =IFERROR(-H15*H14,0) | I16: =IFERROR(-I15*I14,0) | J16: =IFERROR(-J15*J14,0) | ... M16: =IFERROR(-M15*M14,0)
A17: Loss to Lease % — IL | C17: =Scenarios!B58 | D17: =Scenarios!F58 | E17: =D17 | F17: =E17 | G17: =F17 | H17: =G17 | I17: =H17 | J17: =I17 | K17: =J17 | L17: =K17 | M17: =L17
A18: Less: Loss to Lease — IL | C18: =IFERROR(-C17*C14,0) | D18: =IFERROR(-D17*D14,0) | E18: =IFERROR(-E17*E14,0) | F18: =IFERROR(-F17*F14,0) | G18: =IFERROR(-G17*G14,0) | H18: =IFERROR(-H17*H14,0) | I18: =IFERROR(-I17*I14,0) | J18: =IFERROR(-J17*J14,0) | ... M18: =IFERROR(-M17*M14,0)
A19: Bad Debt / Concessions % — IL | C19: =Scenarios!B60 | D19: =Scenarios!F60 | E19: =D19 | F19: =E19 | G19: =F19 | H19: =G19 | I19: =H19 | J19: =I19 | K19: =J19 | L19: =K19 | M19: =L19
A20: Less: Concessions/Bad Debt — IL | C20: =IFERROR(-C19*C14,0) | D20: =IFERROR(-D19*D14,0) | E20: =IFERROR(-E19*E14,0) | F20: =IFERROR(-F19*F14,0) | G20: =IFERROR(-G19*G14,0) | H20: =IFERROR(-H19*H14,0) | I20: =IFERROR(-I19*I14,0) | J20: =IFERROR(-J19*J14,0) | ... M20: =IFERROR(-M19*M14,0)
A21: ── ASSISTED LIVING (AL) ──
A22: Licensed Beds — AL | C22: =Scenarios!B40 | D22: =Scenarios!F40 | E22: =D22 | F22: =E22 | G22: =F22 | H22: =G22 | I22: =H22 | J22: =I22 | K22: =J22 | L22: =K22 | M22: =L22
A23: Avg Monthly Rate — AL | C23: =Scenarios!B45 | D23: =Scenarios!F45 | E23: =D23*(1+E$5) | F23: =E23*(1+F$5) | G23: =F23*(1+G$5) | H23: =G23*(1+H$5) | I23: =H23*(1+I$5) | J23: =I23*(1+J$5) | K23: =J23*(1+K$5) | L23: =K23*(1+L$5) | M23: =L23*(1+M$5)
A24: GPR — AL | C24: =C22*C23*12 | D24: =D22*D23*12 | E24: =E22*E23*12 | F24: =F22*F23*12 | G24: =G22*G23*12 | H24: =H22*H23*12 | I24: =I22*I23*12 | J24: =J22*J23*12 | ... M24: =M22*M23*12 | N24: =SUM(D24:H24) | O24: =SUM(D24:M24) | P24: =IFERROR(O24/10,0) | Q24: =IFERROR(D24/$D$50,0)
A25: Vacancy % — AL | C25: =Scenarios!B54 | D25: =Scenarios!F54 | E25: =D25 | F25: =E25 | G25: =F25 | H25: =G25 | I25: =H25 | J25: =I25 | K25: =J25 | L25: =K25 | M25: =L25
A26: Less: Vacancy — AL | C26: =IFERROR(-C25*C24,0) | D26: =IFERROR(-D25*D24,0) | E26: =IFERROR(-E25*E24,0) | F26: =IFERROR(-F25*F24,0) | G26: =IFERROR(-G25*G24,0) | H26: =IFERROR(-H25*H24,0) | I26: =IFERROR(-I25*I24,0) | J26: =IFERROR(-J25*J24,0) | ... M26: =IFERROR(-M25*M24,0)
A27: Loss to Lease % — AL | C27: =Scenarios!B58 | D27: =Scenarios!F58 | E27: =D27 | F27: =E27 | G27: =F27 | H27: =G27 | I27: =H27 | J27: =I27 | K27: =J27 | L27: =K27 | M27: =L27
A28: Less: Loss to Lease — AL | C28: =IFERROR(-C27*C24,0) | D28: =IFERROR(-D27*D24,0) | E28: =IFERROR(-E27*E24,0) | F28: =IFERROR(-F27*F24,0) | G28: =IFERROR(-G27*G24,0) | H28: =IFERROR(-H27*H24,0) | I28: =IFERROR(-I27*I24,0) | J28: =IFERROR(-J27*J24,0) | ... M28: =IFERROR(-M27*M24,0)
A29: Bad Debt / Concessions % — AL | C29: =Scenarios!B60 | D29: =Scenarios!F60 | E29: =D29 | F29: =E29 | G29: =F29 | H29: =G29 | I29: =H29 | J29: =I29 | K29: =J29 | L29: =K29 | M29: =L29
A30: Less: Concessions/Bad Debt — AL | C30: =IFERROR(-C29*C24,0) | D30: =IFERROR(-D29*D24,0) | E30: =IFERROR(-E29*E24,0) | F30: =IFERROR(-F29*F24,0) | G30: =IFERROR(-G29*G24,0) | H30: =IFERROR(-H29*H24,0) | I30: =IFERROR(-I29*I24,0) | J30: =IFERROR(-J29*J24,0) | ... M30: =IFERROR(-M29*M24,0)
A31: ── MEMORY CARE (MC) ──
A32: Licensed Beds — MC | C32: =Scenarios!B41 | D32: =Scenarios!F41 | E32: =D32 | F32: =E32 | G32: =F32 | H32: =G32 | I32: =H32 | J32: =I32 | K32: =J32 | L32: =K32 | M32: =L32
A33: Avg Monthly Rate — MC | C33: =Scenarios!B46 | D33: =Scenarios!F46 | E33: =D33*(1+E$5) | F33: =E33*(1+F$5) | G33: =F33*(1+G$5) | H33: =G33*(1+H$5) | I33: =H33*(1+I$5) | J33: =I33*(1+J$5) | K33: =J33*(1+K$5) | L33: =K33*(1+L$5) | M33: =L33*(1+M$5)
A34: GPR — MC | C34: =C32*C33*12 | D34: =D32*D33*12 | E34: =E32*E33*12 | F34: =F32*F33*12 | G34: =G32*G33*12 | H34: =H32*H33*12 | I34: =I32*I33*12 | J34: =J32*J33*12 | ... M34: =M32*M33*12 | N34: =SUM(D34:H34) | O34: =SUM(D34:M34) | P34: =IFERROR(O34/10,0) | Q34: =IFERROR(D34/$D$50,0)
A35: Vacancy % — MC | C35: =Scenarios!B55 | D35: =Scenarios!F55 | E35: =D35 | F35: =E35 | G35: =F35 | H35: =G35 | I35: =H35 | J35: =I35 | K35: =J35 | L35: =K35 | M35: =L35
A36: Less: Vacancy — MC | C36: =IFERROR(-C35*C34,0) | D36: =IFERROR(-D35*D34,0) | E36: =IFERROR(-E35*E34,0) | F36: =IFERROR(-F35*F34,0) | G36: =IFERROR(-G35*G34,0) | H36: =IFERROR(-H35*H34,0) | I36: =IFERROR(-I35*I34,0) | J36: =IFERROR(-J35*J34,0) | ... M36: =IFERROR(-M35*M34,0)
A37: Loss to Lease % — MC | C37: =Scenarios!B58 | D37: =Scenarios!F58 | E37: =D37 | F37: =E37 | G37: =F37 | H37: =G37 | I37: =H37 | J37: =I37 | K37: =J37 | L37: =K37 | M37: =L37
A38: Less: Loss to Lease — MC | C38: =IFERROR(-C37*C34,0) | D38: =IFERROR(-D37*D34,0) | E38: =IFERROR(-E37*E34,0) | F38: =IFERROR(-F37*F34,0) | G38: =IFERROR(-G37*G34,0) | H38: =IFERROR(-H37*H34,0) | I38: =IFERROR(-I37*I34,0) | J38: =IFERROR(-J37*J34,0) | ... M38: =IFERROR(-M37*M34,0)
A39: Bad Debt / Concessions % — MC | C39: =Scenarios!B60 | D39: =Scenarios!F60 | E39: =D39 | F39: =E39 | G39: =F39 | H39: =G39 | I39: =H39 | J39: =I39 | K39: =J39 | L39: =K39 | M39: =L39
A40: Less: Concessions/Bad Debt — MC | C40: =IFERROR(-C39*C34,0) | D40: =IFERROR(-D39*D34,0) | E40: =IFERROR(-E39*E34,0) | F40: =IFERROR(-F39*F34,0) | G40: =IFERROR(-G39*G34,0) | H40: =IFERROR(-H39*H34,0) | I40: =IFERROR(-I39*I34,0) | J40: =IFERROR(-J39*J34,0) | ... M40: =IFERROR(-M39*M34,0)
A41: ── SUMMARY ROLLUP ──
A42: Total Licensed Beds | C42: =C12+C22+C32 | D42: =D12+D22+D32 | E42: =E12+E22+E32 | F42: =F12+F22+F32 | G42: =G12+G22+G32 | H42: =H12+H22+H32 | I42: =I12+I22+I32 | J42: =J12+J22+J32 | ... M42: =M12+M22+M32 | N42: =D42 | O42: =D42 | P42: =D42
...

Sheet T-12 Analysis
A1: T-12 ANALYSIS — Trailing 12 Diagnostic Layer (Senior Living)
A2: ANALYSIS on top. Standardized aggregation (Layer 3) and raw paste block (Layer 1) below — scroll down to access data. Per Bed/Month uses occupied beds from Rent Roll Analysis. Benchmarks calibrated to assisted/memory care community norms.
A4: B. RECONCILIATION CHECK — Are all raw lines mapped?
A5: EGI: | B5: =N69 | C5: OpEx: | D5: =N114 | E5: EBITDAR: | F5: 0 | G5: Unmapped $: | H5: 0 | I5: 🟢 all mapped | L5: EGI / Occ Bed / Mo: | M5: 0
A7: C. TREND ANALYSIS — T-3 vs. T-6 vs. T-12 (annualized)
A8: Metric | B8: T-12 Actual | C8: T-6 Annlzd | D8: T-3 Annlzd | E8: T-3 vs T-12 Δ$ | F8: T-3 vs T-12 Δ% | G8: Direction | H8: Read
A9: EGI | B9: =N69 | C9: 0 | D9: 0 | E9: 0 | F9: 0 | G9: → stable | H9: stable
A10: Total OpEx | B10: =N114 | C10: 0 | D10: 0 | E10: 0 | F10: 0 | G10: → stable | H10: stable
A11: EBITDAR | B11: =N69-N114 | C11: 0 | D11: 0 | E11: 0 | F11: 0 | G11: → stable | H11: stable
A12: Bad Debt + Write-offs | B12: =N106 | C12: 0 | D12: 0 | E12: 0 | F12: 0 | G12: → stable | H12: stable
A13: Total Labor & Burden | B13: =N85 | C13: 0 | D13: 0 | E13: 0 | F13: 0 | G13: → stable | H13: stable
A14: Food Cost | B14: =N87 | C14: 0 | D14: 0 | E14: 0 | F14: 0 | G14: → stable | H14: stable
A15: Utilities | B15: =N96 | C15: 0 | D15: 0 | E15: 0 | F15: 0 | G15: → stable | H15: stable
A16: Overtime Wages | B16: =N79 | C16: 0 | D16: 0 | E16: 0 | F16: 0 | G16: → stable | H16: stable
A18: D. ECONOMIC vs. PHYSICAL OCCUPANCY RECONCILIATION
A19: Licensed Beds (IL + AL + MC) | B19: 176
A20: Physically Occupied Beds | B20: 128
A21: Physical Occupancy % | B21: =IFERROR(B20/B19,0)
A22: Gross Potential Rent / GPR (annual) | B22: =N58
A23: Net Rent Revenue (billed) | B23: =N63
A24: Total Revenue / EGI | B24: =N69
A25: Economic Occupancy % (Net Rent / GPR) | B25: =IFERROR(B23/B22,0)
A26: Economic vs. Physical Gap | B26: 0
A27: → Lost Revenue from Gap ($) | B27: 0
A29: E. BAD DEBT & WRITE-OFF LAYERED ANALYSIS
A30: Component | B30: Amount | C30: % of GPR | D30: Per Bed/Mo | E30: Benchmark | F30: Read
A31: Vacancy Loss | B31: 0 | C31: 0 | D31: 0 | E31: 5–10% GPR | F31: ok
A32: Bad Debt / Write-offs | B32: 0 | C32: 0 | D32: 0 | E32: 1–3% GPR | F32: ok
A33: Concessions & Specials | B33: 0 | C33: 0 | D33: 0 | E33: 0.5–2% GPR | F33: ok
A34: Delinquency Change | B34: 0 | C34: 0 | D34: 0 | E34: <2% GPR | F34: ok
A35: Total Rent Reductions | B35: 0 | C35: 0 | D35: 0 | F35: ok
A37: F. TAX & INSURANCE ACCRUAL CHECK
A38: T-12 actuals rarely equal pro forma. Triangulate RE taxes with reassessment estimate; insurance with lender quote.
A40: Real Estate Taxes
A41: T-12 Actual | B41: 0
A42: Pro Forma Estimate | B42: 0
A43: Variance (Actual − PF) | B43: 0
A44: Status | B44: ⚠ not in T-12 — verify with operator / broker
A46: P&C Insurance
A47: T-12 Actual | B47: 0
...

Sheet Acquisition Costs
A1: ACQUISITION COSTS — USE OF CAPITAL
A3: USE OF CAPITAL SUMMARY
A4: Purchase Price | D4: =Scenarios!F7
A5: Less: Total Loan Amount | D5: =-Scenarios!F23
A6: Down Payment Required | D6: =D4+D5
A7: Closing Costs | D7: =D37
A8: Acquisition Fee | B8: =Scenarios!F15 | D8: =Scenarios!F16
A9: Repair Escrow / CapEx | D9: =Scenarios!F12
A10: Operating Reserves | D10: =Scenarios!F13
A11: TOTAL CASH AT CLOSE | D11: =SUM(D6:D10)
A13: CLOSING COSTS DETAIL
A14: Item | B14: Rate/Factor | C14: Notes | D14: Amount
A15: LENDER FEES & THIRD-PARTY COSTS
A16: Environmental (EDR)
A17: Appraisal
A18: Structural Inspection
A19: Lender Legal Fees
A20: Bank Doc Prep Fee
A21: Origination Fee | B21: =Scenarios!F140 | C21: Total origination fees — all tranches | D21: =Scenarios!F140*Scenarios!F135+Scenarios!F147*Scenarios!F142+Scenarios!F154*Scenarios!F149
A22: TITLE & CLOSING COSTS
A23: Title Policy | B23: 0.003 | C23: 0.30% of purchase price | D23: =B23*Scenarios!F7
A24: Survey
A25: Recording
A26: Transfer Taxes | B26: 0.0035 | C26: 0.35% of purchase price | D26: =B26*Scenarios!F7
A27: Title Processing Fee
A28: Title Search
A29: Attorney Fees
A30: OTHER COSTS
A31: Legal (LLC, PPM, OA)
A32: Property Inspection
A33: Travel
A34: Miscellaneous
A35: RE Taxes | D35: =Scenarios!F108/4
A36: Insurance | D36: =Scenarios!F104/4
A37: TOTAL CLOSING & OTHER COSTS | D37: =IF(D4=0, "",SUM(D16:D36))

Sheet Staffing Matrix
A1: STAFFING MATRIX — PER-SHIFT | FTE BUILD | HPPD | TOTAL PAYROLL → P&L R28
A2: Blue=Input | Black=Formula | Green=Cross-sheet. Cell M69 (Total Payroll) feeds P&L!C28 automatically. Census pulled from Scenarios sheet.
A4: SECTION 1 — CENSUS & STAFFING RATE ASSUMPTIONS
A5: Total Units (physical rooms, from Scenarios) | C5: =IFERROR(Scenarios!F8,90) | D5: Physical rooms ≠ licensed beds — see Prop Info for bed count
A6: AL Occupied Beds (Y1 census) | D6: Enter occupied bed count, not room count
A7: MC Occupied Beds (Y1 census) | D7: Enter occupied bed count, not room count
A8: IL Occupied Beds (Y1 census)
A9: Total Care Residents (AL + MC occupied beds) | C9: =C6+C7
A10: Licensed Beds (from Prop Info — regulatory ceiling) | C10: =IFERROR('Prop Info'!$B$15,0) | D10: Licensed beds = regulatory max. Occupied beds ≤ licensed beds.
A11: Rate & Cost Assumptions
A12: Benefits Load (FICA + health + 401k) | C12: 0.2 | D12: Typical 18–22%
A13: Overtime Load | C13: 0.05 | D13: 5% of base wages; AL/MC often higher
A14: Eve Differential ($/hr premium) | C14: 1.5 | D14: 3p–11p shift
A15: Night Differential ($/hr premium) | C15: 2.5 | D15: 11p–7a shift
A16: Weekend Premium ($/hr) | C16: 0.75 | D16: Added to shift differential
A18: Target Staffing Ratios (residents : 1 staff)
A19: Ratio-driven CNA rows auto-calculate headcount. Verify against your state DOH minimum requirements.
A20: AL — Day Shift (1:X residents per aide) | C20: 6 | D20: 1:6 day; increase MC urgency
A21: AL — Evening Shift (1:X) | C21: 7 | D21: 1:7 eve; lighter acuity overnight
A22: AL — Night Shift (1:X) | C22: 10 | D22: 1:10 night minimum
A23: MC — Day Shift (1:X) | C23: 5 | D23: 1:5 MC day; CMS recommends closer to 1:4
A24: MC — Evening Shift (1:X) | C24: 6 | D24: 1:6 MC eve
A25: MC — Night Shift (1:X) | C25: 8 | D25: 1:8 MC night
A27: SECTION 2 — PER-SHIFT HEADCOUNT MATRIX (staff per shift × 6 shifts)
C28: WEEKDAY | F28: WEEKEND | I28: Hrs/Wk | J28: FTEs | K28: Base $/hr | L28: Shift-Adj $/hr | M28: Annual Cost ($) | N28: % Total Payroll
A29: Position | B29: Dept | C29: Day 7a–3p | D29: Eve 3p–11p | E29: Night 11p–7a | F29: Day 7a–3p | G29: Eve 3p–11p | H29: Night 11p–7a
A30: Care Staff
A31: Director of Nursing | B31: Care | D31: 0 | E31: 0 | G31: 0 | H31: 0 | I31: =((C31+D31+E31)*5+(F31+G31+H31)*2)*8 | J31: =IFERROR(I31*52/2080,0) | L31: =IFERROR((C31*K31+D31*(K31+$C$14)+E31*(K31+$C$15)+F31*(K31+$C$16)+G31*(K31+$C$14+$C$16)+H31*(K31+$C$15+$C$16))/MAX(C31+D31+E31+F31+G31+H31,1),K31) | M31: =IFERROR(J31*2080*L31*(1+$C$12)*(1+$C$13),0) | N31: =IFERROR(M31/M67,0)
A32: RN / Asst DON | B32: Care | E32: 0 | G32: 0 | H32: 0 | I32: =((C32+D32+E32)*5+(F32+G32+H32)*2)*8 | J32: =IFERROR(I32*52/2080,0) | L32: =IFERROR((C32*K32+D32*(K32+$C$14)+E32*(K32+$C$15)+F32*(K32+$C$16)+G32*(K32+$C$14+$C$16)+H32*(K32+$C$15+$C$16))/MAX(C32+D32+E32+F32+G32+H32,1),K32) | M32: =IFERROR(J32*2080*L32*(1+$C$12)*(1+$C$13),0) | N32: =IFERROR(M32/M67,0)
A33: Med Tech / CMA | B33: Care | I33: =((C33+D33+E33)*5+(F33+G33+H33)*2)*8 | J33: =IFERROR(I33*52/2080,0) | L33: =IFERROR((C33*K33+D33*(K33+$C$14)+E33*(K33+$C$15)+F33*(K33+$C$16)+G33*(K33+$C$14+$C$16)+H33*(K33+$C$15+$C$16))/MAX(C33+D33+E33+F33+G33+H33,1),K33) | M33: =IFERROR(J33*2080*L33*(1+$C$12)*(1+$C$13),0) | N33: =IFERROR(M33/M67,0)
A34: CNA — Day (AL) | B34: Care | C34: =IFERROR(CEILING(C6/C20,1),0) | D34: 0 | E34: 0 | F34: =IFERROR(CEILING(C6/C20,1),0) | G34: 0 | H34: 0 | I34: =((C34+D34+E34)*5+(F34+G34+H34)*2)*8 | J34: =IFERROR(I34*52/2080,0) | L34: =IFERROR((C34*K34+D34*(K34+$C$14)+E34*(K34+$C$15)+F34*(K34+$C$16)+G34*(K34+$C$14+$C$16)+H34*(K34+$C$15+$C$16))/MAX(C34+D34+E34+F34+G34+H34,1),K34) | M34: =IFERROR(J34*2080*L34*(1+$C$12)*(1+$C$13),0) | N34: =IFERROR(M34/M67,0)
A35: CNA — Eve (AL) | B35: Care | C35: 0 | D35: =IFERROR(CEILING(C6/C21,1),0) | E35: 0 | F35: 0 | G35: =IFERROR(CEILING(C6/C21,1),0) | H35: 0 | I35: =((C35+D35+E35)*5+(F35+G35+H35)*2)*8 | J35: =IFERROR(I35*52/2080,0) | L35: =IFERROR((C35*K35+D35*(K35+$C$14)+E35*(K35+$C$15)+F35*(K35+$C$16)+G35*(K35+$C$14+$C$16)+H35*(K35+$C$15+$C$16))/MAX(C35+D35+E35+F35+G35+H35,1),K35) | M35: =IFERROR(J35*2080*L35*(1+$C$12)*(1+$C$13),0) | N35: =IFERROR(M35/M67,0)
A36: CNA — Night (AL) | B36: Care | C36: 0 | D36: 0 | E36: =IFERROR(CEILING(C6/C22,1),0) | F36: 0 | G36: 0 | H36: =IFERROR(CEILING(C6/C22,1),0) | I36: =((C36+D36+E36)*5+(F36+G36+H36)*2)*8 | J36: =IFERROR(I36*52/2080,0) | L36: =IFERROR((C36*K36+D36*(K36+$C$14)+E36*(K36+$C$15)+F36*(K36+$C$16)+G36*(K36+$C$14+$C$16)+H36*(K36+$C$15+$C$16))/MAX(C36+D36+E36+F36+G36+H36,1),K36) | M36: =IFERROR(J36*2080*L36*(1+$C$12)*(1+$C$13),0) | N36: =IFERROR(M36/M67,0)
A37: CNA — Day (MC) | B37: Care | C37: =IFERROR(CEILING(C7/C23,1),0) | D37: 0 | E37: 0 | F37: =IFERROR(CEILING(C7/C23,1),0) | G37: 0 | H37: 0 | I37: =((C37+D37+E37)*5+(F37+G37+H37)*2)*8 | J37: =IFERROR(I37*52/2080,0) | L37: =IFERROR((C37*K37+D37*(K37+$C$14)+E37*(K37+$C$15)+F37*(K37+$C$16)+G37*(K37+$C$14+$C$16)+H37*(K37+$C$15+$C$16))/MAX(C37+D37+E37+F37+G37+H37,1),K37) | M37: =IFERROR(J37*2080*L37*(1+$C$12)*(1+$C$13),0) | N37: =IFERROR(M37/M67,0)
A38: CNA — Eve (MC) | B38: Care | C38: 0 | D38: =IFERROR(CEILING(C7/C24,1),0) | E38: 0 | F38: 0 | G38: =IFERROR(CEILING(C7/C24,1),0) | H38: 0 | I38: =((C38+D38+E38)*5+(F38+G38+H38)*2)*8 | J38: =IFERROR(I38*52/2080,0) | L38: =IFERROR((C38*K38+D38*(K38+$C$14)+E38*(K38+$C$15)+F38*(K38+$C$16)+G38*(K38+$C$14+$C$16)+H38*(K38+$C$15+$C$16))/MAX(C38+D38+E38+F38+G38+H38,1),K38) | M38: =IFERROR(J38*2080*L38*(1+$C$12)*(1+$C$13),0) | N38: =IFERROR(M38/M67,0)
A39: CNA — Night (MC) | B39: Care | C39: 0 | D39: 0 | E39: =IFERROR(CEILING(C7/C25,1),0) | F39: 0 | G39: 0 | H39: =IFERROR(CEILING(C7/C25,1),0) | I39: =((C39+D39+E39)*5+(F39+G39+H39)*2)*8 | J39: =IFERROR(I39*52/2080,0) | L39: =IFERROR((C39*K39+D39*(K39+$C$14)+E39*(K39+$C$15)+F39*(K39+$C$16)+G39*(K39+$C$14+$C$16)+H39*(K39+$C$15+$C$16))/MAX(C39+D39+E39+F39+G39+H39,1),K39) | M39: =IFERROR(J39*2080*L39*(1+$C$12)*(1+$C$13),0) | N39: =IFERROR(M39/M67,0)
A40: Subtotal — Care Staff | C40: =SUM(C31:C39) | D40: =SUM(D31:D39) | E40: =SUM(E31:E39) | F40: =SUM(F31:F39) | G40: =SUM(G31:G39) | H40: =SUM(H31:H39) | I40: =SUM(I31:I39) | J40: =SUM(J31:J39) | M40: =SUM(M31:M39)
A42: Dining
A43: Dining Manager / Chef | B43: Dining | E43: 0 | H43: 0 | I43: =((C43+D43+E43)*5+(F43+G43+H43)*2)*8 | J43: =IFERROR(I43*52/2080,0) | L43: =IFERROR((C43*K43+D43*(K43+$C$14)+E43*(K43+$C$15)+F43*(K43+$C$16)+G43*(K43+$C$14+$C$16)+H43*(K43+$C$15+$C$16))/MAX(C43+D43+E43+F43+G43+H43,1),K43) | M43: =IFERROR(J43*2080*L43*(1+$C$12)*(1+$C$13),0) | N43: =IFERROR(M43/M67,0)
A44: Cook | B44: Dining | E44: 0 | H44: 0 | I44: =((C44+D44+E44)*5+(F44+G44+H44)*2)*8 | J44: =IFERROR(I44*52/2080,0) | L44: =IFERROR((C44*K44+D44*(K44+$C$14)+E44*(K44+$C$15)+F44*(K44+$C$16)+G44*(K44+$C$14+$C$16)+H44*(K44+$C$15+$C$16))/MAX(C44+D44+E44+F44+G44+H44,1),K44) | M44: =IFERROR(J44*2080*L44*(1+$C$12)*(1+$C$13),0) | N44: =IFERROR(M44/M67,0)
...

Sheet Rent Roll Analysis
A1: RENT ROLL ANALYSIS — Diagnostic Layer (Senior Living)
A2: ANALYSIS on top. Raw rent roll below — paste from RentrollApp-Cl output. AR aging columns Q–T blank (paste from Analyzer AR Input or operator AR aging report). Care level: IL = Independent Living · AL = Assisted Living · MC = Memory Care.
A4: B. HEALTH CHECK — RR vs. Prop Info reconciliation
A5: Date: | C5: Property: | D5: =TODAY() | E5: Lic Beds (Prop): | F5: ='Prop Info'!B15 | G5: Lic Beds (RR): | H5: =COUNTA(B211:B610) | I5: Match: | J5: =IF(F5=H5,"✓ match","⚠ mismatch: "&(H5-F5)) | K5: Total AR: | L5: =SUM(L211:L610) | N5: On Notice: | O5: =COUNTIF(D211:D610,"Notice") | Q5: Occupied: | R5: =COUNTIF(D211:D610,"Occupied")+COUNTIF(D211:D610,"Notice")
D6: As of date for diagnostic
A7: C. CARE LEVEL CENSUS — Licensed beds, occupancy, and rate by level
A8: Care Level | B8: Licensed Beds | C8: Occupied Beds | D8: Occupancy % | E8: Avg Monthly Rate | F8: GPR (ann.) | G8: Avg LOC Rev/Bed | H8: Total Revenue
A9: IL — Independent Living | B9: =COUNTIF($C$211:$C$610,"IL") | C9: =COUNTIFS($C$211:$C$610,"IL",$D$211:$D$610,"Occupied")+COUNTIFS($C$211:$C$610,"IL",$D$211:$D$610,"Notice") | D9: =IFERROR(C9/B9,0) | E9: =IFERROR(AVERAGEIFS($K$211:$K$610,$C$211:$C$610,"IL",$K$211:$K$610,">0"),0) | F9: =B9*AVERAGEIFS($H$211:$H$610,$C$211:$C$610,"IL",$H$211:$H$610,">0")*12 | G9: =IFERROR(SUMIFS($J$211:$J$610,$C$211:$C$610,"IL")/MAX(C9,1),0) | H9: =SUMIFS($K$211:$K$610,$C$211:$C$610,"IL")*12
A10: AL — Assisted Living | B10: =COUNTIF($C$211:$C$610,"AL") | C10: =COUNTIFS($C$211:$C$610,"AL",$D$211:$D$610,"Occupied")+COUNTIFS($C$211:$C$610,"AL",$D$211:$D$610,"Notice") | D10: =IFERROR(C10/B10,0) | E10: =IFERROR(AVERAGEIFS($K$211:$K$610,$C$211:$C$610,"AL",$K$211:$K$610,">0"),0) | F10: =B10*AVERAGEIFS($H$211:$H$610,$C$211:$C$610,"AL",$H$211:$H$610,">0")*12 | G10: =IFERROR(SUMIFS($J$211:$J$610,$C$211:$C$610,"AL")/MAX(C10,1),0) | H10: =SUMIFS($K$211:$K$610,$C$211:$C$610,"AL")*12
A11: MC — Memory Care | B11: =COUNTIF($C$211:$C$610,"MC") | C11: =COUNTIFS($C$211:$C$610,"MC",$D$211:$D$610,"Occupied")+COUNTIFS($C$211:$C$610,"MC",$D$211:$D$610,"Notice") | D11: =IFERROR(C11/B11,0) | E11: =IFERROR(AVERAGEIFS($K$211:$K$610,$C$211:$C$610,"MC",$K$211:$K$610,">0"),0) | F11: =B11*AVERAGEIFS($H$211:$H$610,$C$211:$C$610,"MC",$H$211:$H$610,">0")*12 | G11: =IFERROR(SUMIFS($J$211:$J$610,$C$211:$C$610,"MC")/MAX(C11,1),0) | H11: =SUMIFS($K$211:$K$610,$C$211:$C$610,"MC")*12
A12: TOTAL | B12: =SUM(B9:B11) | C12: =SUM(C9:C11) | D12: =IFERROR(C12/B12,0) | E12: =IFERROR(SUMIFS($K$211:$K$610,$K$211:$K$610,">0")/COUNTIFS($K$211:$K$610,">0"),0) | F12: =SUM(F9:F11) | G12: =IFERROR(SUM(J211:J610)/MAX(C12,1),0) | H12: =SUM(H9:H11)
A14: D. RESIDENT STATUS TAXONOMY — Where everyone stands
A15: Status Bucket | B15: # Beds | C15: % of Total | D15: Sched Charges ($/mo) | E15: Avg Rate/Bed | F15: AR Balance
A16: Occupied — Current (paying, no balance) | B16: =COUNTIFS($D$211:$D$610,"Occupied",$L$211:$L$610,"<=0")+COUNTIFS($D$211:$D$610,"Occupied",$L$211:$L$610,"") | C16: =IFERROR(B16/$B$24,0) | D16: =IFERROR(SUMIFS($K$211:$K$610,$D$211:$D$610,"Occupied",$L$211:$L$610,"<=0")+SUMIFS($K$211:$K$610,$D$211:$D$610,"Occupied",$L$211:$L$610,""),0) | E16: =IFERROR(D16/MAX(B16,1),0) | F16: 0
A17: Occupied — Delinquent (30+ days past due) | B17: =COUNTIFS($D$211:$D$610,"Occupied",$L$211:$L$610,">0")+COUNTIFS($D$211:$D$610,"Notice",$L$211:$L$610,">0") | C17: =IFERROR(B17/$B$24,0) | D17: =SUMIFS($K$211:$K$610,$D$211:$D$610,"Occupied",$L$211:$L$610,">0")+SUMIFS($K$211:$K$610,$D$211:$D$610,"Notice",$L$211:$L$610,">0") | E17: =IFERROR(D17/MAX(B17,1),0) | F17: =SUMIFS($L$211:$L$610,$D$211:$D$610,"Occupied",$L$211:$L$610,">0")+SUMIFS($L$211:$L$610,$D$211:$D$610,"Notice",$L$211:$L$610,">0")
A18: Occupied — On Notice (30-day notice given) | B18: =COUNTIF($D$211:$D$610,"Notice") | C18: =IFERROR(B18/$B$24,0) | D18: =SUMIFS($K$211:$K$610,$D$211:$D$610,"Notice") | E18: =IFERROR(D18/MAX(B18,1),0) | F18: =SUMIFS($L$211:$L$610,$D$211:$D$610,"Notice")
A19: Occupied — Respite / Short-term | B19: =COUNTIF($D$211:$D$610,"Respite") | C19: =IFERROR(B19/$B$24,0) | D19: =SUMIFS($K$211:$K$610,$D$211:$D$610,"Respite") | E19: =IFERROR(D19/MAX(B19,1),0) | F19: =SUMIFS($L$211:$L$610,$D$211:$D$610,"Respite")
A20: Occupied — Hospice | B20: =COUNTIF($D$211:$D$610,"Hospice") | C20: =IFERROR(B20/$B$24,0) | D20: =SUMIFS($K$211:$K$610,$D$211:$D$610,"Hospice") | E20: =IFERROR(D20/MAX(B20,1),0) | F20: =SUMIFS($L$211:$L$610,$D$211:$D$610,"Hospice")
A21: Vacant — Turned (ready) | B21: =COUNTIFS($D$211:$D$610,"Vacant",$G$211:$G$610,"<>") | C21: =IFERROR(B21/$B$24,0) | D21: 0 | E21: 0 | F21: 0
A22: Vacant — Not Turned | B22: =COUNTIFS($D$211:$D$610,"Vacant",$G$211:$G$610,"") | C22: =IFERROR(B22/$B$24,0) | D22: 0 | E22: 0 | F22: 0
A23: Reserved / Pre-Admitted (signed, not in) | B23: =COUNTIF($D$211:$D$610,"Reserved")+COUNTIFS($D$211:$D$610,"Vacant",$F$211:$F$610,">"&TODAY()) | C23: =IFERROR(B23/$B$24,0) | D23: =SUMIFS($K$211:$K$610,$D$211:$D$610,"Reserved") | E23: =IFERROR(D23/MAX(B23,1),0) | F23: 0
A24: TOTAL | B24: =COUNTA($B$211:$B$610) | C24: =SUM(C16:C23) | D24: =SUM(D16:D23) | E24: =IFERROR(D24/MAX(B24,1),0) | F24: =SUM(F16:F23)
A25: Tie-out: Occ + Vacant + Reserved = Licensed Beds | Occ Mkt + Vac Loss should tie to Section E GPR
A27: E. GPR RECONCILIATION — Three views of potential revenue
A28: Metric | B28: Annual Amount | C28: Per Bed/Mo | D28: Notes
A29: Market GPR (all licensed beds × market rate × 12) | B29: =SUM(H211:H610)*12 | C29: =IFERROR(B29/12/MAX(B12,1),0) | D29: Max revenue at 100% occupancy
A30: Scheduled GPR (occupied × sched charges × 12) | B30: {=SUMPRODUCT((($D$211:$D$610="Occupied")+($D$211:$D$610="Notice"))*$K$211:$K$610)*12} | C30: =IFERROR(B30/12/MAX(C12,1),0) | D30: Contracted charges on occupied beds
A31: Loss to Lease (achievable rate − in-place scheduled, occupied) | B31: {=(SUMPRODUCT((($C$211:$C$610="IL")*(($D$211:$D$610="Occupied")+($D$211:$D$610="Notice")))*(_xlfn.MAXIFS($K$211:$K$610,$C$211:$C$610,"IL",$D$211:$D$610,"Occupied")-$K$211:$K$610))+SUMPRODUCT((($C$211:$C$610="AL")*(($D$211:$D$610="Occupied")+($D$211:$D$610="Notice")))*(_xlfn.MAXIFS($K$211:$K$610,$C$211:$C$610,"AL",$D$211:$D$610,"Occupied")-$K$211:$K$610))+SUMPRODUCT((($C$211:$C$610="MC")*(($D$211:$D$610="Occupied")+($D$211:$D$610="Notice")))*(_xlfn.MAXIFS($K$211:$K$610,$C$211:$C$610,"MC",$D$211:$D$610,"Occupied")-$K$211:$K$610)))*12} | C31: =IFERROR(B31/12/MAX(C12,1),0) | D31: Achievable = max scheduled rate within same care level (peer ceiling per CL)
A32: Loss to Lease % | B32: =IFERROR(B31/B30,0) | D32: LTL as % of scheduled GPR
A33: Vacancy Loss (vacant beds × market rate × 12) | B33: =SUMIFS($H$211:$H$610,$D$211:$D$610,"Vacant")*12 | C33: =IFERROR(B33/12/MAX(COUNTIF($D$211:$D$610,"Vacant"),1),0) | D33: Lost revenue from empty beds
A34: Bad Debt Risk (delinquent + on-notice × sched × 12) | B34: =F17*12+F18*12 | C34: =IFERROR(B34/12/MAX(B17+B18,1),0) | D34: Annualized at-risk revenue
A35: LOC / Care Services Revenue (Analyzer UW Output) | B35: =SUM(J211:J610)*12 | C35: =IFERROR(B35/12/MAX(C12,1),0) | D35: Add-on care charges — source from Analyzer
A36: Economic GPR (Market − LTL − Vac − Bad Debt + LOC) | B36: =B29-B31-B33-B34+B35 | C36: =IFERROR(B36/12/MAX(B12,1),0) | D36: Realistic collected revenue estimate
A37: Economic Occupancy % (Econ GPR / Market GPR) | B37: =IFERROR(B36/B29,0) | D37: Compare to physical occupancy above
A38: Current RR GPR — Occupied Scheduled (point-in-time) | B38: {=SUMPRODUCT((($D$211:$D$610="Occupied")+($D$211:$D$610="Notice"))*$K$211:$K$610)*12} | C38: =IFERROR(B38/12/MAX(C12,1),0) | D38: Scheduled rent × occupied beds × 12
A39: Market vs Actual Collected (operator posted rate − actual charges, occupied) | B39: {=SUMPRODUCT((($D$211:$D$610="Occupied")+($D$211:$D$610="Notice"))*($H$211:$H$610-$I$211:$I$610))*12} | C39: =IFERROR(B39/12/MAX(C12,1),0) | D39: Negative = collecting MORE than posted market (over-billing or care fees in I). Positive = collecting LESS than posted market (concessions / discounts in actuals).
A40: F. LENGTH OF STAY COHORT — How long residents have been here
A41: Tenure | B41: # Residents | C41: % Occupied | D41: Avg Sched Rate | E41: Avg Market Rate | F41: LTL/mo/bed | G41: Read
A42: 0–6 months | B42: {=SUMPRODUCT((($D$211:$D$610="Occupied")+($D$211:$D$610="Notice"))*($F$211:$F$610>=TODAY()-180)*($F$211:$F$610<>""))} | C42: =IFERROR(B42/MAX($C$12,1),0) | D42: {=IFERROR(SUMPRODUCT((($D$211:$D$610="Occupied")+($D$211:$D$610="Notice"))*($F$211:$F$610>=TODAY()-180)*($F$211:$F$610<>"")*$K$211:$K$610)/MAX(B42,1),0)} | E42: {=IFERROR(SUMPRODUCT((($D$211:$D$610="Occupied")+($D$211:$D$610="Notice"))*($F$211:$F$610>=TODAY()-180)*($F$211:$F$610<>"")*$H$211:$H$610)/MAX(B42,1),0)} | F42: =IFERROR(E42-D42,0) | G42: Recent admissions — high care needs assessment period
A43: 6–12 months | B43: {=SUMPRODUCT((($D$211:$D$610="Occupied")+($D$211:$D$610="Notice"))*($F$211:$F$610>=TODAY()-365)*($F$211:$F$610<TODAY()-180)*($F$211:$F$610<>""))} | C43: =IFERROR(B43/MAX($C$12,1),0) | D43: {=IFERROR(SUMPRODUCT((($D$211:$D$610="Occupied")+($D$211:$D$610="Notice"))*($F$211:$F$610>=TODAY()-365)*($F$211:$F$610<TODAY()-180)*($F$211:$F$610<>"")*$K$211:$K$610)/MAX(B43,1),0)} | E43: {=IFERROR(SUMPRODUCT((($D$211:$D$610="Occupied")+($D$211:$D$610="Notice"))*($F$211:$F$610>=TODAY()-365)*($F$211:$F$610<TODAY()-180)*($F$211:$F$610<>"")*$H$211:$H$610)/MAX(B43,1),0)} | F43: =IFERROR(E43-D43,0) | G43: Stabilizing
...

Sheet Rental Comps
A1: RENTAL COMPS — BY CARE LEVEL | P1: UNIT MIX & TARGET RENT ANALYSIS — Reference only. Blue = input · Green = formula · Target defaults to comp avg for care level.
A2: Enter up to 12 comps per care level. Summary auto-calculates averages and rate position vs. subject property. | N2: Rent Basis: | O2: Max | P2: Unit Type | Q2: Sq Ft | R2: # Units | S2: Current Rent | V2: Target Rent | AA2: Notes
A3: SUBJECT PROPERTY → | E3: ='Prop Info'!B2 | F3: =Scenarios!F38 | G3: =Scenarios!F38 | H3: =Scenarios!F38 | P3: Type | Q3: Sq Ft | R3: # Units | S3: Avg / mo | T3: Total / mo | U3: $ / Sq Ft | V3: Target / mo | W3: Delta % | X3: Delta $ | Y3: Total / mo | Z3: $ / Sq Ft | AA3: Notes
P4: IL — INDEPENDENT LIVING
A5: INDEPENDENT LIVING (IL) COMPS | P5: IL Studio | Q5: =IFERROR(AVERAGEIFS('Rent Roll Analysis'!T:T,'Rent Roll Analysis'!Y:Y,"IL|Studio",'Rent Roll Analysis'!T:T,">0"),0) | R5: =COUNTIF('Rent Roll Analysis'!Y:Y,"IL|Studio") | S5: =IFERROR(IF($O$2="Max",_xlfn.MAXIFS('Rent Roll Analysis'!I:I,'Rent Roll Analysis'!X:X,"IL|Studio"),AVERAGEIFS('Rent Roll Analysis'!I:I,'Rent Roll Analysis'!X:X,"IL|Studio",'Rent Roll Analysis'!I:I,">0")),0) | T5: =IFERROR(S5*R5,0) | U5: =IFERROR(S5/Q5,0) | V5: =IFERROR(H19,0) | W5: =IFERROR(V5/S5-1,"") | X5: =IFERROR(V5-S5,"") | Y5: =IFERROR(V5*R5,0) | Z5: =IFERROR(V5/Q5,0)
A6: Distance (mi) | B6: Vintage | C6: Units | D6: Type | E6: Property Name | F6: Base Rent/mo | G6: Care Fee/mo | H6: All-In Rate | I6: Occupancy % | J6: Sq Ft | K6: $/Sq Ft | L6: Notes | P6: IL 1-Bed | Q6: =IFERROR(AVERAGEIFS('Rent Roll Analysis'!T:T,'Rent Roll Analysis'!Y:Y,"IL|1 Bedroom",'Rent Roll Analysis'!T:T,">0"),0) | R6: =COUNTIF('Rent Roll Analysis'!Y:Y,"IL|1 Bedroom") | S6: =IFERROR(IF($O$2="Max",_xlfn.MAXIFS('Rent Roll Analysis'!I:I,'Rent Roll Analysis'!X:X,"IL|1 Bedroom"),AVERAGEIFS('Rent Roll Analysis'!I:I,'Rent Roll Analysis'!X:X,"IL|1 Bedroom",'Rent Roll Analysis'!I:I,">0")),0) | T6: =IFERROR(S6*R6,0) | U6: =IFERROR(S6/Q6,0) | V6: =IFERROR(H19,0) | W6: =IFERROR(V6/S6-1,"") | X6: =IFERROR(V6-S6,"") | Y6: =IFERROR(V6*R6,0) | Z6: =IFERROR(V6/Q6,0)
H7: =IFERROR(F7+G7,0) | K7: =IFERROR(F7/J7,0) | P7: IL 2-Bed | Q7: =IFERROR(AVERAGEIFS('Rent Roll Analysis'!T:T,'Rent Roll Analysis'!Y:Y,"IL|2 Bedroom",'Rent Roll Analysis'!T:T,">0"),0) | R7: =COUNTIF('Rent Roll Analysis'!Y:Y,"IL|2 Bedroom") | S7: =IFERROR(IF($O$2="Max",_xlfn.MAXIFS('Rent Roll Analysis'!I:I,'Rent Roll Analysis'!X:X,"IL|2 Bedroom"),AVERAGEIFS('Rent Roll Analysis'!I:I,'Rent Roll Analysis'!X:X,"IL|2 Bedroom",'Rent Roll Analysis'!I:I,">0")),0) | T7: =IFERROR(S7*R7,0) | U7: =IFERROR(S7/Q7,0) | V7: =IFERROR(H19,0) | W7: =IFERROR(V7/S7-1,"") | X7: =IFERROR(V7-S7,"") | Y7: =IFERROR(V7*R7,0) | Z7: =IFERROR(V7/Q7,0)
H8: =IFERROR(F8+G8,0) | K8: =IFERROR(F8/J8,0) | P8: AL — ASSISTED LIVING
H9: =IFERROR(F9+G9,0) | K9: =IFERROR(F9/J9,0) | P9: AL Studio (Pvt) | Q9: =IFERROR(AVERAGEIFS('Rent Roll Analysis'!T:T,'Rent Roll Analysis'!Y:Y,"AL|Studio",'Rent Roll Analysis'!T:T,">0"),0) | R9: =COUNTIF('Rent Roll Analysis'!Y:Y,"AL|Studio") | S9: =IFERROR(IF($O$2="Max",_xlfn.MAXIFS('Rent Roll Analysis'!I:I,'Rent Roll Analysis'!X:X,"AL|Studio"),AVERAGEIFS('Rent Roll Analysis'!I:I,'Rent Roll Analysis'!X:X,"AL|Studio",'Rent Roll Analysis'!I:I,">0")),0) | T9: =IFERROR(S9*R9,0) | U9: =IFERROR(S9/Q9,0) | V9: =IFERROR(H36,0) | W9: =IFERROR(V9/S9-1,"") | X9: =IFERROR(V9-S9,"") | Y9: =IFERROR(V9*R9,0) | Z9: =IFERROR(V9/Q9,0)
H10: =IFERROR(F10+G10,0) | K10: =IFERROR(F10/J10,0) | P10: AL Semi-Private | Q10: =IFERROR(AVERAGEIFS('Rent Roll Analysis'!T:T,'Rent Roll Analysis'!Y:Y,"AL|Semi-Private",'Rent Roll Analysis'!T:T,">0"),0) | R10: =COUNTIF('Rent Roll Analysis'!Y:Y,"AL|Semi-Private") | S10: =IFERROR(IF($O$2="Max",_xlfn.MAXIFS('Rent Roll Analysis'!I:I,'Rent Roll Analysis'!X:X,"AL|Semi-Private"),AVERAGEIFS('Rent Roll Analysis'!I:I,'Rent Roll Analysis'!X:X,"AL|Semi-Private",'Rent Roll Analysis'!I:I,">0")),0) | T10: =IFERROR(S10*R10,0) | U10: =IFERROR(S10/Q10,0) | V10: =IFERROR(H36,0) | W10: =IFERROR(V10/S10-1,"") | X10: =IFERROR(V10-S10,"") | Y10: =IFERROR(V10*R10,0) | Z10: =IFERROR(V10/Q10,0)
H11: =IFERROR(F11+G11,0) | K11: =IFERROR(F11/J11,0) | P11: AL 1-Bed | Q11: =IFERROR(AVERAGEIFS('Rent Roll Analysis'!T:T,'Rent Roll Analysis'!Y:Y,"AL|1 Bedroom",'Rent Roll Analysis'!T:T,">0"),0) | R11: =COUNTIF('Rent Roll Analysis'!Y:Y,"AL|1 Bedroom") | S11: =IFERROR(IF($O$2="Max",_xlfn.MAXIFS('Rent Roll Analysis'!I:I,'Rent Roll Analysis'!X:X,"AL|1 Bedroom"),AVERAGEIFS('Rent Roll Analysis'!I:I,'Rent Roll Analysis'!X:X,"AL|1 Bedroom",'Rent Roll Analysis'!I:I,">0")),0) | T11: =IFERROR(S11*R11,0) | U11: =IFERROR(S11/Q11,0) | V11: =IFERROR(H36,0) | W11: =IFERROR(V11/S11-1,"") | X11: =IFERROR(V11-S11,"") | Y11: =IFERROR(V11*R11,0) | Z11: =IFERROR(V11/Q11,0)
H12: =IFERROR(F12+G12,0) | K12: =IFERROR(F12/J12,0) | P12: MC — MEMORY CARE
H13: =IFERROR(F13+G13,0) | K13: =IFERROR(F13/J13,0) | P13: MC Studio (Pvt) | Q13: =IFERROR(AVERAGEIFS('Rent Roll Analysis'!T:T,'Rent Roll Analysis'!Y:Y,"MC|Studio",'Rent Roll Analysis'!T:T,">0"),0) | R13: =COUNTIF('Rent Roll Analysis'!Y:Y,"MC|Studio") | S13: =IFERROR(IF($O$2="Max",_xlfn.MAXIFS('Rent Roll Analysis'!I:I,'Rent Roll Analysis'!X:X,"MC|Studio"),AVERAGEIFS('Rent Roll Analysis'!I:I,'Rent Roll Analysis'!X:X,"MC|Studio",'Rent Roll Analysis'!I:I,">0")),0) | T13: =IFERROR(S13*R13,0) | U13: =IFERROR(S13/Q13,0) | V13: =IFERROR(H53,0) | W13: =IFERROR(V13/S13-1,"") | X13: =IFERROR(V13-S13,"") | Y13: =IFERROR(V13*R13,0) | Z13: =IFERROR(V13/Q13,0)
H14: =IFERROR(F14+G14,0) | K14: =IFERROR(F14/J14,0) | P14: MC Semi-Private | Q14: =IFERROR(AVERAGEIFS('Rent Roll Analysis'!T:T,'Rent Roll Analysis'!Y:Y,"MC|Semi-Private",'Rent Roll Analysis'!T:T,">0"),0) | R14: =COUNTIF('Rent Roll Analysis'!Y:Y,"MC|Semi-Private") | S14: =IFERROR(IF($O$2="Max",_xlfn.MAXIFS('Rent Roll Analysis'!I:I,'Rent Roll Analysis'!X:X,"MC|Semi-Private"),AVERAGEIFS('Rent Roll Analysis'!I:I,'Rent Roll Analysis'!X:X,"MC|Semi-Private",'Rent Roll Analysis'!I:I,">0")),0) | T14: =IFERROR(S14*R14,0) | U14: =IFERROR(S14/Q14,0) | V14: =IFERROR(H53,0) | W14: =IFERROR(V14/S14-1,"") | X14: =IFERROR(V14-S14,"") | Y14: =IFERROR(V14*R14,0) | Z14: =IFERROR(V14/Q14,0)
H15: =IFERROR(F15+G15,0) | K15: =IFERROR(F15/J15,0) | P15: Other | Q15: =IFERROR(AVERAGEIFS('Rent Roll Analysis'!T:T,'Rent Roll Analysis'!Y:Y,"<>",'Rent Roll Analysis'!Y:Y,"<>IL|Studio",'Rent Roll Analysis'!Y:Y,"<>IL|1 Bedroom",'Rent Roll Analysis'!Y:Y,"<>IL|2 Bedroom",'Rent Roll Analysis'!Y:Y,"<>AL|Studio",'Rent Roll Analysis'!Y:Y,"<>AL|Semi-Private",'Rent Roll Analysis'!Y:Y,"<>AL|1 Bedroom",'Rent Roll Analysis'!Y:Y,"<>MC|Studio",'Rent Roll Analysis'!Y:Y,"<>MC|Semi-Private",'Rent Roll Analysis'!T:T,">0"),0) | R15: =COUNTIF('Rent Roll Analysis'!Y:Y,"?*")-R5-R6-R7-R9-R10-R11-R13-R14 | S15: =IFERROR(IF($O$2="Max",_xlfn.MAXIFS('Rent Roll Analysis'!I:I,'Rent Roll Analysis'!X:X,"<>",'Rent Roll Analysis'!X:X,"<>IL|Studio",'Rent Roll Analysis'!X:X,"<>IL|1 Bedroom",'Rent Roll Analysis'!X:X,"<>IL|2 Bedroom",'Rent Roll Analysis'!X:X,"<>AL|Studio",'Rent Roll Analysis'!X:X,"<>AL|Semi-Private",'Rent Roll Analysis'!X:X,"<>AL|1 Bedroom",'Rent Roll Analysis'!X:X,"<>MC|Studio",'Rent Roll Analysis'!X:X,"<>MC|Semi-Private"),AVERAGEIFS('Rent Roll Analysis'!I:I,'Rent Roll Analysis'!X:X,"<>",'Rent Roll Analysis'!X:X,"<>IL|Studio",'Rent Roll Analysis'!X:X,"<>IL|1 Bedroom",'Rent Roll Analysis'!X:X,"<>IL|2 Bedroom",'Rent Roll Analysis'!X:X,"<>AL|Studio",'Rent Roll Analysis'!X:X,"<>AL|Semi-Private",'Rent Roll Analysis'!X:X,"<>AL|1 Bedroom",'Rent Roll Analysis'!X:X,"<>MC|Studio",'Rent Roll Analysis'!X:X,"<>MC|Semi-Private",'Rent Roll Analysis'!I:I,">0")),0) | T15: =IFERROR(S15*R15,0) | U15: =IFERROR(S15/Q15,0) | V15: =IFERROR(AVERAGE(H19,H36,H53),0) | W15: =IFERROR(V15/S15-1,"") | X15: =IFERROR(V15-S15,"") | Y15: =IFERROR(V15*R15,0) | Z15: =IFERROR(V15/Q15,0)
H16: =IFERROR(F16+G16,0) | K16: =IFERROR(F16/J16,0) | P16: Total / Average | Q16: =IFERROR((Q5*R5+Q6*R6+Q7*R7+Q9*R9+Q10*R10+Q11*R11+Q13*R13+Q14*R14+Q15*R15)/(R5+R6+R7+R9+R10+R11+R13+R14+R15),0) | R16: =IFERROR(R5+R6+R7+R9+R10+R11+R13+R14+R15,0) | S16: =IFERROR((R5*S5+R6*S6+R7*S7+R9*S9+R10*S10+R11*S11+R13*S13+R14*S14+R15*S15)/(R5+R6+R7+R9+R10+R11+R13+R14+R15),0) | T16: =IFERROR(T5+T6+T7+T9+T10+T11+T13+T14+T15,0) | U16: =IFERROR(T16/Q16,0) | V16: =IFERROR((R5*V5+R6*V6+R7*V7+R9*V9+R10*V10+R11*V11+R13*V13+R14*V14+R15*V15)/(R5+R6+R7+R9+R10+R11+R13+R14+R15),0) | W16: =IFERROR(V16/S16-1,"") | X16: =IFERROR(V16-S16,"") | Y16: =IFERROR(Y5+Y6+Y7+Y9+Y10+Y11+Y13+Y14+Y15,0) | Z16: =IFERROR(Y16/Q16,0)
H17: =IFERROR(F17+G17,0) | K17: =IFERROR(F17/J17,0) | P17: VALUE-ADD UNITS (manual inputs — negative R = removed, positive R = added)
H18: =IFERROR(F18+G18,0) | K18: =IFERROR(F18/J18,0) | P18: IL — Value-Add
A19: AVG — IN | F19: =IFERROR(AVERAGEIF(F7:F18,">"&0),0) | G19: =IFERROR(AVERAGEIF(G7:G18,">"&0),0) | H19: =IFERROR(AVERAGEIF(H7:H18,">"&0),0) | I19: =IFERROR(AVERAGEIF(I7:I18,">"&0),0) | P19: Add row 1 (label me) | T19: =IFERROR(S19*R19,0) | U19: =IFERROR(S19/Q19,0) | V19: =IFERROR(H19,0) | W19: =IFERROR(V19/S19-1,"") | X19: =IFERROR(V19-S19,"") | Y19: =IFERROR(V19*R19,0) | Z19: =IFERROR(V19/Q19,0)
A20: Subj. vs. Avg IN Rent | F20: =Scenarios!F38-F19 | P20: Add row 2 (label me) | T20: =IFERROR(S20*R20,0) | U20: =IFERROR(S20/Q20,0) | V20: =IFERROR(H19,0) | W20: =IFERROR(V20/S20-1,"") | X20: =IFERROR(V20-S20,"") | Y20: =IFERROR(V20*R20,0) | Z20: =IFERROR(V20/Q20,0)
P21: AL — Value-Add
A22: ASSISTED LIVING (AL) COMPS | P22: Add row 1 (label me) | T22: =IFERROR(S22*R22,0) | U22: =IFERROR(S22/Q22,0) | V22: =IFERROR(H36,0) | W22: =IFERROR(V22/S22-1,"") | X22: =IFERROR(V22-S22,"") | Y22: =IFERROR(V22*R22,0) | Z22: =IFERROR(V22/Q22,0)
A23: Distance (mi) | B23: Vintage | C23: Units | D23: Type | E23: Property Name | F23: Base Rent/mo | G23: Care Fee/mo | H23: All-In Rate | I23: Occupancy % | J23: Sq Ft | K23: $/Sq Ft | L23: Notes | P23: Add row 2 (label me) | T23: =IFERROR(S23*R23,0) | U23: =IFERROR(S23/Q23,0) | V23: =IFERROR(H36,0) | W23: =IFERROR(V23/S23-1,"") | X23: =IFERROR(V23-S23,"") | Y23: =IFERROR(V23*R23,0) | Z23: =IFERROR(V23/Q23,0)
H24: =IFERROR(F24+G24,0) | K24: =IFERROR(F24/J24,0) | P24: MC — Value-Add
H25: =IFERROR(F25+G25,0) | K25: =IFERROR(F25/J25,0) | P25: Add row 1 (label me) | T25: =IFERROR(S25*R25,0) | U25: =IFERROR(S25/Q25,0) | V25: =IFERROR(H53,0) | W25: =IFERROR(V25/S25-1,"") | X25: =IFERROR(V25-S25,"") | Y25: =IFERROR(V25*R25,0) | Z25: =IFERROR(V25/Q25,0)
H26: =IFERROR(F26+G26,0) | K26: =IFERROR(F26/J26,0) | P26: Subtotal — Value-Add | Q26: {=IFERROR(SUMPRODUCT(Q19:Q25,ABS(R19:R25))/SUMPRODUCT(ABS(R19:R25)),0)} | R26: =SUM(R19:R25) | S26: {=IFERROR(SUMPRODUCT(S19:S25,ABS(R19:R25))/SUMPRODUCT(ABS(R19:R25)),0)} | T26: =SUM(T19:T25) | U26: =IFERROR(T26/(Q26*R26),0) | V26: {=IFERROR(SUMPRODUCT(V19:V25,ABS(R19:R25))/SUMPRODUCT(ABS(R19:R25)),0)} | W26: =IFERROR(V26/S26-1,"") | X26: =IFERROR(V26-S26,"") | Y26: =SUM(Y19:Y25) | Z26: =IFERROR(Y26/(Q26*R26),0)
H27: =IFERROR(F27+G27,0) | K27: =IFERROR(F27/J27,0) | P27: TOTAL — STABILIZED (In-Place + Value-Add) | Q27: =IFERROR((Q16*R16+Q26*R26)/(R16+R26),0) | R27: =R16+R26 | S27: =IFERROR((S16*R16+S26*R26)/(R16+R26),0) | T27: =T16+T26 | U27: =IFERROR(T27/(Q27*R27),0) | V27: =IFERROR((V16*R16+V26*R26)/(R16+R26),0) | W27: =IFERROR(V27/S27-1,"") | X27: =IFERROR(V27-S27,"") | Y27: =Y16+Y26 | Z27: =IFERROR(Y27/(Q27*R27),0)
H28: =IFERROR(F28+G28,0) | K28: =IFERROR(F28/J28,0)
H29: =IFERROR(F29+G29,0) | K29: =IFERROR(F29/J29,0) | P29: SUMMARY | Q29: Toggle Avg/Max at O2 to flex Current rents
H30: =IFERROR(F30+G30,0) | K30: =IFERROR(F30/J30,0) | S30: Current (In-Place) | V30: Target (Comp Repriced) | Y30: Projected (Stabilized) | AB30: T-12 Actual
H31: =IFERROR(F31+G31,0) | K31: =IFERROR(F31/J31,0) | P31: Gross Potential Revenue / mo | S31: =IFERROR(T16,0) | V31: =IFERROR(Y16,0) | Y31: =IFERROR(T27,0) | AA31: Sum of In-Place rows T5:T15 (Avg/Max toggle drives this) | AB31: =IFERROR('T-12 Analysis'!N58/12,0) | AC31: T-12 historical GPR (12-mo billed rent before vacancy/LtL)
H32: =IFERROR(F32+G32,0) | K32: =IFERROR(F32/J32,0) | P32: Gross Potential Revenue / yr (annualized) | S32: =IFERROR(S31*12,0) | V32: =IFERROR(V31*12,0) | Y32: =IFERROR(Y31*12,0) | AA32: row 31 x 12 | AB32: =IFERROR('T-12 Analysis'!N58,0) | AC32: From T-12!N58 Gross Potential Rent
H33: =IFERROR(F33+G33,0) | K33: =IFERROR(F33/J33,0) | P33: Implied Avg Rate / Bed / mo | S33: =IFERROR(S31/R16,0) | V33: =IFERROR(V31/R16,0) | Y33: =IFERROR(Y31/R27,0) | AA33: row 31 / R16 (in-place); Projected uses R27 (stabilized) | AB33: =IFERROR('T-12 Analysis'!N58/12/'Prop Info'!B15,0) | AC33: divided by 12 / licensed beds
H34: =IFERROR(F34+G34,0) | K34: =IFERROR(F34/J34,0) | P34: Gap vs Current ($/mo) | S34: - | V34: =IFERROR(V31-S31,"") | Y34: =IFERROR(Y31-S31,"") | AA34: Uplift opportunity vs in-place | AB34: =IFERROR(AB31-S31,"") | AC34: Positive = current rent roll below historical; negative = above
H35: =IFERROR(F35+G35,0) | K35: =IFERROR(F35/J35,0)
A36: AVG — AS | F36: =IFERROR(AVERAGEIF(F24:F35,">"&0),0) | G36: =IFERROR(AVERAGEIF(G24:G35,">"&0),0) | H36: =IFERROR(AVERAGEIF(H24:H35,">"&0),0) | I36: =IFERROR(AVERAGEIF(I24:I35,">"&0),0)
A37: Subj. vs. Avg AS Rent | F37: =Scenarios!F38-F36
A39: MEMORY CARE (MC) COMPS
A40: Distance (mi) | B40: Vintage | C40: Units | D40: Type | E40: Property Name | F40: Base Rent/mo | G40: Care Fee/mo | H40: All-In Rate | I40: Occupancy % | J40: Sq Ft | K40: $/Sq Ft | L40: Notes
H41: =IFERROR(F41+G41,0) | K41: =IFERROR(F41/J41,0)
...

Sheet Capex
A1: CAPITAL EXPENDITURE BUDGET — DETAILED BREAKDOWN
A2: Classify each item as Value-Add (VA) or Maintenance (M). VA flows into LTC; Maintenance is operating reserve.
A3: Item | B3: Qty | C3: Unit Cost | D3: Total Cost | E3: VA or M? | F3: Funded By | G3: Notes
A4: EXTERIOR & GROUNDS
A5: Roof Replacement | D5: =B5*C5
A6: Parking Lot Resurface | D6: =B6*C6
A7: Landscaping / Curb Appeal | D7: =B7*C7
A8: Signage | D8: =B8*C8
A9: Exterior Paint / Siding | D9: =B9*C9
A10: Lighting (exterior) | D10: =B10*C10
A11: Subtotal — EXTERIOR & GROUNDS | D11: =SUM(D5:D10)
A13: COMMON AREAS
A14: Lobby / Reception Renovation | B14: 1 | D14: =B14*C14 | E14: M | G14: Placeholders
A15: Dining Room Renovation | D15: =B15*C15 | G15: Placeholders
A16: Activity Room Renovation | D16: =B16*C16 | G16: Placeholders
A17: Hallway Flooring | D17: =B17*C17
A18: Common Area Furniture (FF&E) | D18: =B18*C18 | G18: placehodlers
A19: Elevator Modernization | D19: =B19*C19
A20: Subtotal — COMMON AREAS | D20: =SUM(D14:D19)
A22: UNIT INTERIORS
A23: Unit Flooring (per unit) | D23: =B23*C23
A24: Unit Paint (per unit) | D24: =B24*C24
A25: Bathroom Grab Bars / ADA (per unit) | D25: =B25*C25
A26: Kitchen Appliances (per unit) | D26: =B26*C26
A27: Unit Door / Hardware Upgrade | D27: =B27*C27
A28: Window Replacement (per unit) | D28: =B28*C28
A29: Subtotal — UNIT INTERIORS | D29: =SUM(D23:D28)
A31: MEDICAL & SAFETY
A32: Nurse Call System Upgrade | D32: =B32*C32
A33: Fire Suppression / Sprinklers | D33: =B33*C33
A34: HVAC Units | D34: =B34*C34
A35: Emergency Generator | D35: =B35*C35
A36: Security Camera System | D36: =B36*C36
A37: Medication Management System | D37: =B37*C37
A38: Subtotal — MEDICAL & SAFETY | D38: =SUM(D32:D37)
A40: TECHNOLOGY & SYSTEMS
A41: EHR / Resident Mgmt Software | D41: =B41*C41
A42: WiFi Infrastructure | D42: =B42*C42
A43: Telephone / Intercom System | D43: =B43*C43
A44: Access Control / Key Card | D44: =B44*C44
...

Sheet Exit Strategy
A1: EXIT STRATEGY — REFINANCE & SALE ANALYSIS
A4: =IF(ISNUMBER(C5),"Refi - Year "&C5,"Refinance (set Refi Year below)") | E4: =IF(ISNUMBER(Scenarios!F129),"Sale - Year "&Scenarios!F129,"Sale (set Exit Year in Scenarios)")
A5: Refi Year (or NA) | C5: 3 | E5: Net Operating Income | G5: =IFERROR(INDEX('P&L'!D97:M97,1,Scenarios!F129),0)
A6: Net Operating Income | C6: =IFERROR(IF(ISNUMBER(C5),_xlfn.SINGLE(INDEX('P&L'!D97:M97,1,C5)),0),0) | E6: Cap Rate | G6: =Scenarios!F130
A7: Cap Rate at Re-Finance | C7: 0.06 | E7: Insurance/Tax/Lender Escrows | G7: =SUM('Acquisition Costs'!D35:D36)
A8: Appraised Value | C8: =IFERROR(C6/C7,0) | E8: Operating Reserves remaining | G8: =IFERROR(INDEX('P&L'!D108:M108,1,Scenarios!F129),0) | I8: Remaining capital in account for operating reserves
A9: Re-Finance LTV | C9: 0.75 | E9: Sales Price | G9: =IFERROR(G5/G6,0)
A10: Interest Rate | C10: 0.07 | E10: Sales Cost | F10: 0.03 | G10: =-G9*F10
A11: Term / Amortization (Years) | C11: 30 | E11: Outstanding Loan Balance | G11: =-(IFERROR(INDEX(Loans!J43:S43,1,Scenarios!F129),0))
A12: Re-Finance Loan Amount | C12: =IFERROR(C8*C9,0) | E12: Total Equity | G12: =G9+G10+G11+G7+G8
A13: - Re-Finance Costs | B13: 0.02 | C13: =-C12*B13 | E13: - Return of Member Capital | G13: =Scenarios!F33+Scenarios!F34
A14: - Prepayment Penalty | C14: 0 | E14: - Members Preferred Return Deficiency | G14: =IFERROR(MAX((Waterfall!M39+Waterfall!M41)-(Waterfall!M40+Waterfall!M42),0),0)
A15: - Repay Outstanding Loan Balance | C15: =-(IFERROR(INDEX(Loans!J43:S43,1,C5),0)) | E15: Net Proceeds/Profit from Sale | G15: =G12-G13-G14
A16: Gross Proceeds from Re-Finance | C16: =IFERROR(C12+C13+C14+C15,0) | E16: Principal Reduction | G16: =IFERROR(Scenarios!F135-INDEX(Loans!J43:S43,1,Scenarios!F129),0)
A17: - Return of Member Capital | C17: =IFERROR(MIN(C16,Scenarios!$F$33+Scenarios!$F$34),0) | E17: Appreciation | G17: =G15-G16
A18: Capital Account Balance After Re-Fi | C18: =IFERROR(MAX(Scenarios!$F$33+Scenarios!$F$34-C17,0),0) | E18: Capital Transaction Fee to Mgr | F18: 0.01 | G18: =G9*F18
A19: % of Initial Investment Returned | C19: =IFERROR(C17/(Scenarios!$F$33+Scenarios!$F$34),0) | E19: Net Proceeds/Profit Paid to Members | F19: =1-Scenarios!F36 | G19: =(G15-G18)*(1-Scenarios!F36)
A20: Net Proceeds/Profit from Re-Finance | C20: =IFERROR(C16-C17,0) | E20: Net Proceeds/Profit Paid to Manager | F20: =Scenarios!F36 | G20: =(G15-G18)*Scenarios!F36
