Workbook
Name EGI: Scenarios!$F$50
Name StdBuckets: _StdCOA!$A$4:$A$56
Name Total_Payroll: Payroll!$F$25
Name Units: Scenarios!$B$8

Sheet Cover
A1: =IF('Prop Info'!B4="","MULTIFAMILY — INVESTMENT SUMMARY","MULTIFAMILY — INVESTMENT SUMMARY"&" — "&'Prop Info'!B4) -> MULTIFAMILY — INVESTMENT SUMMARY
A2: Confidential — For Authorized Recipients Only
A4: PROPERTY INFORMATION
A5: Property Name | B5: ='Prop Info'!B4 -> 0
A6: Location | B6: ='Prop Info'!B5 -> 0
A7: Year Built | B7: ='Prop Info'!B9 -> 0
A8: Total Units | B8: =Scenarios!F8 -> 0
A9: Gross Sq Ft | B9: ='Prop Info'!B11 -> 0
A10: Asset Class (A/B/C) | B10: ='Prop Info'!B13 -> 0
A11: Active Scenario | B11: =Scenarios!B2 -> 1. T-12 Actuals
A12: Avg Monthly Rent / Unit | B12: =Scenarios!F39 -> 0
A13: KEY DEAL METRICS
A14: Metric | B14: Value | C14: / Beds | D14: Returns Metric | E14: Value
A15: Purchase Price | B15: =Scenarios!F7 -> 0 | D15: LP IRR | E15: =Waterfall!B66 -> 0
A16: Price Per Unit | B16: =Scenarios!F9 -> 0 | C16: =IFERROR(Scenarios!F7/'Prop Info'!$B$6,0) -> 0 | D16: GP IRR | E16: =Waterfall!E66 -> 0
A17: Total Acquisition Cost | B17: =IFERROR(Scenarios!F17,0) -> 0 | D17: LP Equity Multiple | E17: =Waterfall!B64 -> 0
A18: Loan Amount (Total) | B18: =Scenarios!F117 -> 0 | D18: Y1 Cash-on-Cash | E18: ='P&L'!D68
A19: LTV | B19: =IFERROR(Scenarios!F117/Scenarios!F7,0) -> 0 | D19: Year 5 NOI | E19: ='P&L'!H40
A20: LTC | B20: =IFERROR(Scenarios!F117/Scenarios!F17,0) -> 0 | D20: Exit Year | E20: =Scenarios!F82 -> 0
A21: Equity Required | B21: =Scenarios!F31 -> 0 | D21: Exit Cap Rate | E21: =Waterfall!B6 -> 0
A22: Down Payment % | B22: =Scenarios!F10 -> 0.2 | D22: Gross Sale Price | E22: =Waterfall!B32 -> 0
A23: Entry Cap Rate | B23: =IFERROR('P&L'!D40/Scenarios!F7,0) -> 0 | D23: Net to Equity (Exit) | E23: =Waterfall!B35 -> 0
A24: Stabilized Cap Rate (Y5) | B24: =IFERROR('P&L'!H40/Scenarios!F7,0) -> 0 | D24: Avg Annual Return (LP) | E24: =IFERROR((Waterfall!M54-(Waterfall!B9+Waterfall!B10))/(Waterfall!B9+Waterfall!B10)/Scenarios!F82,0) -> 0
A26: CAPITAL STACK
A27: Tranche | B27: Amount | C27: % | D27: Rate | E27: Term (yrs) | F27: Amort (yrs)
A28: Senior Loan (1st) | B28: =Scenarios!F88 -> 0 | C28: =IFERROR(Scenarios!F88/Scenarios!F17,0) -> 0 | D28: =Scenarios!F89 -> 0 | E28: =Scenarios!F91 -> 0 | F28: =Scenarios!F90 -> 0
A29: 2nd Loan | B29: =Scenarios!F95 -> 0 | C29: =IFERROR(Scenarios!F95/Scenarios!F17,0) -> 0 | D29: =Scenarios!F96 -> 0 | E29: =Scenarios!F98 -> 0 | F29: =Scenarios!F97 -> 0
A30: Supplemental | B30: =Scenarios!F102 -> 0 | C30: =IFERROR(Scenarios!F102/Scenarios!F17,0) -> 0 | D30: =Scenarios!F103 -> 0 | E30: =Scenarios!F105 -> 0 | F30: =Scenarios!F104 -> 0
A31: GP Equity | B31: =Scenarios!F32 -> 0 | C31: =Scenarios!F28 -> 0.3 | D31: — | E31: — | F31: —
A32: Class A LP Equity | B32: =Scenarios!F33 -> 0 | C32: =Scenarios!F29 -> 0.7 | D32: =Scenarios!F35 -> 0 | E32: — | F32: —
A33: Class B LP Equity | B33: =Scenarios!F34 -> 0 | C33: =Scenarios!F30 -> 0 | D33: — | E33: — | F33: —
A34: TOTAL | B34: =Scenarios!F31 -> 0 | C34: =IFERROR(Scenarios!F31/Scenarios!F17,0) -> 0 | D34: — | E34: — | F34: —
A36: INVESTOR RETURNS SUMMARY
A37: Metric | B37: Class A LP | C37: Class B LP | D37: LP Combined | E37: GP | F37: Notes
A38: Total Equity Invested | B38: =Waterfall!B9 -> 0 | C38: =Waterfall!B10 -> 0 | D38: =Waterfall!B9+Waterfall!B10 -> 0 | E38: =Waterfall!B8 -> 0 | F38: Capital contributed by each party
A39: Total Distributions | B39: =Waterfall!M52 -> 0 | C39: =Waterfall!M53 -> 0 | D39: =Waterfall!M54 -> 0 | E39: =Waterfall!M55 -> 0 | F39: Operating CF + exit proceeds
A40: Net Profit | B40: =Waterfall!M52-Waterfall!B9 -> 0 | C40: =IFERROR(Waterfall!M53-Waterfall!B10,0) -> 0 | D40: =Waterfall!M54-(Waterfall!B9+Waterfall!B10) -> 0 | E40: =Waterfall!M55-Waterfall!B8 -> 0
A41: Equity Multiple (EM) | B41: =IFERROR(Waterfall!B64,0) -> 0 | C41: =IFERROR(Waterfall!C64,0) -> 0 | D41: =IFERROR(Waterfall!D64,0) -> 0 | E41: =IFERROR(Waterfall!E64,0) -> 0 | F41: Total value returned / capital in
A42: IRR | B42: =Waterfall!B66 -> 0 | C42: =Waterfall!C66 -> 0 | D42: =Waterfall!D66 -> 0 | E42: =Waterfall!E66 -> 0 | F42: Includes exit proceeds
A43: Avg Annual Return (simple, incl. exit) | B43: =IFERROR((Waterfall!M52-Waterfall!B9)/Waterfall!B9/Scenarios!F82,0) -> 0 | C43: =IFERROR((Waterfall!M53-Waterfall!B10)/Waterfall!B10/Scenarios!F82,0) -> 0 | D43: =IFERROR((Waterfall!M54-(Waterfall!B9+Waterfall!B10))/(Waterfall!B9+Waterfall!B10)/Scenarios!F82,0) -> 0 | E43: =IFERROR(IF(Waterfall!B8=0,"N/A",(Waterfall!M55-Waterfall!B8)/Waterfall!B8/Scenarios!F82),0) -> N/A | F43: Simple: (total distributions − equity) ÷ equity ÷ hold yrs. Not compounded.
...

Sheet Dashboard
B1: =IF('Prop Info'!B4=0,"Property",'Prop Info'!B4)&" — Underwriting" -> Property — Underwriting | R1: DASHBOARD CALC ENGINE (helper — unlevered returns / NPV)
B2: =IF('Prop Info'!B6=0,"",TEXT('Prop Info'!B6,"#,##0")&" Units")&IF('Prop Info'!B5=0,""," · "&'Prop Info'!B5) | R2: Discount Rate (NPV) | S2: 0.08
B3: $, unless noted otherwise | R3: Hold Period (yrs) | S3: =IF(Scenarios!F82=0,5,Scenarios!F82) -> 5
R4: Exit Cap Rate | S4: =IF(Scenarios!F83=0,0.0725,Scenarios!F83) -> 0.0725
B5: Property Overview | H5: Sources and Uses of Capital | R5: Sale Cost % | S5: =IFERROR(ABS('Exit Strategy'!G10)/'Exit Strategy'!G9,0.02) -> 0.02
B6: Property Name | D6: =IF('Prop Info'!B4=0,"",'Prop Info'!B4) | H6: Sources of Capital | J6: Assumption | L6: % | M6: $ | N6: $ / RSF | O6: $ / Unit | R6: Total Cost (basis) | S6: =Scenarios!F17 -> 0
B7: Address | D7: =IF('Prop Info'!B5=0,"",'Prop Info'!B5) | H7: Total Debt | L7: =IFERROR(M7/$M$11,0) -> 0 | M7: =Scenarios!F23 -> 0 | N7: =IFERROR(M7/'Prop Info'!$B$15,0) -> 0 | O7: =IFERROR(M7/'Prop Info'!$B$6,0) -> 0 | R7: Total Equity | S7: =Scenarios!F31 -> 0
B8: City / Market | D8: =IF('Prop Info'!B20=0,"",'Prop Info'!B20) | H8: LP Equity | L8: =IFERROR(M8/$M$11,0) -> 0 | M8: =Scenarios!F33+Scenarios!F34 -> 0 | N8: =IFERROR(M8/'Prop Info'!$B$15,0) -> 0 | O8: =IFERROR(M8/'Prop Info'!$B$6,0) -> 0 | R8: Forward NOI (exit+1) | S8: {=IFERROR(INDEX('P&L'!$D$40:$M$40,1,$S$3+1),0)}
B9: Submarket / MSA | D9: =IF('Prop Info'!B21=0,"",'Prop Info'!B21) | H9: GP Equity | L9: =IFERROR(M9/$M$11,0) -> 0 | M9: =Scenarios!F32 -> 0 | N9: =IFERROR(M9/'Prop Info'!$B$15,0) -> 0 | O9: =IFERROR(M9/'Prop Info'!$B$6,0) -> 0 | R9: Unlev Net Sale | S9: =IFERROR($S$8/$S$4*(1-$S$5),0) -> 0
B10: Building Class | D10: =IF('Prop Info'!B13=0,"",'Prop Info'!B13) | H10: Total Equity | L10: =IFERROR(M10/$M$11,0) -> 0 | M10: =Scenarios!F31 -> 0 | N10: =IFERROR(M10/'Prop Info'!$B$15,0) -> 0 | O10: =IFERROR(M10/'Prop Info'!$B$6,0) -> 0
B11: Amenity Tier | D11: =IF('Prop Info'!B14=0,"",'Prop Info'!B14) | H11: Total Sources of Capital | L11: =IFERROR(M11/$M$11,0) -> 0 | M11: =M7+M10 -> 0 | N11: =IFERROR(M11/'Prop Info'!$B$15,0) -> 0 | O11: =IFERROR(M11/'Prop Info'!$B$6,0) -> 0
B12: Year Built | D12: =IF('Prop Info'!B9=0,"",TEXT('Prop Info'!B9,"0")) | R12: Year | S12: 0 | T12: 1 | U12: 2 | V12: 3 | W12: 4 | X12: 5 | Y12: 6 | Z12: 7 | AA12: 8 | AB12: 9 | AC12: 10
B13: Acquisition Date | H13: Uses of Capital | J13: Assumption | L13: % | M13: $ | N13: $ / RSF | O13: $ / Unit | R13: Unlev NOI | S13: 0 | T13: =IF(AND(T$12>=1,T$12<=$S$3),N(INDEX('P&L'!$D$40:$M$40,1,T$12)),0) -> 0 | U13: =IF(AND(U$12>=1,U$12<=$S$3),N(INDEX('P&L'!$D$40:$M$40,1,U$12)),0) -> 0 | V13: =IF(AND(V$12>=1,V$12<=$S$3),N(INDEX('P&L'!$D$40:$M$40,1,V$12)),0) -> 0 | W13: =IF(AND(W$12>=1,W$12<=$S$3),N(INDEX('P&L'!$D$40:$M$40,1,W$12)),0) -> 0 | X13: =IF(AND(X$12>=1,X$12<=$S$3),N(INDEX('P&L'!$D$40:$M$40,1,X$12)),0) -> 0 | Y13: =IF(AND(Y$12>=1,Y$12<=$S$3),N(INDEX('P&L'!$D$40:$M$40,1,Y$12)),0) -> 0 | Z13: =IF(AND(Z$12>=1,Z$12<=$S$3),N(INDEX('P&L'!$D$40:$M$40,1,Z$12)),0) -> 0 | AA13: =IF(AND(AA$12>=1,AA$12<=$S$3),N(INDEX('P&L'!$D$40:$M$40,1,AA$12)),0) -> 0 | ... AC13: =IF(AND(AC$12>=1,AC$12<=$S$3),N(INDEX('P&L'!$D$40:$M$40,1,AC$12)),0) -> 0
H14: Purchase Price | L14: =IFERROR(M14/$M$19,0) -> 0 | M14: =Scenarios!F7 -> 0 | N14: =IFERROR(M14/'Prop Info'!$B$15,0) -> 0 | O14: =IFERROR(M14/'Prop Info'!$B$6,0) -> 0 | R14: Unlev Sale | S14: 0 | T14: =IF(T$12=$S$3,$S$9,0) -> 0 | U14: =IF(U$12=$S$3,$S$9,0) -> 0 | V14: =IF(V$12=$S$3,$S$9,0) -> 0 | W14: =IF(W$12=$S$3,$S$9,0) -> 0 | X14: =IF(X$12=$S$3,$S$9,0) -> 0 | Y14: =IF(Y$12=$S$3,$S$9,0) -> 0 | Z14: =IF(Z$12=$S$3,$S$9,0) -> 0 | AA14: =IF(AA$12=$S$3,$S$9,0) -> 0 | ... AC14: =IF(AC$12=$S$3,$S$9,0) -> 0
B15: Number of Units | D15: ='Prop Info'!B6 -> 0 | H15: Capital Improvements | L15: =IFERROR(M15/$M$19,0) -> 0 | M15: =Scenarios!F12 -> 0 | N15: =IFERROR(M15/'Prop Info'!$B$15,0) -> 0 | O15: =IFERROR(M15/'Prop Info'!$B$6,0) -> 0 | R15: Unlev Total CF | S15: =-$S$6 -> 0 | T15: =N(T13)+N(T14) -> 0 | U15: =N(U13)+N(U14) -> 0 | V15: =N(V13)+N(V14) -> 0 | W15: =N(W13)+N(W14) -> 0 | X15: =N(X13)+N(X14) -> 0 | Y15: =N(Y13)+N(Y14) -> 0 | Z15: =N(Z13)+N(Z14) -> 0 | AA15: =N(AA13)+N(AA14) -> 0 | ... AC15: =N(AC13)+N(AC14) -> 0
B16: Number of Buildings | D16: ='Prop Info'!B7 -> 0 | H16: Closing & Legal | J16: =IF(Scenarios!F7=0,"",TEXT(M16/M14,"0.0%")&" of Purchase Price") | L16: =IFERROR(M16/$M$19,0) -> 0 | M16: =Scenarios!F14 -> 0 | N16: =IFERROR(M16/'Prop Info'!$B$15,0) -> 0 | O16: =IFERROR(M16/'Prop Info'!$B$6,0) -> 0 | R16: Lev Op CF | S16: =-$S$7 -> 0 | T16: =IF(AND(T$12>=1,T$12<=$S$3),N(INDEX('P&L'!$D$48:$M$48,1,T$12)),0) -> 0 | U16: =IF(AND(U$12>=1,U$12<=$S$3),N(INDEX('P&L'!$D$48:$M$48,1,U$12)),0) -> 0 | V16: =IF(AND(V$12>=1,V$12<=$S$3),N(INDEX('P&L'!$D$48:$M$48,1,V$12)),0) -> 0 | W16: =IF(AND(W$12>=1,W$12<=$S$3),N(INDEX('P&L'!$D$48:$M$48,1,W$12)),0) -> 0 | X16: =IF(AND(X$12>=1,X$12<=$S$3),N(INDEX('P&L'!$D$48:$M$48,1,X$12)),0) -> 0 | Y16: =IF(AND(Y$12>=1,Y$12<=$S$3),N(INDEX('P&L'!$D$48:$M$48,1,Y$12)),0) -> 0 | Z16: =IF(AND(Z$12>=1,Z$12<=$S$3),N(INDEX('P&L'!$D$48:$M$48,1,Z$12)),0) -> 0 | AA16: =IF(AND(AA$12>=1,AA$12<=$S$3),N(INDEX('P&L'!$D$48:$M$48,1,AA$12)),0) -> 0 | ... AC16: =IF(AND(AC$12>=1,AC$12<=$S$3),N(INDEX('P&L'!$D$48:$M$48,1,AC$12)),0) -> 0
B17: Total Rentable SF | D17: ='Prop Info'!B15 -> 0 | H17: Acquisition Fee | J17: =IF(Scenarios!F7=0,"",TEXT(M17/M14,"0.0%")&" of Purchase Price") | L17: =IFERROR(M17/$M$19,0) -> 0 | M17: =Scenarios!F16 -> 0 | N17: =IFERROR(M17/'Prop Info'!$B$15,0) -> 0 | O17: =IFERROR(M17/'Prop Info'!$B$6,0) -> 0 | R17: Lev Total CF | S17: =-$S$7 -> 0 | T17: =N(T16)+IF(T$12=$S$3,N(Waterfall!$B$35),0) -> 0 | U17: =N(U16)+IF(U$12=$S$3,N(Waterfall!$B$35),0) -> 0 | V17: =N(V16)+IF(V$12=$S$3,N(Waterfall!$B$35),0) -> 0 | W17: =N(W16)+IF(W$12=$S$3,N(Waterfall!$B$35),0) -> 0 | X17: =N(X16)+IF(X$12=$S$3,N(Waterfall!$B$35),0) -> 0 | Y17: =N(Y16)+IF(Y$12=$S$3,N(Waterfall!$B$35),0) -> 0 | Z17: =N(Z16)+IF(Z$12=$S$3,N(Waterfall!$B$35),0) -> 0 | AA17: =N(AA16)+IF(AA$12=$S$3,N(Waterfall!$B$35),0) -> 0 | ... AC17: =N(AC16)+IF(AC$12=$S$3,N(Waterfall!$B$35),0) -> 0
B18: Average RSF | D18: =IFERROR('Prop Info'!B15/'Prop Info'!B6,0) -> 0 | H18: Operating Reserves | L18: =IFERROR(M18/$M$19,0) -> 0 | M18: =Scenarios!F13 -> 0 | N18: =IFERROR(M18/'Prop Info'!$B$15,0) -> 0 | O18: =IFERROR(M18/'Prop Info'!$B$6,0) -> 0
B19: Land Area | D19: ='Prop Info'!B10 -> 0 | H19: Total Uses of Capital | L19: =IFERROR(M19/$M$19,0) -> 0 | M19: =SUM(M14:M18) -> 0 | N19: =IFERROR(M19/'Prop Info'!$B$15,0) -> 0 | O19: =IFERROR(M19/'Prop Info'!$B$6,0) -> 0 | R19: Unlev IRR | S19: =IFERROR(IRR(S15:AC15),0) -> 0
B20: Units / Acre | D20: =IFERROR('Prop Info'!B6/'Prop Info'!B10,0) -> 0 | R20: Unlev MOIC | S20: =IFERROR(SUM(T15:AC15)/$S$6,0) -> 0
B21: Parking Spaces | D21: ='Prop Info'!B12 -> 0 | R21: Unlev Profit | S21: =SUM(S15:AC15) -> 0
B22: Parking Ratio (Spaces / 1K SF) | D22: =IFERROR('Prop Info'!B12/('Prop Info'!B15/1000),0) -> 0 | H22: Unit Mix and Pro Forma Rents | R22: Unlev Equity | S22: =$S$6 -> 0
H23: Unit Type | I23: % Reno | J23: Units | K23: Avg RSF | L23: In-Place $/U | M23: $/RSF | N23: Rent Prem. | O23: Post-Reno $/U | R23: Unlev Avg Yield | S23: =IFERROR(SUM(T13:AC13)/$S$3/$S$6,0) -> 0
B24: Returns Summary | H24: {=IFERROR(INDEX(_xlfn.UNIQUE(_xlfn._xlws.FILTER('Rent Roll Analysis'!$C$273:$C$1772,'Rent Roll Analysis'!$C$273:$C$1772<>"")),ROW()-23),"")} | J24: =IF($H24="","",COUNTIF('Rent Roll Analysis'!$C$273:$C$1772,$H24)) | K24: =IF($H24="","",IFERROR(AVERAGEIF('Rent Roll Analysis'!$C$273:$C$1772,$H24,'Rent Roll Analysis'!$D$273:$D$1772),0)) | L24: =IF($H24="","",IFERROR(AVERAGEIF('Rent Roll Analysis'!$C$273:$C$1772,$H24,'Rent Roll Analysis'!$N$273:$N$1772),0)) | M24: =IFERROR(L24/K24,0) -> 0 | O24: =IF($H24="","",N(L24)+N(N24))
D25: Unlevered | E25: Levered (LP) | H25: {=IFERROR(INDEX(_xlfn.UNIQUE(_xlfn._xlws.FILTER('Rent Roll Analysis'!$C$273:$C$1772,'Rent Roll Analysis'!$C$273:$C$1772<>"")),ROW()-23),"")} | J25: =IF($H25="","",COUNTIF('Rent Roll Analysis'!$C$273:$C$1772,$H25)) | K25: =IF($H25="","",IFERROR(AVERAGEIF('Rent Roll Analysis'!$C$273:$C$1772,$H25,'Rent Roll Analysis'!$D$273:$D$1772),0)) | L25: =IF($H25="","",IFERROR(AVERAGEIF('Rent Roll Analysis'!$C$273:$C$1772,$H25,'Rent Roll Analysis'!$N$273:$N$1772),0)) | M25: =IFERROR(L25/K25,0) -> 0 | O25: =IF($H25="","",N(L25)+N(N25)) | R25: Lev Avg Yield | S25: =IFERROR(SUM(T16:AC16)/$S$3/$S$7,0) -> 0
B26: IRR | D26: =S19 -> 0 | E26: =IFERROR(N(Waterfall!D66),0) -> 0 | H26: {=IFERROR(INDEX(_xlfn.UNIQUE(_xlfn._xlws.FILTER('Rent Roll Analysis'!$C$273:$C$1772,'Rent Roll Analysis'!$C$273:$C$1772<>"")),ROW()-23),"")} | J26: =IF($H26="","",COUNTIF('Rent Roll Analysis'!$C$273:$C$1772,$H26)) | K26: =IF($H26="","",IFERROR(AVERAGEIF('Rent Roll Analysis'!$C$273:$C$1772,$H26,'Rent Roll Analysis'!$D$273:$D$1772),0)) | L26: =IF($H26="","",IFERROR(AVERAGEIF('Rent Roll Analysis'!$C$273:$C$1772,$H26,'Rent Roll Analysis'!$N$273:$N$1772),0)) | M26: =IFERROR(L26/K26,0) -> 0 | O26: =IF($H26="","",N(L26)+N(N26))
B27: MOIC | D27: =S20 -> 0 | E27: =IFERROR(N(Waterfall!D64),0) -> 0 | H27: {=IFERROR(INDEX(_xlfn.UNIQUE(_xlfn._xlws.FILTER('Rent Roll Analysis'!$C$273:$C$1772,'Rent Roll Analysis'!$C$273:$C$1772<>"")),ROW()-23),"")} | J27: =IF($H27="","",COUNTIF('Rent Roll Analysis'!$C$273:$C$1772,$H27)) | K27: =IF($H27="","",IFERROR(AVERAGEIF('Rent Roll Analysis'!$C$273:$C$1772,$H27,'Rent Roll Analysis'!$D$273:$D$1772),0)) | L27: =IF($H27="","",IFERROR(AVERAGEIF('Rent Roll Analysis'!$C$273:$C$1772,$H27,'Rent Roll Analysis'!$N$273:$N$1772),0)) | M27: =IFERROR(L27/K27,0) -> 0 | O27: =IF($H27="","",N(L27)+N(N27)) | R27: Current Value (NPV) | S27: =NPV($S$2,T15:AC15) -> 0
B28: Profit | D28: =S21 -> 0 | E28: =IFERROR(N(Waterfall!D65),0) -> 0 | H28: {=IFERROR(INDEX(_xlfn.UNIQUE(_xlfn._xlws.FILTER('Rent Roll Analysis'!$C$273:$C$1772,'Rent Roll Analysis'!$C$273:$C$1772<>"")),ROW()-23),"")} | J28: =IF($H28="","",COUNTIF('Rent Roll Analysis'!$C$273:$C$1772,$H28)) | K28: =IF($H28="","",IFERROR(AVERAGEIF('Rent Roll Analysis'!$C$273:$C$1772,$H28,'Rent Roll Analysis'!$D$273:$D$1772),0)) | L28: =IF($H28="","",IFERROR(AVERAGEIF('Rent Roll Analysis'!$C$273:$C$1772,$H28,'Rent Roll Analysis'!$N$273:$N$1772),0)) | M28: =IFERROR(L28/K28,0) -> 0 | O28: =IF($H28="","",N(L28)+N(N28)) | R28: Implied Cap | S28: =IFERROR(N('P&L'!$D$40)/$S$27,0) -> 0
B29: Equity | D29: =S22 -> 0 | E29: =N(Waterfall!B9)+N(Waterfall!B10) -> 0 | H29: {=IFERROR(INDEX(_xlfn.UNIQUE(_xlfn._xlws.FILTER('Rent Roll Analysis'!$C$273:$C$1772,'Rent Roll Analysis'!$C$273:$C$1772<>"")),ROW()-23),"")} | J29: =IF($H29="","",COUNTIF('Rent Roll Analysis'!$C$273:$C$1772,$H29)) | K29: =IF($H29="","",IFERROR(AVERAGEIF('Rent Roll Analysis'!$C$273:$C$1772,$H29,'Rent Roll Analysis'!$D$273:$D$1772),0)) | L29: =IF($H29="","",IFERROR(AVERAGEIF('Rent Roll Analysis'!$C$273:$C$1772,$H29,'Rent Roll Analysis'!$N$273:$N$1772),0)) | M29: =IFERROR(L29/K29,0) -> 0 | O29: =IF($H29="","",N(L29)+N(N29)) | R29: Yr 1 NOI | S29: =N('P&L'!$D$40) -> 0
B30: Average Yield | D30: =S23 -> 0 | E30: =S25 -> 0 | H30: Total / Weighted Avg | I30: =IFERROR(SUMPRODUCT(I24:I29,J24:J29)/SUM(J24:J29),0) -> 0 | J30: =SUM(J24:J29) -> 0 | K30: =IFERROR(SUMPRODUCT(K24:K29,J24:J29)/J30,0) -> 0 | L30: =IFERROR(SUMPRODUCT(L24:L29,J24:J29)/J30,0) -> 0 | M30: =IFERROR(L30/K30,0) -> 0 | N30: =IFERROR(SUMPRODUCT(N24:N29,J24:J29)/J30,0) -> 0 | O30: =N(L30)+N(N30) -> 0
R31: SENS ENGINE (Levered approx: IRR=MOIC^(1/yr)-1)
B32: NPV Reversion | H32: Pro Forma Assumptions
B33: Discount Rate | D33: =S2 -> 0.08 | E33: Current Value | F33: =S27 -> 0 | J33: Yr. 1 | K33: Yr. 2 | L33: Yr. 3 | M33: Yr. 4 | N33: Yr. 5 | O33: Yr. 6 + | S33: =MAX(1,$S$3-1) -> 4 | T33: =$S$3 -> 5 | U33: =$S$3+1 -> 6 | W33: =S33 -> 4 | X33: =T33 -> 5 | Y33: =U33 -> 6
B34: Per Unit | D34: =IFERROR(S27/'Prop Info'!$B$6,0) -> 0 | E34: Per RSF | F34: =IFERROR(S27/'Prop Info'!$B$15,0) -> 0 | H34: Growth Rates | R34: =$S$4-0.005 -> 0.0675 | S34: =IFERROR(((N(INDEX('P&L'!$D$40:$M$40,1,S$33+1))/$R34*(1-$S$5)-N(Scenarios!$F$116)+SUM(INDEX($T$16:$AC$16,1,1):INDEX($T$16:$AC$16,1,S$33)))/$S$7)^(1/S$33)-1,0) -> 0 | T34: =IFERROR(((N(INDEX('P&L'!$D$40:$M$40,1,T$33+1))/$R34*(1-$S$5)-N(Scenarios!$F$116)+SUM(INDEX($T$16:$AC$16,1,1):INDEX($T$16:$AC$16,1,T$33)))/$S$7)^(1/T$33)-1,0) -> 0 | U34: =IFERROR(((N(INDEX('P&L'!$D$40:$M$40,1,U$33+1))/$R34*(1-$S$5)-N(Scenarios!$F$116)+SUM(INDEX($T$16:$AC$16,1,1):INDEX($T$16:$AC$16,1,U$33)))/$S$7)^(1/U$33)-1,0) -> 0 | V34: =R34 -> 0.0675 | W34: =IFERROR((N(INDEX('P&L'!$D$40:$M$40,1,W$33+1))/$V34*(1-$S$5)-N(Scenarios!$F$116)+SUM(INDEX($T$16:$AC$16,1,1):INDEX($T$16:$AC$16,1,W$33)))/$S$7,0) -> 0 | X34: =IFERROR((N(INDEX('P&L'!$D$40:$M$40,1,X$33+1))/$V34*(1-$S$5)-N(Scenarios!$F$116)+SUM(INDEX($T$16:$AC$16,1,1):INDEX($T$16:$AC$16,1,X$33)))/$S$7,0) -> 0 | Y34: =IFERROR((N(INDEX('P&L'!$D$40:$M$40,1,Y$33+1))/$V34*(1-$S$5)-N(Scenarios!$F$116)+SUM(INDEX($T$16:$AC$16,1,1):INDEX($T$16:$AC$16,1,Y$33)))/$S$7,0) -> 0
B35: Yr. 1 NOI | D35: =S29 -> 0 | E35: Imp. Cap Rate | F35: =S28 -> 0 | H35: Current Rent | J35: =IFERROR(N('P&L'!D10)/N('P&L'!C10)-1,0) -> 0 | K35: =IFERROR(N('P&L'!E10)/N('P&L'!D10)-1,0) -> 0 | L35: =IFERROR(N('P&L'!F10)/N('P&L'!E10)-1,0) -> 0 | M35: =IFERROR(N('P&L'!G10)/N('P&L'!F10)-1,0) -> 0 | N35: =IFERROR(N('P&L'!H10)/N('P&L'!G10)-1,0) -> 0 | O35: =IFERROR(N('P&L'!I10)/N('P&L'!H10)-1,0) -> 0 | R35: =$S$4-0.0025 -> 0.07 | S35: =IFERROR(((N(INDEX('P&L'!$D$40:$M$40,1,S$33+1))/$R35*(1-$S$5)-N(Scenarios!$F$116)+SUM(INDEX($T$16:$AC$16,1,1):INDEX($T$16:$AC$16,1,S$33)))/$S$7)^(1/S$33)-1,0) -> 0 | T35: =IFERROR(((N(INDEX('P&L'!$D$40:$M$40,1,T$33+1))/$R35*(1-$S$5)-N(Scenarios!$F$116)+SUM(INDEX($T$16:$AC$16,1,1):INDEX($T$16:$AC$16,1,T$33)))/$S$7)^(1/T$33)-1,0) -> 0 | U35: =IFERROR(((N(INDEX('P&L'!$D$40:$M$40,1,U$33+1))/$R35*(1-$S$5)-N(Scenarios!$F$116)+SUM(INDEX($T$16:$AC$16,1,1):INDEX($T$16:$AC$16,1,U$33)))/$S$7)^(1/U$33)-1,0) -> 0 | V35: =R35 -> 0.07 | W35: =IFERROR((N(INDEX('P&L'!$D$40:$M$40,1,W$33+1))/$V35*(1-$S$5)-N(Scenarios!$F$116)+SUM(INDEX($T$16:$AC$16,1,1):INDEX($T$16:$AC$16,1,W$33)))/$S$7,0) -> 0 | X35: =IFERROR((N(INDEX('P&L'!$D$40:$M$40,1,X$33+1))/$V35*(1-$S$5)-N(Scenarios!$F$116)+SUM(INDEX($T$16:$AC$16,1,1):INDEX($T$16:$AC$16,1,X$33)))/$S$7,0) -> 0 | Y35: =IFERROR((N(INDEX('P&L'!$D$40:$M$40,1,Y$33+1))/$V35*(1-$S$5)-N(Scenarios!$F$116)+SUM(INDEX($T$16:$AC$16,1,1):INDEX($T$16:$AC$16,1,Y$33)))/$S$7,0) -> 0
H36: Post-Renovation Rent | J36: =IFERROR(N('P&L'!D10)/N('P&L'!C10)-1,0) -> 0 | K36: =IFERROR(N('P&L'!E10)/N('P&L'!D10)-1,0) -> 0 | L36: =IFERROR(N('P&L'!F10)/N('P&L'!E10)-1,0) -> 0 | M36: =IFERROR(N('P&L'!G10)/N('P&L'!F10)-1,0) -> 0 | N36: =IFERROR(N('P&L'!H10)/N('P&L'!G10)-1,0) -> 0 | O36: =IFERROR(N('P&L'!I10)/N('P&L'!H10)-1,0) -> 0 | R36: =$S$4 -> 0.0725 | S36: =IFERROR(((N(INDEX('P&L'!$D$40:$M$40,1,S$33+1))/$R36*(1-$S$5)-N(Scenarios!$F$116)+SUM(INDEX($T$16:$AC$16,1,1):INDEX($T$16:$AC$16,1,S$33)))/$S$7)^(1/S$33)-1,0) -> 0 | T36: =IFERROR(((N(INDEX('P&L'!$D$40:$M$40,1,T$33+1))/$R36*(1-$S$5)-N(Scenarios!$F$116)+SUM(INDEX($T$16:$AC$16,1,1):INDEX($T$16:$AC$16,1,T$33)))/$S$7)^(1/T$33)-1,0) -> 0 | U36: =IFERROR(((N(INDEX('P&L'!$D$40:$M$40,1,U$33+1))/$R36*(1-$S$5)-N(Scenarios!$F$116)+SUM(INDEX($T$16:$AC$16,1,1):INDEX($T$16:$AC$16,1,U$33)))/$S$7)^(1/U$33)-1,0) -> 0 | V36: =R36 -> 0.0725 | W36: =IFERROR((N(INDEX('P&L'!$D$40:$M$40,1,W$33+1))/$V36*(1-$S$5)-N(Scenarios!$F$116)+SUM(INDEX($T$16:$AC$16,1,1):INDEX($T$16:$AC$16,1,W$33)))/$S$7,0) -> 0 | X36: =IFERROR((N(INDEX('P&L'!$D$40:$M$40,1,X$33+1))/$V36*(1-$S$5)-N(Scenarios!$F$116)+SUM(INDEX($T$16:$AC$16,1,1):INDEX($T$16:$AC$16,1,X$33)))/$S$7,0) -> 0 | Y36: =IFERROR((N(INDEX('P&L'!$D$40:$M$40,1,Y$33+1))/$V36*(1-$S$5)-N(Scenarios!$F$116)+SUM(INDEX($T$16:$AC$16,1,1):INDEX($T$16:$AC$16,1,Y$33)))/$S$7,0) -> 0
H37: Utility & Other Income | J37: =IFERROR(N('P&L'!D18)/N('P&L'!C18)-1,0) -> 0 | K37: =IFERROR(N('P&L'!E18)/N('P&L'!D18)-1,0) -> 0 | L37: =IFERROR(N('P&L'!F18)/N('P&L'!E18)-1,0) -> 0 | M37: =IFERROR(N('P&L'!G18)/N('P&L'!F18)-1,0) -> 0 | N37: =IFERROR(N('P&L'!H18)/N('P&L'!G18)-1,0) -> 0 | O37: =IFERROR(N('P&L'!I18)/N('P&L'!H18)-1,0) -> 0 | R37: =$S$4+0.0025 -> 0.075 | S37: =IFERROR(((N(INDEX('P&L'!$D$40:$M$40,1,S$33+1))/$R37*(1-$S$5)-N(Scenarios!$F$116)+SUM(INDEX($T$16:$AC$16,1,1):INDEX($T$16:$AC$16,1,S$33)))/$S$7)^(1/S$33)-1,0) -> 0 | T37: =IFERROR(((N(INDEX('P&L'!$D$40:$M$40,1,T$33+1))/$R37*(1-$S$5)-N(Scenarios!$F$116)+SUM(INDEX($T$16:$AC$16,1,1):INDEX($T$16:$AC$16,1,T$33)))/$S$7)^(1/T$33)-1,0) -> 0 | U37: =IFERROR(((N(INDEX('P&L'!$D$40:$M$40,1,U$33+1))/$R37*(1-$S$5)-N(Scenarios!$F$116)+SUM(INDEX($T$16:$AC$16,1,1):INDEX($T$16:$AC$16,1,U$33)))/$S$7)^(1/U$33)-1,0) -> 0 | V37: =R37 -> 0.075 | W37: =IFERROR((N(INDEX('P&L'!$D$40:$M$40,1,W$33+1))/$V37*(1-$S$5)-N(Scenarios!$F$116)+SUM(INDEX($T$16:$AC$16,1,1):INDEX($T$16:$AC$16,1,W$33)))/$S$7,0) -> 0 | X37: =IFERROR((N(INDEX('P&L'!$D$40:$M$40,1,X$33+1))/$V37*(1-$S$5)-N(Scenarios!$F$116)+SUM(INDEX($T$16:$AC$16,1,1):INDEX($T$16:$AC$16,1,X$33)))/$S$7,0) -> 0 | Y37: =IFERROR((N(INDEX('P&L'!$D$40:$M$40,1,Y$33+1))/$V37*(1-$S$5)-N(Scenarios!$F$116)+SUM(INDEX($T$16:$AC$16,1,1):INDEX($T$16:$AC$16,1,Y$33)))/$S$7,0) -> 0
B38: Exit Assumptions | H38: General OpEx | J38: =IFERROR((N('P&L'!D38)-N('P&L'!D28))/(N('P&L'!C38)-N('P&L'!C28))-1,0) -> 0 | K38: =IFERROR((N('P&L'!E38)-N('P&L'!E28))/(N('P&L'!D38)-N('P&L'!D28))-1,0) -> 0 | L38: =IFERROR((N('P&L'!F38)-N('P&L'!F28))/(N('P&L'!E38)-N('P&L'!E28))-1,0) -> 0 | M38: =IFERROR((N('P&L'!G38)-N('P&L'!G28))/(N('P&L'!F38)-N('P&L'!F28))-1,0) -> 0 | N38: =IFERROR((N('P&L'!H38)-N('P&L'!H28))/(N('P&L'!G38)-N('P&L'!G28))-1,0) -> 0 | O38: =IFERROR((N('P&L'!I38)-N('P&L'!I28))/(N('P&L'!H38)-N('P&L'!H28))-1,0) -> 0 | R38: =$S$4+0.005 -> 0.0775 | S38: =IFERROR(((N(INDEX('P&L'!$D$40:$M$40,1,S$33+1))/$R38*(1-$S$5)-N(Scenarios!$F$116)+SUM(INDEX($T$16:$AC$16,1,1):INDEX($T$16:$AC$16,1,S$33)))/$S$7)^(1/S$33)-1,0) -> 0 | T38: =IFERROR(((N(INDEX('P&L'!$D$40:$M$40,1,T$33+1))/$R38*(1-$S$5)-N(Scenarios!$F$116)+SUM(INDEX($T$16:$AC$16,1,1):INDEX($T$16:$AC$16,1,T$33)))/$S$7)^(1/T$33)-1,0) -> 0 | U38: =IFERROR(((N(INDEX('P&L'!$D$40:$M$40,1,U$33+1))/$R38*(1-$S$5)-N(Scenarios!$F$116)+SUM(INDEX($T$16:$AC$16,1,1):INDEX($T$16:$AC$16,1,U$33)))/$S$7)^(1/U$33)-1,0) -> 0 | V38: =R38 -> 0.0775 | W38: =IFERROR((N(INDEX('P&L'!$D$40:$M$40,1,W$33+1))/$V38*(1-$S$5)-N(Scenarios!$F$116)+SUM(INDEX($T$16:$AC$16,1,1):INDEX($T$16:$AC$16,1,W$33)))/$S$7,0) -> 0 | X38: =IFERROR((N(INDEX('P&L'!$D$40:$M$40,1,X$33+1))/$V38*(1-$S$5)-N(Scenarios!$F$116)+SUM(INDEX($T$16:$AC$16,1,1):INDEX($T$16:$AC$16,1,X$33)))/$S$7,0) -> 0 | Y38: =IFERROR((N(INDEX('P&L'!$D$40:$M$40,1,Y$33+1))/$V38*(1-$S$5)-N(Scenarios!$F$116)+SUM(INDEX($T$16:$AC$16,1,1):INDEX($T$16:$AC$16,1,Y$33)))/$S$7,0) -> 0
B39: Exit Year | D39: ="Yr. "&TEXT(S3,"0") -> Yr. 5 | E39: Exit Month | F39: ="Mo. "&TEXT(S3*12,"0") -> Mo. 60 | H39: Real Estate Taxes | J39: =IFERROR(N('P&L'!D28)/N('P&L'!C28)-1,0) -> 0 | K39: =IFERROR(N('P&L'!E28)/N('P&L'!D28)-1,0) -> 0 | L39: =IFERROR(N('P&L'!F28)/N('P&L'!E28)-1,0) -> 0 | M39: =IFERROR(N('P&L'!G28)/N('P&L'!F28)-1,0) -> 0 | N39: =IFERROR(N('P&L'!H28)/N('P&L'!G28)-1,0) -> 0 | O39: =IFERROR(N('P&L'!I28)/N('P&L'!H28)-1,0) -> 0
B40: Forward NOI | F40: =S8 | H40: Operating Assumptions
...

Sheet Inputs
A1: =IF('Prop Info'!B4="","MODEL INPUTS — NAVIGATION","MODEL INPUTS — NAVIGATION"&" — "&'Prop Info'!B4) -> MODEL INPUTS — NAVIGATION
A3: COLOR LEGEND
A4: Blue | B4: Hardcoded input — type here
A5: Black | B5: Same-sheet formula — do not edit
A6: Green | B6: Cross-sheet link — do not edit
A7: Red | B7: External file link — do not edit
A9: Total input cells: | B9: 452 | C9: across | D9: 14 | E9: tabs
A11: Tab | B11: Cell | C11: Label | D11: Current Value
A12: SCENARIOS | B12: 66 inputs
A13: Scenarios | B13: =HYPERLINK("#Scenarios!B10","B10") -> B10 | C13: Down Payment % | D13: 0.2
A14: Scenarios | B14: =HYPERLINK("#Scenarios!B15","B15") -> B15 | C14: Acquisition Fee (%) | D14: 0.03
A15: Scenarios | B15: =HYPERLINK("#Scenarios!B28","B28") -> B28 | C15: GP Ownership % | D15: 0.3
A16: Scenarios | B16: =HYPERLINK("#Scenarios!C28","C28") -> C28 | C16: GP Ownership % | D16: 0.3
A17: Scenarios | B17: =HYPERLINK("#Scenarios!C32","C32") -> C32 | C17: GP Equity ($) | D17: 0
A18: Scenarios | B18: =HYPERLINK("#Scenarios!B35","B35") -> B35 | C18: Class A Preferred Return % | D18: 0
A19: Scenarios | B19: =HYPERLINK("#Scenarios!C35","C35") -> C35 | C19: Class A Preferred Return % | D19: 0
A20: Scenarios | B20: =HYPERLINK("#Scenarios!B36","B36") -> B36 | C20: Class B Preferred Return % (T-12 Actuals) | D20: =Scenarios!B36 -> 0
A21: Scenarios | B21: =HYPERLINK("#Scenarios!C36","C36") -> C36 | C21: Class B Preferred Return % (My Version) | D21: =Scenarios!C36 -> 0
A22: Scenarios | B22: =HYPERLINK("#Scenarios!D36","D36") -> D36 | C22: Class B Preferred Return % (Projected) | D22: =Scenarios!D36 -> 0
A23: Scenarios | B23: =HYPERLINK("#Scenarios!E36","E36") -> E36 | C23: Class B Preferred Return % (Offer) | D23: =Scenarios!E36 -> 0
A24: Scenarios | B24: =HYPERLINK("#Scenarios!C46","C46") -> C46 | C24: Covered/garage: 1–3% of GPR | D24: 0
A25: Scenarios | B25: =HYPERLINK("#Scenarios!B77","B77") -> B77 | C25: Market Cap Rate | D25: 0.08
A26: Scenarios | B26: =HYPERLINK("#Scenarios!D77","D77") -> D77 | C26: Market Cap Rate | D26: 0.08
A27: Scenarios | B27: =HYPERLINK("#Scenarios!E77","E77") -> E77 | C27: Market Cap Rate | D27: 0.08
A28: Scenarios | B28: =HYPERLINK("#Scenarios!B79","B79") -> B79 | C28: As-Is Appraised Value | D28: 0
A29: Scenarios | B29: =HYPERLINK("#Scenarios!D80","D80") -> D80 | C29: Exit Year | D29: 7
A30: Scenarios | B30: =HYPERLINK("#Scenarios!E80","E80") -> E80 | C30: Exit Year | D30: 7
A31: Scenarios | B31: =HYPERLINK("#Scenarios!D81","D81") -> D81 | C31: Exit Cap Rate | D31: 0.085
A32: Scenarios | B32: =HYPERLINK("#Scenarios!E81","E81") -> E81 | C32: Exit Cap Rate | D32: 0.085
A33: Scenarios | B33: =HYPERLINK("#Scenarios!B91","B91") -> B91 | C33: Origination Fee % — 1st | D33: 0.01
A34: Scenarios | B34: =HYPERLINK("#Scenarios!C91","C91") -> C91 | C34: Origination Fee % — 1st | D34: 0.01
A35: Scenarios | B35: =HYPERLINK("#Scenarios!C93","C93") -> C93 | C35: Loan Amount — 2nd ($) | D35: 0
A36: Scenarios | B36: =HYPERLINK("#Scenarios!C94","C94") -> C94 | C36: Interest Rate — 2nd (%) | D36: 0
A37: Scenarios | B37: =HYPERLINK("#Scenarios!C95","C95") -> C95 | C37: Amortization (years) — 2nd | D37: 0
A38: Scenarios | B38: =HYPERLINK("#Scenarios!C96","C96") -> C96 | C38: Loan Term (years) — 2nd | D38: 0
A39: Scenarios | B39: =HYPERLINK("#Scenarios!C97","C97") -> C97 | C39: Interest-Only Period (months) — 2nd | D39: 0
A40: Scenarios | B40: =HYPERLINK("#Scenarios!B98","B98") -> B98 | C40: Origination Fee % — 2nd | D40: 0
A41: Scenarios | B41: =HYPERLINK("#Scenarios!C98","C98") -> C98 | C41: Origination Fee % — 2nd | D41: 0
A42: Scenarios | B42: =HYPERLINK("#Scenarios!C100","C100") -> C100 | C42: Loan Amount — Supplemental ($) | D42: 0
A43: Scenarios | B43: =HYPERLINK("#Scenarios!C101","C101") -> C101 | C43: Interest Rate — Supplemental (%) | D43: 0
...

Sheet Prop Info
A1: =IF('Prop Info'!B4="","PROPERTY INFORMATION & MARKET DATA","PROPERTY INFORMATION & MARKET DATA"&" — "&'Prop Info'!B4) -> PROPERTY INFORMATION & MARKET DATA
A2: Blue = manual input. Use the AI Market Research tool (separate app) to auto-populate market fields.
A3: PROPERTY DETAILS
A4: Property Name
A5: Location / Address
A6: # Units
A7: # Buildings
A8: Height (stories)
A9: Year Built
A10: Lot Size (acres)
A11: Gross Sq Ft
A12: Parking Spaces
A13: Building Class (A/B/C)
... A47: Value-Add Thesis

Sheet Data Refresh
A1: =IF('Prop Info'!B4="","DATA REFRESH — Power Query connections for live market data","DATA REFRESH — Power Query connections for live market data"&" — "&'Prop Info'!B4) -> DATA REFRESH — Power Query connections for live market data
A2: Pulls Census, FRED, and BLS data on demand. Refresh updates these cells in Prop Info automatically.
A4: A. HOW THIS WORKS
A5: 1. Get free API keys (5 min, one-time):
A6: • Census Bureau: https://api.census.gov/data/key_signup.html
A7: • FRED (St. Louis Fed): https://fred.stlouisfed.org/docs/api/api_key.html
A8: • BLS (optional): https://data.bls.gov/registrationEngine/
A10: 2. Open Excel → Data tab → Get Data → From Other Sources → Blank Query → Advanced Editor
A12: 3. Paste the M code from sections B, C, or D below into the editor. Replace YOUR_KEY_HERE with your key.
A14: 4. Name the query (e.g. "Census_Demographics"), click Close & Load → Load To → Existing Worksheet → "_API_Output" tab.
A16: 5. To refresh: Data tab → Refresh All. Prop Info cells will recalculate from latest API data.
A18: 6. To schedule auto-refresh: Data → Connections → Properties → "Refresh every X min" or "Refresh on file open".
A21: B. CENSUS ACS 1-YEAR API — covers 7 of 17 Prop Info cells
A22: Atlanta MSA (CBSA #12060). Returns population, age cohorts, income, household tenure in one call.
A24: Prop Info Cell | B24: Metric | C24: Census ACS Variable | D24: Last Refreshed | E24: Notes
A25: B22 | B25: MSA Population | C25: B01003_001E | D25: (set after refresh) | E25: Total pop, single variable
A26: B23 | B26: City Population | C26: B01003_001E (place geo) | D26: (set after refresh) | E26: Separate query — geography=place:04000
A27: B25 | B27: Renter-Age Pop (25–44) | C27: B01001_011E..014E + _035E..038E | D27: (set after refresh) | E27: Sum 8 male+female age cohorts
A28: B27 | B28: Avg Household Income | C28: B19025_001E / B11001_001E | D28: (set after refresh) | E28: Aggregate income / household count
A29: B28 | B29: Median Income | C29: B19013_001E | D29: (set after refresh) | E29: Direct variable
A30: B37 | B30: Renter Household % | C30: B25003_003E / B25003_001E | D30: (set after refresh) | E30: Renter-occupied / total occupied
A31: B24 | B31: Population Growth Rate | C31: (B01003_001E[year] - B01003_001E[year-1]) / prev | D31: (set after refresh) | E31: Two queries: current year + prior year
A33: M code → paste into Power Query Advanced Editor:
A34: let // ===== USER CONFIGURATION ===== ApiKey = "YOUR_CENSUS_API_KEY", // Free at https://api.census.gov/data/key_signup.html Year = "2024", // Latest ACS 1-year CbsaCode = "12060", // Atlanta-Sandy Springs-Roswell MSA // ===== VARIABLES TO FETCH ===== // B01003_001E = Total population // B01001_011E..014E = Male age 25-44 cohorts (4 brackets) // B01001_035E..038E = Female age 25-44 cohorts (4 brackets) // B19013_001E = Median household income // B19025_001E = Aggregate household income (for mean calc) // B11001_001E = Total households // B25003_001E = Total occupied housing units // B25003_003E = Renter-occupied housing units Vars = "NAME,B01003_001E,B01001_011E,B01001_012E,B01001_013E,B01001_014E,B01001_035E,B01001_036E,B01001_037E,B01001_038E,B19013_001E,B19025_001E,B11001_001E,B25003_001E,B25003_003E", Url = "https://api.census.gov/data/" & Year & "/acs/acs1?get=" & Vars & "&for=metropolitan%20statistical%20area/micropolitan%20statistical%20area:" & CbsaCode & "&key=" & ApiKey, Source = Json.Document(Web.Contents(Url)), Headers = List.Transform(Source{0}, Text.From), Data = List.Transform(List.Skip(Source, 1), each List.Transform(_, Text.From)), Raw = #table(Headers, Data), // Convert numeric columns NumCols = List.RemoveItems(Headers, {"NAME"}), Typed = Table.TransformColumnTypes(Raw, List.Transform(NumCols, each {_, type number})), // ===== DERIVED METRICS ===== Pop = Record.Field(Typed{0}, "B01003_001E"), RenterAge = Record.Field(Typed{0}, "B01001_011E") + Record.Field(Typed{0}, "B01001_012E") + Record.Field(Typed{0}, "B01001_013E") + Record.Field(Typed{0}, "B01001_014E") + Record.Field(Typed{0}, "B01001_035E") + Record.Field(Typed{0}, "B01001_036E") + Record.Field(Typed{0}, "B01001_037E") + Record.Field(Typed{0}, "B01001_038E"), MedInc = Record.Field(Typed{0}, "B19013_001E"), AggInc = Record.Field(Typed{0}, "B19025_001E"), Households = Record.Field(Typed{0}, "B11001_001E"), AvgInc = if Households > 0 then AggInc / Households else null, OccUnits = Record.Field(Typed{0}, "B25003_001E"), RenterUnits = Record.Field(Typed{0}, "B25003_003E"), RenterPct = if OccUnits > 0 then RenterUnits / OccUnits else null, // ===== OUTPUT TABLE ===== Output = #table( {"Metric", "Value", "Source", "Refreshed"}, { {"MSA Population", Pop, "Census ACS B01003_001E", DateTime.LocalNow()}, {"Renter-Age Population (25-44)", RenterAge, "Census ACS B01001 sum", DateTime.LocalNow()}, {"Median Household Income", MedInc, "Census ACS B19013_001E", DateTime.LocalNow()}, {"Avg Household Income", AvgInc, "Census ACS B19025/B11001", DateTime.LocalNow()}, {"Renter Household %", RenterPct, "Census ACS B25003_003/_001E", DateTime.LocalNow()} } ) in Output
A36: C. FRED API — population growth + economic proxies
A37: Use this for time-series data: population growth rate, building permits (supply proxy), employment.
A39: Prop Info Cell | B39: Metric | C39: FRED Series ID | D39: Last Refreshed | E39: Notes
A40: B24 | B40: Population Growth Rate | C40: ATLPOP | D40: (set after refresh) | E40: Annual MSA population — derive YoY %
A41: B36 | B41: Housing Starts (proxy) | C41: ATLA013BPPRIVSA | D41: (set after refresh) | E41: Building permits — proxy for new supply
A42: — | B42: Atlanta unemployment | C42: ATLA013URN | D42: (set after refresh) | E42: Indicates renter income strength
A43: — | B43: Per capita income | C43: PCPI13013 | D43: (set after refresh) | E43: Atlanta MSA per capita personal income
A45: M code → paste into Power Query Advanced Editor:
A46: let // ===== USER CONFIGURATION ===== ApiKey = "YOUR_FRED_API_KEY", // Free at https://fred.stlouisfed.org/docs/api/api_key.html SeriesId = "ATLPOP", // Atlanta MSA Resident Population (annual) Url = "https://api.stlouisfed.org/fred/series/observations?series_id=" & SeriesId & "&api_key=" & ApiKey & "&file_type=json&sort_order=desc&limit=10", Source = Json.Document(Web.Contents(Url)), Observations = Source[observations], Raw = Table.FromRecords(Observations), Typed = Table.TransformColumnTypes(Raw, {{"date", type date}, {"value", type number}}), Sorted = Table.Sort(Typed, {{"date", Order.Descending}}), // Calculate YoY growth rate Latest = Sorted{0}[value], Prior = Sorted{1}[value], Growth = if Prior > 0 then (Latest - Prior) / Prior else null, // Output table Output = #table( {"Metric", "Value", "Source", "AsOf", "Refreshed"}, { {"Latest Population", Latest, "FRED " & SeriesId, Sorted{0}[date], DateTime.LocalNow()}, {"Prior Year Population", Prior, "FRED " & SeriesId, Sorted{1}[date], DateTime.LocalNow()}, {"YoY Growth Rate", Growth, "FRED derived", Sorted{0}[date], DateTime.LocalNow()} } ) in Output
A48: D. WIRE API OUTPUT INTO PROP INFO — formula pattern
A49: After Power Query loads to a sheet (e.g. '_API_Output'), replace Prop Info column B with formulas like:
A51: Cell | B51: Formula | D51: Pulls
A52: Prop Info!B22 | B52: =INDEX(_api_output!b:b, MATCH("MSA Population", _api_output!a:a, 0)) | D52: Pull MSA pop from Census query output
A53: Prop Info!B25 | B53: =INDEX(_api_output!b:b, MATCH("Renter-Age Population (25-44)", _api_output!a:a, 0)) | D53: Pull renter-age count
A54: Prop Info!B28 | B54: =INDEX(_api_output!b:b, MATCH("Median Household Income", _api_output!a:a, 0)) | D54: Pull median income
A55: Prop Info!B37 | B55: =INDEX(_api_output!b:b, MATCH("Renter Household %", _api_output!a:a, 0)) | D55: Pull renter %
...

Sheet Data Checklist
A1: =IF('Prop Info'!B4="","DATA CHECKLIST — Due Diligence Tracker","DATA CHECKLIST — Due Diligence Tracker"&" — "&'Prop Info'!B4) -> DATA CHECKLIST — Due Diligence Tracker
A2: Track every DD item from request through review. Status dropdown drives % complete and color flags. Cross-Check column shows reconciliation formulas where relevant.
F3: Total Items | G3: Complete | H3: % Complete | I3: Critical Open | J3: Status
F4: =COUNT(A7:A97) -> 74 | G4: =COUNTIF(C7:C97,"Complete")+COUNTIF(C7:C97,"N/A") -> 0 | H4: =IFERROR(G4/F4,0) -> 0 | I4: =SUMPRODUCT((LEFT(B7:B97,1)="⚠")*(C7:C97<>"Complete")*(C7:C97<>"N/A")) -> 32 | J4: =IF(I4>5,"🔴 many critical open",IF(I4>0,"🟡 critical items pending","🟢 critical items resolved")) -> 🔴 many critical open
A6: # | B6: Item | C6: Status | D6: Date Requested | E6: Date Received | F6: Source / Counterparty | G6: Format | H6: Reviewer | I6: Cross-Check / Reconciliation | J6: Notes
A7: A. FINANCIAL STATEMENTS
A8: 1 | B8: ⚠ Trailing 12 (T-12) — current month-end | C8: Not Requested | I8: =IF('T-12 Analysis'!N80>0,"✓ EGI loaded $"&TEXT('T-12 Analysis'!N80,"#,##0"),"⚠ T-12 not loaded") -> ⚠ T-12 not loaded | J8: PSI/Yardi cash basis Apr 2025-Mar 2026
A9: 2 | B9: ⚠ Trailing 3 (T-3) — current month-end | C9: Not Requested | I9: =IF('T-12 Analysis'!O80>0,"✓ T-3 derived from T-12","derive from T-12 monthly") -> derive from T-12 monthly | J9: Derived from T-12 monthly columns
A10: 3 | B10: Year-to-Date Income Statement (current FY) | C10: Not Requested | J10: YTD compared to prior year same period
A11: 4 | B11: Prior Year (Y-1) Annual Income Statement | C11: Not Requested | J11: For T-12 trend comparison
A12: 5 | B12: Prior Year (Y-2) Annual Income Statement | C12: Not Requested | J12: Validates 3-year trajectory
A13: 6 | B13: Budget vs Actual — current FY | C13: Not Requested | J13: Reveals operator forecasting accuracy
A14: 7 | B14: General Ledger (current FY) | C14: Not Requested | J14: For deep-dive on individual accounts
A15: 8 | B15: Bank Statements (last 3 months) | C15: Not Requested | J15: For revenue verification
A16: 9 | B16: Tax Returns (last 2 years) | C16: Not Requested | J16: Form 8825 / Schedule E
A18: B. RENT ROLL & ACCOUNTS RECEIVABLE
A19: 10 | B19: ⚠ Current Rent Roll (with all status detail) | C19: Received | I19: =IF('Rent Roll Analysis'!I5>0,"✓ "&'Rent Roll Analysis'!I5&" units in RR vs "&'Rent Roll Analysis'!G5&" total","⚠ RR not loaded") -> ⚠ RR not loaded | J19: As of 4/16/2026
A20: 11 | B20: ⚠ Detailed AR Aging (0-30, 31-60, 61-90, 90+) | C20: Received | I20: =IF('Rent Roll Analysis'!C94>0,"✓ Total AR $"&TEXT('Rent Roll Analysis'!C94,"#,##0"),"⚠ AR not loaded") -> ⚠ AR not loaded | J20: In rent roll columns Q-T
A21: 12 | B21: ⚠ Eviction Status Report | C21: Received | I21: =IF('Rent Roll Analysis'!B113>0,"✓ "&'Rent Roll Analysis'!B113&" units flagged for legal/eviction (** in source)","none flagged") -> none flagged | J21: 9 active evictions, 1 bankruptcy known
A22: 13 | B22: Lease Files / Tenant Files (sample) | C22: Not Requested | J22: Pull random sample of 10-15 leases
A23: 14 | B23: ⚠ Bankruptcy / Litigation Disclosures | C23: Received | I23: =IF('Rent Roll Analysis'!D113>0,"⚠ $"&TEXT('Rent Roll Analysis'!D113,"#,##0")&" AR exposure on legal cohort","none on record") -> none on record | J23: Smith N6 Ch 7 filed 3/28/26
A24: 15 | B24: Concession Log (last 12 months) | C24: Not Requested | J24: Reconcile to T-12 concession lines
A25: 16 | B25: Move-In/Move-Out Report (last 12 months) | C25: Not Requested | J25: For turnover rate calculation
A26: 17 | B26: Pre-Paid Rent / Security Deposits Schedule | C26: Not Requested | J26: Liability transfer at closing
A27: 18 | B27: Delinquency History (24 months) | C27: Not Requested | J27: Trend analysis on collection
A29: C. OPERATING EXPENSE DETAIL
A30: 19 | B30: ⚠ Property Tax Bills (last 2 years) | C30: Not Requested | J30: Validate accrual + millage rate
A31: 20 | B31: ⚠ Property Tax Reassessment Estimate | C31: Not Requested | J31: Critical: post-sale reassessment
A32: 21 | B32: ⚠ Insurance Policy & Premium Detail | C32: Not Requested | J32: Validate insurance line + coverage
A33: 22 | B33: ⚠ Insurance Loss Runs (5 years) | C33: Not Requested | J33: Material claims history
A34: 23 | B34: ⚠ Utility Bills (Water/Electric/Gas — 12 months) | C34: Not Requested | I34: =IF('T-12 Analysis'!P96>70,"⚠ water $"&TEXT('T-12 Analysis'!P96,"0.00")&" PUPM — investigate","ok") -> ok | J34: Water bill $198K — investigate leak
A35: 24 | B35: Trash / Recycling Contract | C35: Not Requested
A36: 25 | B36: Pest Control Contract | C36: Not Requested
A37: 26 | B37: Landscaping Contract | C37: Not Requested
A38: 27 | B38: Property Management Agreement | C38: Not Requested | J38: Termination notice required for sale
A39: 28 | B39: Service Contracts — All | C39: Not Requested | J39: Pool, elevator, HVAC, security, etc.
A40: 29 | B40: Vendor Invoices (sample, last 6 months) | C40: Not Requested | J40: For expense verification
A41: 30 | B41: ⚠ Payroll Register (current employees) | C41: Not Requested | J41: On-site staff & wages
A42: 31 | B42: Employee Benefits Schedule | C42: Not Requested | J42: Healthcare, 401k contribution
A44: D. CAPITAL EXPENDITURES
...

Sheet Scenarios
A1: =IF('Prop Info'!B4="","SIDE-BY-SIDE SCENARIO ANALYSIS — ""The 10-Minute Offer""","SIDE-BY-SIDE SCENARIO ANALYSIS — ""The 10-Minute Offer"""&" — "&'Prop Info'!B4) -> SIDE-BY-SIDE SCENARIO ANALYSIS — "The 10-Minute Offer"
A2: Active Scenario → | B2: 1. T-12 Actuals
A3: Selecting an active scenario drives P&L, Cover Sheet, and Sensitivity tabs. Column B = T-12 Actuals (last 12 months, hardwired to T-12 Analysis). Yellow cells have explanatory comments — hover to see source mapping.
A4: Line Item | B4: 1. T-12 Actuals | C4: 2. My Version | D4: 3. Projected | E4: 4. Offer | F4: Active Scenario | G4: $/Unit | H4: Benchmark
A5: ACQUISITION
A6: Asking Price | C6: =IFERROR(B6,0) -> 0 | D6: =IFERROR(C6,0) -> 0 | E6: =IFERROR(D6,0) -> 0 | F6: =IFERROR(CHOOSE(MATCH(B$2,{"1. T-12 Actuals","2. My Version","3. Projected","4. Offer"},0),B6,C6,D6,E6),0) -> 0 | G6: =IFERROR(IF((B6/Units)=0,"",(B6/Units)),"") | H6: $5–100M+ MF; Class A 250-unit typically $40–100M
A7: Purchase Price / Offer | C7: =IFERROR(B7,0) -> 0 | D7: =IFERROR(C7,0) -> 0 | E7: =IFERROR(D7,0) -> 0 | F7: =IFERROR(CHOOSE(MATCH(B$2,{"1. T-12 Actuals","2. My Version","3. Projected","4. Offer"},0),B7,C7,D7,E7),0) -> 0 | G7: =IFERROR(IF((B7/Units)=0,"",(B7/Units)),"") | H7: Offer 3–8% below ask; value-add plays
A8: # Units | B8: =IFERROR('Prop Info'!B6,0) -> 0 | C8: =IFERROR(Units,0) -> 0 | D8: =IFERROR(C8,0) -> 0 | E8: =IFERROR(D8,0) -> 0 | F8: =IFERROR(CHOOSE(MATCH(B$2,{"1. T-12 Actuals","2. My Version","3. Projected","4. Offer"},0),B8,C8,D8,E8),0) -> 0 | G8: =IFERROR(IF(('Prop Info'!$B$6)=0,"",('Prop Info'!$B$6)),"") | H8: Total unit count — drives GPR and all per-unit metrics
A9: Price Per Unit | B9: =IFERROR(IFERROR(B7/B8,0),0) -> 0 | C9: =IFERROR(IFERROR(C7/C8,0),0) -> 0 | D9: =IFERROR(IFERROR(D7/D8,0),0) -> 0 | E9: =IFERROR(IFERROR(E7/E8,0),0) -> 0 | F9: =IFERROR(CHOOSE(MATCH(B$2,{"1. T-12 Actuals","2. My Version","3. Projected","4. Offer"},0),B9,C9,D9,E9),0) -> 0 | G9: =IFERROR(IF((IFERROR(F7/'Prop Info'!$B$6,0))=0,"",(IFERROR(F7/'Prop Info'!$B$6,0))),"") | H9: Class A: $200–400k/door; Class B: $100–200k/door
A10: Down Payment % | B10: 0.2 | C10: =IFERROR(B10,0) -> 0.2 | D10: =IFERROR(C10,0) -> 0.2 | E10: =IFERROR(D10,0) -> 0.2 | F10: =IFERROR(CHOOSE(MATCH(B$2,{"1. T-12 Actuals","2. My Version","3. Projected","4. Offer"},0),B10,C10,D10,E10),0) -> 0.2 | H10: 25–35% down; 65–75% LTV target
A11: Down Payment $ | B11: =IFERROR(B10*B7,0) -> 0 | C11: =IFERROR(C10*C7,0) -> 0 | D11: =IFERROR(D10*D7,0) -> 0 | E11: =IFERROR(E10*E7,0) -> 0 | F11: =IFERROR(CHOOSE(MATCH(B$2,{"1. T-12 Actuals","2. My Version","3. Projected","4. Offer"},0),B11,C11,D11,E11),0) -> 0 | H11: Auto-calculated from down payment
A12: Repairs / CapEx at Close | B12: =IFERROR(Capex!$D$51,0) -> 0 | C12: =IFERROR(Capex!$D$51,0) -> 0 | D12: =IFERROR(Capex!$D$51,0) -> 0 | E12: =IFERROR(Capex!$D$51,0) -> 0 | F12: =IFERROR(CHOOSE(MATCH(B$2,{"1. T-12 Actuals","2. My Version","3. Projected","4. Offer"},0),B12,C12,D12,E12),0) -> 0 | H12: Get contractor bid at LOI stage
A13: Operating Reserves | B13: =IFERROR((B70/12)*G13,0) -> 0 | C13: =B13 -> 0 | D13: =C13 -> 0 | E13: =D13 -> 0 | F13: =IFERROR(CHOOSE(MATCH(B$2,{"1. T-12 Actuals","2. My Version","3. Projected","4. Offer"},0),B13,C13,D13,E13),0) -> 0 | G13: 1 | H13: 3–6 months operating expenses
A14: Est. Closing Costs | B14: =IFERROR('Acquisition Costs'!$D$35,0) -> 0 | C14: =IFERROR('Acquisition Costs'!$D$35,0) -> 0 | D14: =IFERROR('Acquisition Costs'!$D$35,0) -> 0 | E14: =IFERROR('Acquisition Costs'!$D$35,0) -> 0 | F14: =IFERROR(CHOOSE(MATCH(B$2,{"1. T-12 Actuals","2. My Version","3. Projected","4. Offer"},0),B14,C14,D14,E14),0) -> 0 | G14: =IFERROR(IF((IFERROR(F14/F7,0))=0,"",(IFERROR(F14/F7,0))),"") | H14: 1.5–2.5% of purchase price
A15: Acquisition Fee (%) | B15: 0.02 | C15: =IFERROR(B15,0) -> 0.02 | D15: =IFERROR(C15,0) -> 0.02 | E15: =IFERROR(D15,0) -> 0.02 | F15: =IFERROR(CHOOSE(MATCH(B$2,{"1. T-12 Actuals","2. My Version","3. Projected","4. Offer"},0),B15,C15,D15,E15),0) -> 0.02 | H15: 0.5–1.5% acquisition fee standard
A16: Acquisition Fee ($) | B16: =IFERROR(B15*B7,0) -> 0 | C16: =IFERROR(C15*C7,0) -> 0 | D16: =IFERROR(D15*D7,0) -> 0 | E16: =IFERROR(E15*E7,0) -> 0 | F16: =IFERROR(CHOOSE(MATCH(B$2,{"1. T-12 Actuals","2. My Version","3. Projected","4. Offer"},0),B16,C16,D16,E16),0) -> 0 | H16: Auto-calculated
A17: TOTAL ACQUISITION COST | B17: =IFERROR(B7+IFERROR(VALUE(B12),0)+IFERROR(VALUE(B13),0)+IFERROR(VALUE(B14),0)+IFERROR(VALUE(B16),0),"") -> 0 | C17: =IFERROR(C7+IFERROR(VALUE(C12),0)+IFERROR(VALUE(C13),0)+IFERROR(VALUE(C14),0)+IFERROR(VALUE(C16),0),"") -> 0 | D17: =IFERROR(D7+IFERROR(VALUE(D12),0)+IFERROR(VALUE(D13),0)+IFERROR(VALUE(D14),0)+IFERROR(VALUE(D16),0),"") -> 0 | E17: =IFERROR(E7+IFERROR(VALUE(E12),0)+IFERROR(VALUE(E13),0)+IFERROR(VALUE(E14),0)+IFERROR(VALUE(E16),0),"") -> 0 | F17: =IFERROR(CHOOSE(MATCH(B$2,{"1. T-12 Actuals","2. My Version","3. Projected","4. Offer"},0),B17,C17,D17,E17),0) -> 0 | H17: Auto-calculated total cost
A19: DEBT STRUCTURE
A20: Loan Amount (1st) | B20: =IFERROR(B88,0) -> 0 | C20: =IFERROR(C88,0) -> 0 | D20: =IFERROR(D88,0) -> 0 | E20: =IFERROR(E88,0) -> 0 | F20: =IFERROR(CHOOSE(MATCH(B$2,{"1. T-12 Actuals","2. My Version","3. Projected","4. Offer"},0),B20,C20,D20,E20),0) -> 0 | H20: 65–75% LTV; Agency (FNMA/FHLMC) or CMBS/bridge
A21: Loan Amount (2nd) | B21: =IFERROR(B95,0) -> 0 | C21: =IFERROR(C95,0) -> 0 | D21: =IFERROR(D95,0) -> 0 | E21: =IFERROR(E95,0) -> 0 | F21: =IFERROR(CHOOSE(MATCH(B$2,{"1. T-12 Actuals","2. My Version","3. Projected","4. Offer"},0),B21,C21,D21,E21),0) -> 0 | H21: $0 if no mezz; up to 10% of stack
A22: Supplemental Loan | B22: =IFERROR(B102,0) -> 0 | C22: =IFERROR(C102,0) -> 0 | D22: =IFERROR(D102,0) -> 0 | E22: =IFERROR(E102,0) -> 0 | F22: =IFERROR(CHOOSE(MATCH(B$2,{"1. T-12 Actuals","2. My Version","3. Projected","4. Offer"},0),B22,C22,D22,E22),0) -> 0 | H22: $0 supplemental; add if SBA/seller
A23: Total Debt | B23: =IFERROR(B20+B21+B22,0) -> 0 | C23: =IFERROR(C20+C21+C22,0) -> 0 | D23: =IFERROR(D20+D21+D22,0) -> 0 | E23: =IFERROR(E20+E21+E22,0) -> 0 | F23: =IFERROR(CHOOSE(MATCH(B$2,{"1. T-12 Actuals","2. My Version","3. Projected","4. Offer"},0),B23,C23,D23,E23),0) -> 0 | H23: Auto-calculated total debt
A24: LTV (Loan/Purchase Price) | B24: =IFERROR(IFERROR(B23/B7,0),0) -> 0 | C24: =IFERROR(IFERROR(C23/C7,0),0) -> 0 | D24: =IFERROR(IFERROR(D23/D7,0),0) -> 0 | E24: =IFERROR(IFERROR(E23/E7,0),0) -> 0 | F24: =IFERROR(CHOOSE(MATCH(B$2,{"1. T-12 Actuals","2. My Version","3. Projected","4. Offer"},0),B24,C24,D24,E24),0) -> 0 | H24: Target ≤75% LTV; agency max 80%
A25: LTC (Loan/Total Acq. Cost) | B25: =IFERROR(IFERROR(B23/B17,0),0) -> 0 | C25: =IFERROR(IFERROR(C23/C17,0),0) -> 0 | D25: =IFERROR(IFERROR(D23/D17,0),0) -> 0 | E25: =IFERROR(IFERROR(E23/E17,0),0) -> 0 | F25: =IFERROR(CHOOSE(MATCH(B$2,{"1. T-12 Actuals","2. My Version","3. Projected","4. Offer"},0),B25,C25,D25,E25),0) -> 0 | H25: Target ≤85% LTC (value-add); 75–80% stabilized
A27: EQUITY STRUCTURE
A28: GP Ownership % | B28: 0.3 | C28: 0.3 | D28: =IFERROR(C28,0) -> 0.3 | E28: =IFERROR(D28,0) -> 0.3 | F28: =IFERROR(CHOOSE(MATCH(B$2,{"1. T-12 Actuals","2. My Version","3. Projected","4. Offer"},0),B28,C28,D28,E28),0) -> 0.3 | H28: GP co-invest 5–20% of total equity
A29: Class A LP % | B29: =IFERROR(1-B28,0) -> 0.7 | C29: =IFERROR(1-C28,0) -> 0.7 | D29: =IFERROR(1-D28,0) -> 0.7 | E29: =IFERROR(1-E28,0) -> 0.7 | F29: =IFERROR(CHOOSE(MATCH(B$2,{"1. T-12 Actuals","2. My Version","3. Projected","4. Offer"},0),B29,C29,D29,E29),0) -> 0.7 | H29: Class A LP 40–70% of total equity
A30: Class B LP % (auto) | B30: =IFERROR(1-B28-B29,0) -> 0 | C30: =IFERROR(1-C28-C29,0) -> 0 | D30: =IFERROR(1-D28-D29,0) -> 0 | E30: =IFERROR(1-E28-E29,0) -> 0 | F30: =IFERROR(CHOOSE(MATCH(B$2,{"1. T-12 Actuals","2. My Version","3. Projected","4. Offer"},0),B30,C30,D30,E30),0) -> 0 | H30: Class B LP 20–40% of total equity
A31: Total Equity (Acq Cost − Debt) | B31: =IFERROR(IFERROR(B17-B117,0),0) -> 0 | C31: =IFERROR(IFERROR(C17-C117,0),0) -> 0 | D31: =IFERROR(IFERROR(D17-D117,0),0) -> 0 | E31: =IFERROR(IFERROR(E17-E117,0),0) -> 0 | F31: =IFERROR(CHOOSE(MATCH(B$2,{"1. T-12 Actuals","2. My Version","3. Projected","4. Offer"},0),B31,C31,D31,E31),0) -> 0 | H31: Auto-calculated
A32: GP Equity ($) | B32: 0 | C32: =B32 -> 0 | D32: =C32 -> 0 | E32: =D32 -> 0 | F32: =IFERROR(CHOOSE(MATCH(B$2,{"1. T-12 Actuals","2. My Version","3. Projected","4. Offer"},0),B32,C32,D32,E32),0) -> 0 | H32: Enter GP co-invest $ directly — not tied to GP Ownership %
A33: Class A LP Equity ($) | B33: =IFERROR(B31-B32,0) -> 0 | C33: =IFERROR(C31-C32,0) -> 0 | D33: =IFERROR(D31-D32,0) -> 0 | E33: =IFERROR(E31-E32,0) -> 0 | F33: =IFERROR(CHOOSE(MATCH(B$2,{"1. T-12 Actuals","2. My Version","3. Projected","4. Offer"},0),B33,C33,D33,E33),0) -> 0 | H33: Total Equity − GP co-invest. GP can be $0 (all-LP deal).
A34: Class B LP Equity ($) | B34: =IFERROR(B30*B31,0) -> 0 | C34: =IFERROR(C30*C31,0) -> 0 | D34: =IFERROR(D30*D31,0) -> 0 | E34: =IFERROR(E30*E31,0) -> 0 | F34: =IFERROR(CHOOSE(MATCH(B$2,{"1. T-12 Actuals","2. My Version","3. Projected","4. Offer"},0),B34,C34,D34,E34),0) -> 0 | H34: Auto-calculated
A35: Class A Preferred Return % | F35: =IFERROR(CHOOSE(MATCH(B$2,{"1. T-12 Actuals","2. My Version","3. Projected","4. Offer"},0),B35,C35,D35,E35),0) -> 0 | H35: Class A pref: 6–8% typical MF PE
A36: Class B Preferred Return % | F36: =IFERROR(CHOOSE(MATCH(B$2,{"1. T-12 Actuals","2. My Version","3. Projected","4. Offer"},0),B36,C36,D36,E36),0) -> 0 | H36: Class B pref (subordinated); 0 if no Class B equity
A37: GP Promote % (defaults to GP% — edit to override) | B37: =IFERROR(B28,0) -> 0.3 | C37: =IFERROR(C28,0) -> 0.3 | D37: =IFERROR(D28,0) -> 0.3 | E37: =IFERROR(E28,0) -> 0.3 | F37: =IFERROR(CHOOSE(MATCH(B$2,{"1. T-12 Actuals","2. My Version","3. Projected","4. Offer"},0),B37,C37,D37,E37),0) -> 0.3 | H37: Promote: 20–30% GP typical
A38: INCOME (YEAR 1 SNAPSHOT) — Revenue is per UNIT, not per bed
A39: Avg Monthly Rent / Unit (at 100% occupancy) | B39: =IFERROR(C39,0) -> 0 | C39: =IFERROR(IFERROR(IF('T-12 Analysis'!N58>=MAX('Rent Roll Analysis'!B26,'Rent Roll Analysis'!B34)*0.95,'T-12 Analysis'!N58,MAX('Rent Roll Analysis'!B26,'Rent Roll Analysis'!B34))/12/'Prop Info'!$B$6,0),0) -> 0 | D39: =IFERROR('Rent Roll Analysis'!C34,0) -> 0 | E39: =IFERROR(D39,0) -> 0 | F39: =IFERROR(CHOOSE(MATCH(B$2,{"1. T-12 Actuals","2. My Version","3. Projected","4. Offer"},0),B39,C39,D39,E39),0) -> 0 | H39: Avg rent × total units × 12 = max revenue potential | I39: C38 benchmark = MAX(RR Market GPR, Occupied Scheduled GPR). If residents pay above listed market rent, occupied scheduled is the truer market. T-12 credibility check and fallback both use this MAX. B38 = T-12 actuals (unchanged).
A40: Gross Potential Rent (at 100% unit occupancy) | B40: =IFERROR('Prop Info'!$B$6*B39*12,0) -> 0 | C40: =IFERROR('Prop Info'!$B$6*C39*12,0) -> 0 | D40: =IFERROR('Prop Info'!$B$6*D39*12,0) -> 0 | E40: =IFERROR('Prop Info'!$B$6*E39*12,0) -> 0 | F40: =IFERROR(CHOOSE(MATCH(B$2,{"1. T-12 Actuals","2. My Version","3. Projected","4. Offer"},0),B40,C40,D40,E40),0) -> 0 | H40: Units × avg rent × 12 — maximum revenue at 100% occupancy
A41: Unit Vacancy % (unoccupied units ÷ total units) | B41: =IFERROR(C41,0) -> 0 | C41: =IFERROR(IFERROR(('Rent Roll Analysis'!B13+'Rent Roll Analysis'!B14)/'Prop Info'!$B$6,0),0) -> 0 | D41: =IFERROR(C41,0) -> 0 | E41: =IFERROR(D41,0) -> 0 | F41: =IFERROR(CHOOSE(MATCH(B$2,{"1. T-12 Actuals","2. My Version","3. Projected","4. Offer"},0),B41,C41,D41,E41),0) -> 0 | H41: Class A target 5–8%; value-add 10–15% at acquisition
A42: Vacancy ($) | B42: =IFERROR(-B41*B40,0) -> 0 | C42: =IFERROR(-C41*C40,0) -> 0 | D42: =IFERROR(-D41*D40,0) -> 0 | E42: =IFERROR(-E41*E40,0) -> 0 | F42: =IFERROR(CHOOSE(MATCH(B$2,{"1. T-12 Actuals","2. My Version","3. Projected","4. Offer"},0),B42,C42,D42,E42),0) -> 0
...

Sheet Acquisition Costs
A1: =IF('Prop Info'!B4="","ACQUISITION COSTS — USE OF CAPITAL","ACQUISITION COSTS — USE OF CAPITAL"&" — "&'Prop Info'!B4) -> ACQUISITION COSTS — USE OF CAPITAL
A3: USE OF CAPITAL SUMMARY
A4: Purchase Price | D4: =Scenarios!F7 -> 0
A5: Less: Total Loan Amount | D5: =-Scenarios!F116 -> 0
A6: Down Payment Required | D6: =D4+D5 -> 0
A7: Closing Costs | D7: =D35 -> 0
A8: Acquisition Fee | B8: =Scenarios!F15 -> 0.02 | D8: =Scenarios!F16 -> 0
A9: Repair Escrow / CapEx | D9: =Scenarios!F12 -> 0
A10: Operating Reserves | D10: =IFERROR(Scenarios!F13,0) -> 0
A11: TOTAL CASH AT CLOSE | D11: =SUM(D6:D10) -> 0
A13: CLOSING COSTS DETAIL
A14: Item | B14: Rate/Factor | C14: Notes | D14: Amount
A15: LENDER FEES & THIRD-PARTY COSTS
A16: Environmental (EDR) | C16: Phase I ESA — flat fee | D16: 3500
A17: Appraisal | C17: Commercial appraisal — flat fee | D17: 6500
A18: Structural Inspection | C18: PCA / structural — flat fee | D18: 4500
A19: Lender Legal Fees | C19: Lender counsel — flat fee | D19: 15000
A20: Bank Doc Prep Fee | C20: Lender doc prep — flat fee | D20: 2500
A21: Origination Fee | B21: =Loans!B9 -> 0.01 | C21: Total origination fees — all tranches | D21: =Loans!E10 -> 0
A22: TITLE & CLOSING COSTS
A23: Title Policy | B23: 0.003 | C23: 0.30% of purchase price | D23: =B23*Scenarios!F7 -> 0
A24: Survey | C24: ALTA survey — flat fee | D24: 5000
A25: Recording | C25: Recording fees — flat fee | D25: 1500
A26: Transfer Taxes | B26: 0.0035 | C26: 0.35% of purchase price | D26: =B26*Scenarios!F7 -> 0
A27: Title Processing Fee | C27: Title processing — flat fee | D27: 750
A28: Title Search | C28: Title search — flat fee | D28: 500
A29: Attorney Fees | C29: Buyer's counsel — flat fee | D29: 12500
A30: OTHER COSTS
A31: Legal (LLC, PPM, OA) | C31: Sponsor legal — LLC formation, PPM, operating agreement | D31: 7500
A32: Property Inspection | C32: Buyer property walks & unit inspections — flat estimate | D32: 3500
A33: Travel | C33: Sponsor travel & DD logistics — flat estimate | D33: 7500
A34: Miscellaneous | B34: 0.005 | C34: Contingency — % of Purchase Price for unknowns | D34: =B34*Scenarios!F7 -> 0
A35: TOTAL CLOSING & OTHER COSTS | D35: =IF(Scenarios!$F$7=0,0,SUM(D16:D34)) -> 0

Sheet T-12 Analysis
A1: =IF('Prop Info'!B4="","T-12 ANALYSIS — Trailing 12 Diagnostic Layer","T-12 ANALYSIS — Trailing 12 Diagnostic Layer"&" — "&'Prop Info'!B4) -> T-12 ANALYSIS — Trailing 12 Diagnostic Layer
A2: ANALYSIS on top. Standardized aggregation (Layer 3) and raw paste block (Layer 1) below — scroll down to access data.
A4: B. RECONCILIATION CHECK — Are all raw lines mapped?
A5: EGI: | B5: =N80 -> 0 | C5: OpEx: | D5: =N100 -> 0 | E5: NOI: | F5: =N101 -> 0 | G5: Unmapped $: | H5: =SUMIF(P106:P255,"",O106:O255)+SUMIF(P106:P255,"— UNMAPPED —",O106:O255) -> 0 | I5: =IF(ABS(H5)<1,"🟢 all mapped","🔴 mapping incomplete") -> 🟢 all mapped | L5: EGI/Unit/Mo: | M5: =IFERROR(N80/12/'Prop Info'!$B$6,0) -> 0
A7: C. TREND ANALYSIS — T-3 vs. T-6 vs. T-12 (annualized)
A8: Metric | B8: T-12 Actual | C8: T-6 Annlzd | D8: T-3 Annlzd | E8: T-3 vs T-12 Δ$ | F8: T-3 vs T-12 Δ% | G8: Direction | H8: Read
A9: EGI | B9: =N80 -> 0 | C9: =SUM(H80:M80)*2 -> 0 | D9: =SUM(K80:M80)*4 -> 0 | E9: =D9-B9 -> 0 | F9: =IFERROR(D9/B9-1,0) -> 0 | G9: =IF(F9>0.05,"↑ rising",IF(F9<-0.05,"↓ falling","→ stable")) -> → stable | H9: =IF(F9>0.1,"improving",IF(F9<-0.1,"⚠ deteriorating","stable")) -> stable
A10: Total OpEx | B10: =N100 -> 0 | C10: =SUM(H100:M100)*2 -> 0 | D10: =SUM(K100:M100)*4 -> 0 | E10: =D10-B10 -> 0 | F10: =IFERROR(D10/B10-1,0) -> 0 | G10: =IF(F10>0.05,"↑ rising",IF(F10<-0.05,"↓ falling","→ stable")) -> → stable | H10: =IF(F10>0.1,"⚠ deteriorating",IF(F10<-0.1,"improving","stable")) -> stable
A11: NOI | B11: =N101 -> 0 | C11: =SUM(H101:M101)*2 -> 0 | D11: =SUM(K101:M101)*4 -> 0 | E11: =D11-B11 -> 0 | F11: =IFERROR(D11/B11-1,0) -> 0 | G11: =IF(F11>0.05,"↑ rising",IF(F11<-0.05,"↓ falling","→ stable")) -> → stable | H11: =IF(F11>0.1,"improving",IF(F11<-0.1,"⚠ deteriorating","stable")) -> stable
A12: Bad Debt + Write-offs | B12: =N65 -> 0 | C12: =SUM(H65:M65)*2 -> 0 | D12: =SUM(K65:M65)*4 -> 0 | E12: =D12-B12 -> 0 | F12: =IFERROR(D12/B12-1,0) -> 0 | G12: =IF(F12>0.05,"↑ rising",IF(F12<-0.05,"↓ falling","→ stable")) -> → stable | H12: =IF(F12>0.1,"⚠ deteriorating",IF(F12<-0.1,"improving","stable")) -> stable
A13: Water & Sewer | B13: =N96 -> 0 | C13: =SUM(H96:M96)*2 -> 0 | D13: =SUM(K96:M96)*4 -> 0 | E13: =D13-B13 -> 0 | F13: =IFERROR(D13/B13-1,0) -> 0 | G13: =IF(F13>0.05,"↑ rising",IF(F13<-0.05,"↓ falling","→ stable")) -> → stable | H13: =IF(F13>0.1,"⚠ deteriorating",IF(F13<-0.1,"improving","stable")) -> stable
A14: Payroll | B14: =N88 -> 0 | C14: =SUM(H88:M88)*2 -> 0 | D14: =SUM(K88:M88)*4 -> 0 | E14: =D14-B14 -> 0 | F14: =IFERROR(D14/B14-1,0) -> 0 | G14: =IF(F14>0.05,"↑ rising",IF(F14<-0.05,"↓ falling","→ stable")) -> → stable | H14: =IF(F14>0.1,"⚠ deteriorating",IF(F14<-0.1,"improving","stable")) -> stable
A15: Repairs & Maintenance | B15: =N82 -> 0 | C15: =SUM(H82:M82)*2 -> 0 | D15: =SUM(K82:M82)*4 -> 0 | E15: =D15-B15 -> 0 | F15: =IFERROR(D15/B15-1,0) -> 0 | G15: =IF(F15>0.05,"↑ rising",IF(F15<-0.05,"↓ falling","→ stable")) -> → stable | H15: =IF(F15>0.1,"⚠ deteriorating",IF(F15<-0.1,"improving","stable")) -> stable
A16: Make-Ready | B16: =N87 -> 0 | C16: =SUM(H87:M87)*2 -> 0 | D16: =SUM(K87:M87)*4 -> 0 | E16: =D16-B16 -> 0 | F16: =IFERROR(D16/B16-1,0) -> 0 | G16: =IF(F16>0.05,"↑ rising",IF(F16<-0.05,"↓ falling","→ stable")) -> → stable | H16: =IF(F16>0.1,"⚠ deteriorating",IF(F16<-0.1,"improving","stable")) -> stable
A18: D. ECONOMIC vs. PHYSICAL OCCUPANCY RECONCILIATION
A19: Total Units | B19: ='Prop Info'!$B$6 -> 0
A20: Physically Occupied Units | B20: ='Rent Roll Analysis'!T5 -> 0
A21: Physical Occupancy % | B21: =IFERROR(B20/B19,0) -> 0
A22: Gross Potential Rent (annual) | B22: =N58 -> 0
A23: Gross Rent Billed (Net Rent Rev) | B23: =N67 -> 0
A24: Total Revenue (EGI) | B24: =N80 -> 0
A25: Economic Occupancy % (Net Rent / GPR) | B25: =IFERROR(B23/B22,0) -> 0
A26: Economic vs. Physical Gap | B26: =B21-B25 -> 0
A27: → Lost Revenue from Gap ($) | B27: =B26*B22 -> 0
A29: E. BAD DEBT & WRITE-OFF LAYERED ANALYSIS
A30: Component | B30: Amount | C30: % of GPR | D30: PUPM | E30: Benchmark | F30: Read
A31: Vacancy Loss | B31: =ABS(N60) -> 0 | C31: =IFERROR(B31/N58,0) -> 0 | D31: =IFERROR(B31/12/'Prop Info'!$B$6,0) -> 0 | E31: 5-8% GPR
A32: Bad Debt / Write-offs | B32: =ABS(N65) -> 0 | C32: =IFERROR(B32/N58,0) -> 0 | D32: =IFERROR(B32/12/'Prop Info'!$B$6,0) -> 0 | E32: 1-3% GPR
A33: Concessions | B33: =ABS(N63) -> 0 | C33: =IFERROR(B33/N58,0) -> 0 | D33: =IFERROR(B33/12/'Prop Info'!$B$6,0) -> 0 | E33: 0.5-2% GPR
