Workbook

Sheet Dashboard
O1: Care Type | P1: Property | Q1: Market
B2: ="UNDERWRITING DASHBOARD"&IF(AND(ISTEXT(Cover!B5),Cover!B5<>"")," — "&Cover!B5,"") | O2: Independent Living | P2: =IFERROR(IF('T12 Analytics'!B6>0,'T12 Analytics'!B11/'T12 Analytics'!B6,NA()),NA()) | Q2: 0.91
B3: ="Period: "&IF(AND(ISTEXT('T12 Analytics'!E2),'T12 Analytics'!E2<>""),'T12 Analytics'!E2,"T12")&" | Basis: "&IF(AND(ISTEXT('T12 Analytics'!H2),'T12 Analytics'!H2<>""),'T12 Analytics'!H2,"As-Reported")&" | Refreshed: "&TEXT(TODAY(),"mmm d, yyyy") | O3: Assisted Living | P3: =IFERROR(IF('T12 Analytics'!C6>0,'T12 Analytics'!C11/'T12 Analytics'!C6,NA()),NA()) | Q3: 0.879
O4: Memory Care | P4: =IFERROR(IF('T12 Analytics'!D6>0,'T12 Analytics'!D11/'T12 Analytics'!D6,NA()),NA()) | Q4: 0.88
B5: OCCUPANCY | E5: EBITDARM MARGIN | H5: GOING-IN CAP RATE | K5: REVPOR | O5: Blended | P5: =IFERROR('T12 Analytics'!F134,NA()) | Q5: 0.895
B6: =IFERROR(IF(ISNUMBER('T12 Analytics'!F134),TEXT('T12 Analytics'!F134,"0.0%"),"—"),"—") | E6: =IFERROR(IF(ISNUMBER('T12 Analytics'!F162),TEXT('T12 Analytics'!F162,"0.0%"),"—"),"—") | H6: =IFERROR(IF(ISNUMBER('T12 Analytics'!F118),TEXT('T12 Analytics'!F118,"0.00%"),"—"),"—") | K6: =IFERROR(IF(ISNUMBER('T12 Analytics'!F143),TEXT('T12 Analytics'!F143,"$#,##0"),"—"),"—")
B7: Normalized community occupancy | E7: Normalized (pre-mgmt fee) | H7: Normalized NOI / Purchase Price | K7: Normalized RevPOR per resident | O7: Payer | P7: Revenue
B8: =IF(ISNUMBER('T12 Analytics'!F134),IF('T12 Analytics'!F134>=0.9,"✓ At/above 90% stabilized hurdle",IF('T12 Analytics'!F134>=0.85,"⚠ Below stabilized, lease-up risk","✗ Distressed occupancy")),"— Source not populated") | E8: =IF(ISNUMBER('T12 Analytics'!F162),IF('T12 Analytics'!F162>=0.27,"✓ In-line with REIT SHOP avg ~27%",IF('T12 Analytics'!F162>=0.22,"⚠ Below institutional median","✗ Margin distressed")),"— Source not populated") | H8: =IF(ISNUMBER('T12 Analytics'!F118),IF('T12 Analytics'!F118>=0.07,"✓ Above 6.2% market avg",IF('T12 Analytics'!F118>=0.055,"⚠ At market, modest yield","✗ Below market, aggressive")),"— Source not populated") | K8: =IF(ISNUMBER('T12 Analytics'!F143),"vs blended market $5,500-$6,500","— Source not populated") | O8: Private Pay | P8: =IFERROR(IF(ISNUMBER(E43),E43,0),0)
O9: Medicaid | P9: =IFERROR(IF(ISNUMBER(E44),E44,0),0)
B10: EFFECTIVE GROSS INCOME | E10: EBITDAR | H10: PRICE / BED | O10: LTC Insurance | P10: =IFERROR(IF(ISNUMBER(E45),E45,0),0)
B11: =IFERROR(IF(ISNUMBER('T12 Analytics'!F52),TEXT('T12 Analytics'!F52,"$#,##0"),"—"),"—") | E11: =IFERROR(IF(ISNUMBER('T12 Analytics'!F163),TEXT('T12 Analytics'!F163,"$#,##0"),"—"),"—") | H11: =IFERROR(IF(AND(ISNUMBER('T12 Analytics'!F117),ISNUMBER('T12 Analytics'!E6),'T12 Analytics'!E6>0),TEXT('T12 Analytics'!F117/'T12 Analytics'!E6,"$#,##0"),"—"),"—") | O11: VA | P11: =IFERROR(IF(ISNUMBER(E46),E46,0),0)
B12: Annual revenue (T12) | E12: After mgmt fee (lender NOI) | H12: Purchase price / licensed bed | O12: Managed Care | P12: =IFERROR(IF(ISNUMBER(E47),E47,0),0)
B13: =IF(ISNUMBER('T12 Analytics'!F52),"✓ EGI captured","— Source not populated") | E13: =IFERROR(IF(ISNUMBER('T12 Analytics'!F164),"Margin: "&TEXT('T12 Analytics'!F164,"0.0%"),"— Margin n/a"),"—") | H13: =IFERROR(IF(AND(ISNUMBER('T12 Analytics'!F117),ISNUMBER('T12 Analytics'!E6),'T12 Analytics'!E6>0),"on "&TEXT('T12 Analytics'!E6,"#,##0")&" licensed beds","— Source not populated"),"—") | O13: Self-Pay | P13: =IFERROR(IF(ISNUMBER(E48),E48,0),0)
O14: Other | P14: =IFERROR(IF(ISNUMBER(E49),E49,0),0)
B15: OPERATING PERFORMANCE
B17: CAPACITY & OCCUPANCY | E17: REVENUE & RATE | H17: PROFITABILITY | K17: COST STRUCTURE & LABOR
B18: Licensed beds (total) | C18: =IFERROR(IF(ISNUMBER('T12 Analytics'!E6),'T12 Analytics'!E6,"—"),"—") | E18: Gross potential rent | F18: =IFERROR(IF(ISNUMBER('T12 Analytics'!F37),'T12 Analytics'!F37,"—"),"—") | H18: EBITDARM $ | I18: =IFERROR(IF(ISNUMBER('T12 Analytics'!F161),'T12 Analytics'!F161,"—"),"—") | K18: Total labor % EGI | L18: =IFERROR(IF(ISNUMBER('T12 Analytics'!F148),'T12 Analytics'!F148,"—"),"—")
B19: IL / AL / MC | C19: =IFERROR(IF(ISNUMBER('T12 Analytics'!B6),TEXT('T12 Analytics'!B6,"0")&" / "&TEXT('T12 Analytics'!C6,"0")&" / "&TEXT('T12 Analytics'!D6,"0"),"—"),"—") | E19: Effective gross income | F19: =IFERROR(IF(ISNUMBER('T12 Analytics'!F52),'T12 Analytics'!F52,"—"),"—") | H19: EBITDARM margin | I19: =IFERROR(IF(ISNUMBER('T12 Analytics'!F162),'T12 Analytics'!F162,"—"),"—") | K19: Direct labor % EGI | L19: =IFERROR(IF(ISNUMBER('T12 Analytics'!F149),'T12 Analytics'!F149,"—"),"—")
B20: Avg occupied beds | C20: =IFERROR(IF(ISNUMBER('T12 Analytics'!E11),'T12 Analytics'!E11,"—"),"—") | E20: Blended ADR / day | F20: =IFERROR(IF(ISNUMBER('T12 Analytics'!F140),'T12 Analytics'!F140,"—"),"—") | H20: EBITDAR $ (post mgmt fee) | I20: =IFERROR(IF(ISNUMBER('T12 Analytics'!F163),'T12 Analytics'!F163,"—"),"—") | K20: Overtime % | L20: =IFERROR(IF(ISNUMBER('T12 Analytics'!F150),'T12 Analytics'!F150,"—"),"—")
B21: Community occupancy % | C21: =IFERROR(IF(ISNUMBER('T12 Analytics'!F134),'T12 Analytics'!F134,"—"),"—") | E21: RevPOR (blended) | F21: =IFERROR(IF(ISNUMBER('T12 Analytics'!F143),'T12 Analytics'!F143,"—"),"—") | H21: EBITDAR margin | I21: =IFERROR(IF(ISNUMBER('T12 Analytics'!F164),'T12 Analytics'!F164,"—"),"—") | K21: Agency labor % | L21: =IFERROR(IF(ISNUMBER('T12 Analytics'!F152),'T12 Analytics'!F152,"—"),"—")
B22: Economic occupancy % | C22: =IFERROR(IF(ISNUMBER('Rent Roll Recon'!E13),'Rent Roll Recon'!E13,"—"),"—") | E22: RevPAB | F22: =IFERROR(IF(ISNUMBER('T12 Analytics'!F145),'T12 Analytics'!F145,"—"),"—") | H22: EGI / occupied bed | I22: =IFERROR(IF(ISNUMBER('T12 Analytics'!F144),'T12 Analytics'!F144,"—"),"—") | K22: Food PPD | L22: =IFERROR(IF(ISNUMBER('T12 Analytics'!F154),'T12 Analytics'!F154,"—"),"—")
B23: Loss to lease % | C23: =IFERROR(IF(AND(ISNUMBER('T12 Analytics'!F41),ISNUMBER('T12 Analytics'!F37),'T12 Analytics'!F37<>0),ABS('T12 Analytics'!F41)/'T12 Analytics'!F37,"—"),"—") | E23: Level of care % | F23: =IFERROR(IF(ISNUMBER('T12 Analytics'!F146),'T12 Analytics'!F146,"—"),"—") | H23: Opex / occupied bed | I23: =IFERROR(IF(ISNUMBER('T12 Analytics'!F160),'T12 Analytics'!F160,"—"),"—") | K23: Mgmt fee % | L23: =IFERROR(IF(ISNUMBER('T12 Analytics'!F157),'T12 Analytics'!F157,"—"),"—")
B24: Vacancy % | C24: =IFERROR(IF(AND(ISNUMBER('T12 Analytics'!F38),ISNUMBER('T12 Analytics'!F37),'T12 Analytics'!F37<>0),ABS('T12 Analytics'!F38)/'T12 Analytics'!F37,"—"),"—") | E24: Bad debt % | F24: =IFERROR(IF(ISNUMBER('T12 Analytics'!F158),'T12 Analytics'!F158,"—"),"—") | H24: Total opex $ | I24: =IFERROR(IF(ISNUMBER('T12 Analytics'!F105),'T12 Analytics'!F105,"—"),"—") | K24: Insurance (P&C) % | L24: =IFERROR(IF(ISNUMBER('T12 Analytics'!F159),'T12 Analytics'!F159,"—"),"—")
B26: VALUATION & MARKET BENCHMARKING
B28: DEAL ECONOMICS | H28: OCCUPANCY vs MARKET (NIC MAP Q1 2026)
B29: Metric | D29: Property | E29: Market | F29: Read
B30: Purchase price | D30: =IFERROR(IF(ISNUMBER('T12 Analytics'!F117),'T12 Analytics'!F117,"—"),"—") | E30: n/a | F30: —
B31: Price / total bed | D31: =IFERROR(IF(AND(ISNUMBER('T12 Analytics'!F117),ISNUMBER('T12 Analytics'!E6),'T12 Analytics'!E6>0),'T12 Analytics'!F117/'T12 Analytics'!E6,"—"),"—") | E31: $220-280k | F31: =IF(ISNUMBER(D31),IF(D31<=280000,"✓",IF(D31<=350000,"⚠","✗")),"—")
B32: Going-in cap rate | D32: =IFERROR(IF(ISNUMBER('T12 Analytics'!F118),'T12 Analytics'!F118,"—"),"—") | E32: 0.062 | F32: =IF(ISNUMBER(D32),IF(D32>=0.07,"✓",IF(D32>=0.055,"⚠","✗")),"—")
B33: EBITDAR cap rate | D33: =IFERROR(IF(ISNUMBER('T12 Analytics'!F120),'T12 Analytics'!F120,"—"),"—") | E33: 5.7-6.5% | F33: =IF(ISNUMBER(D33),IF(D33>=0.065,"✓",IF(D33>=0.055,"⚠","✗")),"—")
B34: EBITDARM margin | D34: =IFERROR(IF(ISNUMBER('T12 Analytics'!F162),'T12 Analytics'!F162,"—"),"—") | E34: 0.27 | F34: =IF(ISNUMBER(D34),IF(D34>=0.27,"✓",IF(D34>=0.22,"⚠","✗")),"—")
B35: Community occupancy | D35: =IFERROR(IF(ISNUMBER('T12 Analytics'!F134),'T12 Analytics'!F134,"—"),"—") | E35: 0.895 | F35: =IF(ISNUMBER(D35),IF(D35>=0.9,"✓",IF(D35>=0.85,"⚠","✗")),"—")
B36: Labor % EGI | D36: =IFERROR(IF(ISNUMBER('T12 Analytics'!F148),'T12 Analytics'!F148,"—"),"—") | E36: 43-45% | F36: =IF(ISNUMBER(D36),IF(D36<=0.45,"✓",IF(D36<=0.5,"⚠","✗")),"—")
B37: Agency labor % | D37: =IFERROR(IF(ISNUMBER('T12 Analytics'!F152),'T12 Analytics'!F152,"—"),"—") | E37: <3% | F37: =IF(ISNUMBER(D37),IF(D37<=0.03,"✓",IF(D37<=0.06,"⚠","✗")),"—")
B39: PAYER MIX
B41: Payer Mix — Revenue & Census | H41: Payer Mix — Revenue Share
B42: Payer Type | C42: Resident Count | D42: % of Census | E42: Revenue (T12) | F42: % of Revenue
B43: Private Pay | C43: =IFERROR(IF(ISNUMBER('Rent Roll Recon'!B40),'Rent Roll Recon'!B40,"—"),"—") | D43: =IFERROR(IF(ISNUMBER('Rent Roll Recon'!C40),'Rent Roll Recon'!C40,"—"),"—") | E43: =IFERROR(IF(ISNUMBER('Rent Roll Recon'!H40),'Rent Roll Recon'!H40,"—"),"—") | F43: =IFERROR(IF(ISNUMBER('Rent Roll Recon'!I40),'Rent Roll Recon'!I40,"—"),"—")
B44: Medicaid | C44: =IFERROR(IF(ISNUMBER('Rent Roll Recon'!B41),'Rent Roll Recon'!B41,"—"),"—") | D44: =IFERROR(IF(ISNUMBER('Rent Roll Recon'!C41),'Rent Roll Recon'!C41,"—"),"—") | E44: =IFERROR(IF(ISNUMBER('Rent Roll Recon'!H41),'Rent Roll Recon'!H41,"—"),"—") | F44: =IFERROR(IF(ISNUMBER('Rent Roll Recon'!I41),'Rent Roll Recon'!I41,"—"),"—")
B45: LTC Insurance | C45: =IFERROR(IF(ISNUMBER('Rent Roll Recon'!B42),'Rent Roll Recon'!B42,"—"),"—") | D45: =IFERROR(IF(ISNUMBER('Rent Roll Recon'!C42),'Rent Roll Recon'!C42,"—"),"—") | E45: =IFERROR(IF(ISNUMBER('Rent Roll Recon'!H42),'Rent Roll Recon'!H42,"—"),"—") | F45: =IFERROR(IF(ISNUMBER('Rent Roll Recon'!I42),'Rent Roll Recon'!I42,"—"),"—")
...
