Workbook

Sheet Investment Dashboard
B2: SENIOR HOUSING — INVESTMENT DASHBOARD
B3: ="Property: " & 'T12 Analytics'!B2 & " | T12 Period: " & 'T12 Analytics'!E2 & " | Basis: " & 'T12 Analytics'!H2
B4: All KPIs link live to T12 Analytics and Rent Roll Recon. Update source tabs and values refresh.
B6: AT-A-GLANCE — T12 ACTUAL
B7: Total Licensed Beds | C7: Physical Occupancy | D7: Effective Gross Income | E7: EBITDARM Margin | F7: Going-In Cap (EBITDARM) | G7: Price / Licensed Bed
B8: ='T12 Analytics'!E6 | C8: ='T12 Analytics'!E8 | D8: ='T12 Analytics'!E52 | E8: ='T12 Analytics'!E162 | F8: ='T12 Analytics'!E118 | G8: ='T12 Analytics'!E123
B9: ="IL " & 'T12 Analytics'!B6 & " / AL " & 'T12 Analytics'!C6 & " / MC " & 'T12 Analytics'!D6 | C9: ="Target " & TEXT('T12 Analytics'!E10,"0%") & " | Gap " & TEXT('T12 Analytics'!E10-'T12 Analytics'!E8,"0.0%") | D9: ="Normalized: " & TEXT('T12 Analytics'!F52,"$#,##0") | E9: ="Normalized: " & TEXT('T12 Analytics'!F162,"0.0%") | F9: ="Stabilized: " & TEXT('T12 Analytics'!F118,"0.00%") | G9: ="Purchase: " & TEXT('T12 Analytics'!E117,"$#,##0,") & "K"
B11: 1. OCCUPANCY & CAPACITY
B12: Metric | C12: IL | D12: AL | E12: MC | F12: Total | G12: Target | H12: Status
B13: Licensed beds | C13: ='T12 Analytics'!B6 | D13: ='T12 Analytics'!C6 | E13: ='T12 Analytics'!D6 | F13: ='T12 Analytics'!E6
B14: Avg occupied beds (T12) | C14: ='T12 Analytics'!B7 | D14: ='T12 Analytics'!C7 | E14: ='T12 Analytics'!D7 | F14: ='T12 Analytics'!E7
B15: Physical occupancy % | C15: ='T12 Analytics'!B8 | D15: ='T12 Analytics'!C8 | E15: ='T12 Analytics'!D8 | F15: ='T12 Analytics'!E8 | G15: ='T12 Analytics'!E10 | H15: =IF(F15>=G15,"✓ At target",IF(F15>=G15-0.1,"⚠ Below","✗ Distressed"))
B16: Vacant beds | C16: ='Rent Roll Recon'!B9 | D16: ='Rent Roll Recon'!C9 | E16: ='Rent Roll Recon'!D9 | F16: ='Rent Roll Recon'!E9
B17: Beds to fill (to stabilization) | C17: =MAX(0,'T12 Analytics'!B11-'T12 Analytics'!B7) | D17: =MAX(0,'T12 Analytics'!C11-'T12 Analytics'!C7) | E17: =MAX(0,'T12 Analytics'!D11-'T12 Analytics'!D7) | F17: =SUM(C17:E17) | H17: Lease-up runway
B19: 2. REVENUE & RATE PERFORMANCE
B20: Metric | C20: IL | D20: AL | E20: MC | F20: Blended | G20: Normalized | H20: Delta
B21: ADR (base $/occ bed/mo) | C21: ='T12 Analytics'!B17 | D21: ='T12 Analytics'!C17 | E21: ='T12 Analytics'!D17 | F21: ='T12 Analytics'!E17
B22: RevPOR (base + LOC) | C22: ='T12 Analytics'!E141 | D22: ='T12 Analytics'!E142 | E22: ='T12 Analytics'!E143 | F22: ='T12 Analytics'!E144 | G22: ='T12 Analytics'!F144
B23: RevPAB ($/available bed/mo) | F23: ='T12 Analytics'!E145 | G23: ='T12 Analytics'!F145 | H23: =G23-F23
B24: LOC % of base rent (acuity) | F24: ='T12 Analytics'!E146 | G24: ='T12 Analytics'!F146
B25: T12 Base Rent ($) | C25: ='T12 Analytics'!B16 | D25: ='T12 Analytics'!C16 | E25: ='T12 Analytics'!D16 | F25: ='T12 Analytics'!E16 | G25: ='T12 Analytics'!F20 | H25: =G25-F25
B26: T12 LOC Revenue ($) | C26: ='T12 Analytics'!B23 | D26: ='T12 Analytics'!C23 | E26: ='T12 Analytics'!D23 | F26: ='T12 Analytics'!E23 | G26: ='T12 Analytics'!F27 | H26: =G26-F26
B27: Effective Gross Income (EGI) | F27: ='T12 Analytics'!E52 | G27: ='T12 Analytics'!F52 | H27: =G27-F27
B28: RR / T12 base rent gap (annualized) | F28: ='Rent Roll Recon'!E20 | G28: % of T12 | H28: =IFERROR('Rent Roll Recon'!E20/'Rent Roll Recon'!E19,"-")
B30: 3. MARGIN & COST STRUCTURE
B31: Metric | C31: T12 Actual | D31: Normalized | E31: Benchmark
B32: Total Operating Expenses (excl. mgmt) | C32: ='T12 Analytics'!E105 | D32: ='T12 Analytics'!F105
B33: Total labor & burden (% EGI) | C33: ='T12 Analytics'!E148 | D33: ='T12 Analytics'!F148 | E33: 55–65%
B34: Contract / agency labor (% direct) | C34: ='T12 Analytics'!E152 | D34: ='T12 Analytics'!F152 | E34: ≤3%
B35: Overtime (% direct wages) | C35: ='T12 Analytics'!E150 | D35: ='T12 Analytics'!F150 | E35: ≤5%
B36: Food cost (% EGI) | C36: ='T12 Analytics'!E155 | D36: ='T12 Analytics'!F155 | E36: 6–9%
B37: Food cost per patient day (PPD) | C37: ='T12 Analytics'!E154 | D37: ='T12 Analytics'!F154 | E37: $8–14
B38: P&C insurance (% EGI) | C38: ='T12 Analytics'!E159 | D38: ='T12 Analytics'!F159 | E38: 4–7%
B39: Bad debt (% gross revenue) | C39: ='T12 Analytics'!E158 | D39: ='T12 Analytics'!F158 | E39: ≤2%
B40: Mgmt fee (% revenue) | C40: ='T12 Analytics'!E157 | D40: ='T12 Analytics'!F157 | E40: 5–7%
B41: OpEx per occupied bed / month | C41: ='T12 Analytics'!E160 | D41: ='T12 Analytics'!F160
B43: EBITDARM ($) | C43: ='T12 Analytics'!E108 | D43: ='T12 Analytics'!F108 | E43: =D43-C43
B44: EBITDARM margin (%) | C44: ='T12 Analytics'!E162 | D44: ='T12 Analytics'!F162 | E44: 20–30%+
B45: EBITDAR ($, after mgmt fee) | C45: ='T12 Analytics'!E110 | D45: ='T12 Analytics'!F110 | E45: 15–25%+
B46: EBITDAR margin (%) | C46: ='T12 Analytics'!E164 | D46: ='T12 Analytics'!F164
...
